{
  "version": 8,
  "blockIdVersion": 11,
  "anchorX": 0,
  "anchorY": 0,
  "anchorZ": 0,
  "blocks": [
    {
      "x": -16,
      "y": 0,
      "z": -14,
      "name": "Cloth_Block_Wool_Red"
    },
    {
      "x": -16,
      "y": 1,
      "z": -14,
      "name": "Rock_Ice"
    },
    {
      "x": -16,
      "y": 2,
      "z": -14,
      "name": "Rock_Marble_Brick"
    },
    {
      "x": -16,
      "y": 3,
      "z": -14,
      "name": "Rock_Ice"
    },
    {
      "x": -16,
      "y": 4,
      "z": -14,
      "name": "Rock_Ice"
    },
    {
      "x": -16,
      "y": 5,
      "z": -14,
      "name": "Rock_Marble_Brick"
    },
    {
      "x": -16,
      "y": 6,
      "z": -14,
      "name": "Rock_Marble_Brick"
    },
    {
      "x": -16,
      "y": 7,
      "z": -14,
      "name": "Cloth_Block_Wool_Red"
    },
    {
      "x": -16,
      "y": 0,
      "z": -13,
      "name": "Rock_Marble_Brick"
    },
    {
      "x": -16,
      "y": 1,
      "z": -13,
      "name": "Rock_Marble_Brick_Decorative"
    },
    {
      "x": -16,
      "y": 2,
      "z": -13,
      "name": "Rock_Marble_Brick"
    },
    {
      "x": -16,
      "y": 3,
      "z": -13,
      "name": "Rock_Marble_Brick"
    },
    {
      "x": -16,
      "y": 4,
      "z": -13,
      "name": "Rock_Marble_Brick"
    },
    {
      "x": -16,
      "y": 5,
      "z": -13,
      "name": "Rock_Marble_Brick"
    },
    {
      "x": -16,
      "y": 6,
      "z": -13,
      "name": "Rock_Marble_Brick"
    },
    {
      "x": -16,
      "y": 7,
      "z": -13,
      "name": "Empty"
    },
    {
      "x": -16,
      "y": 0,
      "z": -12,
      "name": "Rock_Marble_Brick"
    },
    {
      "x": -16,
      "y": 1,
      "z": -12,
      "name": "Rock_Marble_Brick_Decorative"
    },
    {
      "x": -16,
      "y": 2,
      "z": -12,
      "name": "Rock_Ice"
    },
    {
      "x": -16,
      "y": 3,
      "z": -12,
      "name": "Rock_Marble_Brick"
    },
    {
      "x": -16,
      "y": 4,
      "z": -12,
      "name": "Rock_Marble_Brick"
    },
    {
      "x": -16,
      "y": 5,
      "z": -12,
      "name": "Rock_Marble_Brick"
    },
    {
      "x": -16,
      "y": 6,
      "z": -12,
      "name": "Rock_Marble_Brick"
    },
    {
      "x": -16,
      "y": 7,
      "z": -12,
      "name": "Empty"
    },
    {
      "x": -16,
      "y": 0,
      "z": -11,
      "name": "Rock_Marble_Brick"
    },
    {
      "x": -16,
      "y": 1,
      "z": -11,
      "name": "Rock_Marble_Brick_Decorative"
    },
    {
      "x": -16,
      "y": 2,
      "z": -11,
      "name": "Rock_Marble_Brick"
    },
    {
      "x": -16,
      "y": 3,
      "z": -11,
      "name": "Rock_Ice"
    },
    {
      "x": -16,
      "y": 4,
      "z": -11,
      "name": "Rock_Marble_Brick"
    },
    {
      "x": -16,
      "y": 5,
      "z": -11,
      "name": "Rock_Marble_Brick"
    },
    {
      "x": -16,
      "y": 6,
      "z": -11,
      "name": "Rock_Marble_Brick"
    },
    {
      "x": -16,
      "y": 7,
      "z": -11,
      "name": "Empty"
    },
    {
      "x": -16,
      "y": 0,
      "z": -10,
      "name": "Rock_Marble_Brick"
    },
    {
      "x": -16,
      "y": 1,
      "z": -10,
      "name": "Rock_Marble_Brick_Decorative"
    },
    {
      "x": -16,
      "y": 2,
      "z": -10,
      "name": "Rock_Marble_Brick"
    },
    {
      "x": -16,
      "y": 3,
      "z": -10,
      "name": "Rock_Marble_Brick"
    },
    {
      "x": -16,
      "y": 4,
      "z": -10,
      "name": "Rock_Marble_Brick"
    },
    {
      "x": -16,
      "y": 5,
      "z": -10,
      "name": "Rock_Ice"
    },
    {
      "x": -16,
      "y": 6,
      "z": -10,
      "name": "Rock_Marble_Brick"
    },
    {
      "x": -16,
      "y": 7,
      "z": -10,
      "name": "Empty"
    },
    {
      "x": -16,
      "y": 0,
      "z": -9,
      "name": "Rock_Marble_Brick"
    },
    {
      "x": -16,
      "y": 1,
      "z": -9,
      "name": "Rock_Marble_Brick"
    },
    {
      "x": -16,
      "y": 2,
      "z": -9,
      "name": "Rock_Marble_Brick"
    },
    {
      "x": -16,
      "y": 3,
      "z": -9,
      "name": "Rock_Marble_Brick"
    },
    {
      "x": -16,
      "y": 4,
      "z": -9,
      "name": "Rock_Ice"
    },
    {
      "x": -16,
      "y": 5,
      "z": -9,
      "name": "Rock_Ice"
    },
    {
      "x": -16,
      "y": 6,
      "z": -9,
      "name": "Rock_Ice"
    },
    {
      "x": -16,
      "y": 7,
      "z": -9,
      "name": "Empty"
    },
    {
      "x": -16,
      "y": 0,
      "z": -8,
      "name": "Empty"
    },
    {
      "x": -16,
      "y": 1,
      "z": -8,
      "name": "Empty"
    },
    {
      "x": -16,
      "y": 2,
      "z": -8,
      "name": "Empty"
    },
    {
      "x": -16,
      "y": 3,
      "z": -8,
      "name": "Empty"
    },
    {
      "x": -16,
      "y": 4,
      "z": -8,
      "name": "Empty"
    },
    {
      "x": -16,
      "y": 5,
      "z": -8,
      "name": "Empty"
    },
    {
      "x": -16,
      "y": 6,
      "z": -8,
      "name": "Empty"
    },
    {
      "x": -16,
      "y": 7,
      "z": -8,
      "name": "Empty"
    },
    {
      "x": -16,
      "y": 0,
      "z": -7,
      "name": "Empty"
    },
    {
      "x": -16,
      "y": 1,
      "z": -7,
      "name": "Empty"
    },
    {
      "x": -16,
      "y": 2,
      "z": -7,
      "name": "Empty"
    },
    {
      "x": -16,
      "y": 3,
      "z": -7,
      "name": "Empty"
    },
    {
      "x": -16,
      "y": 4,
      "z": -7,
      "name": "Empty"
    },
    {
      "x": -16,
      "y": 5,
      "z": -7,
      "name": "Empty"
    },
    {
      "x": -16,
      "y": 6,
      "z": -7,
      "name": "Empty"
    },
    {
      "x": -16,
      "y": 7,
      "z": -7,
      "name": "Empty"
    },
    {
      "x": -16,
      "y": 0,
      "z": -6,
      "name": "Empty"
    },
    {
      "x": -16,
      "y": 1,
      "z": -6,
      "name": "Empty"
    },
    {
      "x": -16,
      "y": 2,
      "z": -6,
      "name": "Empty"
    },
    {
      "x": -16,
      "y": 3,
      "z": -6,
      "name": "Empty"
    },
    {
      "x": -16,
      "y": 4,
      "z": -6,
      "name": "Empty"
    },
    {
      "x": -16,
      "y": 5,
      "z": -6,
      "name": "Empty"
    },
    {
      "x": -16,
      "y": 6,
      "z": -6,
      "name": "Empty"
    },
    {
      "x": -16,
      "y": 7,
      "z": -6,
      "name": "Empty"
    },
    {
      "x": -16,
      "y": 0,
      "z": -5,
      "name": "Empty"
    },
    {
      "x": -16,
      "y": 1,
      "z": -5,
      "name": "Empty"
    },
    {
      "x": -16,
      "y": 2,
      "z": -5,
      "name": "Empty"
    },
    {
      "x": -16,
      "y": 3,
      "z": -5,
      "name": "Empty"
    },
    {
      "x": -16,
      "y": 4,
      "z": -5,
      "name": "Empty"
    },
    {
      "x": -16,
      "y": 5,
      "z": -5,
      "name": "Empty"
    },
    {
      "x": -16,
      "y": 6,
      "z": -5,
      "name": "Empty"
    },
    {
      "x": -16,
      "y": 7,
      "z": -5,
      "name": "Empty"
    },
    {
      "x": -16,
      "y": 0,
      "z": -4,
      "name": "Empty"
    },
    {
      "x": -16,
      "y": 1,
      "z": -4,
      "name": "Empty"
    },
    {
      "x": -16,
      "y": 2,
      "z": -4,
      "name": "Empty"
    },
    {
      "x": -16,
      "y": 3,
      "z": -4,
      "name": "Empty"
    },
    {
      "x": -16,
      "y": 4,
      "z": -4,
      "name": "Empty"
    },
    {
      "x": -16,
      "y": 5,
      "z": -4,
      "name": "Empty"
    },
    {
      "x": -16,
      "y": 6,
      "z": -4,
      "name": "Empty"
    },
    {
      "x": -16,
      "y": 7,
      "z": -4,
      "name": "Empty"
    },
    {
      "x": -16,
      "y": 0,
      "z": -3,
      "name": "Empty"
    },
    {
      "x": -16,
      "y": 1,
      "z": -3,
      "name": "Empty"
    },
    {
      "x": -16,
      "y": 2,
      "z": -3,
      "name": "Empty"
    },
    {
      "x": -16,
      "y": 3,
      "z": -3,
      "name": "Empty"
    },
    {
      "x": -16,
      "y": 4,
      "z": -3,
      "name": "Empty"
    },
    {
      "x": -16,
      "y": 5,
      "z": -3,
      "name": "Empty"
    },
    {
      "x": -16,
      "y": 6,
      "z": -3,
      "name": "Empty"
    },
    {
      "x": -16,
      "y": 7,
      "z": -3,
      "name": "Empty"
    },
    {
      "x": -16,
      "y": 0,
      "z": -2,
      "name": "Empty"
    },
    {
      "x": -16,
      "y": 1,
      "z": -2,
      "name": "Empty"
    },
    {
      "x": -16,
      "y": 2,
      "z": -2,
      "name": "Empty"
    },
    {
      "x": -16,
      "y": 3,
      "z": -2,
      "name": "Empty"
    },
    {
      "x": -16,
      "y": 4,
      "z": -2,
      "name": "Empty"
    },
    {
      "x": -16,
      "y": 5,
      "z": -2,
      "name": "Empty"
    },
    {
      "x": -16,
      "y": 6,
      "z": -2,
      "name": "Empty"
    },
    {
      "x": -16,
      "y": 7,
      "z": -2,
      "name": "Empty"
    },
    {
      "x": -16,
      "y": 0,
      "z": -1,
      "name": "Empty"
    },
    {
      "x": -16,
      "y": 1,
      "z": -1,
      "name": "Empty"
    },
    {
      "x": -16,
      "y": 2,
      "z": -1,
      "name": "Empty"
    },
    {
      "x": -16,
      "y": 3,
      "z": -1,
      "name": "Empty"
    },
    {
      "x": -16,
      "y": 4,
      "z": -1,
      "name": "Empty"
    },
    {
      "x": -16,
      "y": 5,
      "z": -1,
      "name": "Empty"
    },
    {
      "x": -16,
      "y": 6,
      "z": -1,
      "name": "Empty"
    },
    {
      "x": -16,
      "y": 7,
      "z": -1,
      "name": "Empty"
    },
    {
      "x": -16,
      "y": 0,
      "z": 0,
      "name": "Empty"
    },
    {
      "x": -16,
      "y": 1,
      "z": 0,
      "name": "Empty"
    },
    {
      "x": -16,
      "y": 2,
      "z": 0,
      "name": "Empty"
    },
    {
      "x": -16,
      "y": 3,
      "z": 0,
      "name": "Empty"
    },
    {
      "x": -16,
      "y": 4,
      "z": 0,
      "name": "Empty"
    },
    {
      "x": -16,
      "y": 5,
      "z": 0,
      "name": "Empty"
    },
    {
      "x": -16,
      "y": 6,
      "z": 0,
      "name": "Empty"
    },
    {
      "x": -16,
      "y": 7,
      "z": 0,
      "name": "Empty"
    },
    {
      "x": -16,
      "y": 0,
      "z": 1,
      "name": "Empty"
    },
    {
      "x": -16,
      "y": 1,
      "z": 1,
      "name": "Empty"
    },
    {
      "x": -16,
      "y": 2,
      "z": 1,
      "name": "Empty"
    },
    {
      "x": -16,
      "y": 3,
      "z": 1,
      "name": "Empty"
    },
    {
      "x": -16,
      "y": 4,
      "z": 1,
      "name": "Empty"
    },
    {
      "x": -16,
      "y": 5,
      "z": 1,
      "name": "Empty"
    },
    {
      "x": -16,
      "y": 6,
      "z": 1,
      "name": "Empty"
    },
    {
      "x": -16,
      "y": 7,
      "z": 1,
      "name": "Empty"
    },
    {
      "x": -16,
      "y": 0,
      "z": 2,
      "name": "Empty"
    },
    {
      "x": -16,
      "y": 1,
      "z": 2,
      "name": "Empty"
    },
    {
      "x": -16,
      "y": 2,
      "z": 2,
      "name": "Empty"
    },
    {
      "x": -16,
      "y": 3,
      "z": 2,
      "name": "Empty"
    },
    {
      "x": -16,
      "y": 4,
      "z": 2,
      "name": "Empty"
    },
    {
      "x": -16,
      "y": 5,
      "z": 2,
      "name": "Empty"
    },
    {
      "x": -16,
      "y": 6,
      "z": 2,
      "name": "Empty"
    },
    {
      "x": -16,
      "y": 7,
      "z": 2,
      "name": "Empty"
    },
    {
      "x": -16,
      "y": 0,
      "z": 3,
      "name": "Empty"
    },
    {
      "x": -16,
      "y": 1,
      "z": 3,
      "name": "Empty"
    },
    {
      "x": -16,
      "y": 2,
      "z": 3,
      "name": "Empty"
    },
    {
      "x": -16,
      "y": 3,
      "z": 3,
      "name": "Empty"
    },
    {
      "x": -16,
      "y": 4,
      "z": 3,
      "name": "Empty"
    },
    {
      "x": -16,
      "y": 5,
      "z": 3,
      "name": "Empty"
    },
    {
      "x": -16,
      "y": 6,
      "z": 3,
      "name": "Empty"
    },
    {
      "x": -16,
      "y": 7,
      "z": 3,
      "name": "Empty"
    },
    {
      "x": -16,
      "y": 0,
      "z": 4,
      "name": "Empty"
    },
    {
      "x": -16,
      "y": 1,
      "z": 4,
      "name": "Empty"
    },
    {
      "x": -16,
      "y": 2,
      "z": 4,
      "name": "Empty"
    },
    {
      "x": -16,
      "y": 3,
      "z": 4,
      "name": "Empty"
    },
    {
      "x": -16,
      "y": 4,
      "z": 4,
      "name": "Empty"
    },
    {
      "x": -16,
      "y": 5,
      "z": 4,
      "name": "Empty"
    },
    {
      "x": -16,
      "y": 6,
      "z": 4,
      "name": "Empty"
    },
    {
      "x": -16,
      "y": 7,
      "z": 4,
      "name": "Empty"
    },
    {
      "x": -16,
      "y": 0,
      "z": 5,
      "name": "Empty"
    },
    {
      "x": -16,
      "y": 1,
      "z": 5,
      "name": "Empty"
    },
    {
      "x": -16,
      "y": 2,
      "z": 5,
      "name": "Empty"
    },
    {
      "x": -16,
      "y": 3,
      "z": 5,
      "name": "Empty"
    },
    {
      "x": -16,
      "y": 4,
      "z": 5,
      "name": "Empty"
    },
    {
      "x": -16,
      "y": 5,
      "z": 5,
      "name": "Empty"
    },
    {
      "x": -16,
      "y": 6,
      "z": 5,
      "name": "Empty"
    },
    {
      "x": -16,
      "y": 7,
      "z": 5,
      "name": "Empty"
    },
    {
      "x": -16,
      "y": 0,
      "z": 6,
      "name": "Empty"
    },
    {
      "x": -16,
      "y": 1,
      "z": 6,
      "name": "Empty"
    },
    {
      "x": -16,
      "y": 2,
      "z": 6,
      "name": "Empty"
    },
    {
      "x": -16,
      "y": 3,
      "z": 6,
      "name": "Empty"
    },
    {
      "x": -16,
      "y": 4,
      "z": 6,
      "name": "Empty"
    },
    {
      "x": -16,
      "y": 5,
      "z": 6,
      "name": "Empty"
    },
    {
      "x": -16,
      "y": 6,
      "z": 6,
      "name": "Empty"
    },
    {
      "x": -16,
      "y": 7,
      "z": 6,
      "name": "Empty"
    },
    {
      "x": -16,
      "y": 0,
      "z": 7,
      "name": "Empty"
    },
    {
      "x": -16,
      "y": 1,
      "z": 7,
      "name": "Empty"
    },
    {
      "x": -16,
      "y": 2,
      "z": 7,
      "name": "Empty"
    },
    {
      "x": -16,
      "y": 3,
      "z": 7,
      "name": "Empty"
    },
    {
      "x": -16,
      "y": 4,
      "z": 7,
      "name": "Empty"
    },
    {
      "x": -16,
      "y": 5,
      "z": 7,
      "name": "Empty"
    },
    {
      "x": -16,
      "y": 6,
      "z": 7,
      "name": "Empty"
    },
    {
      "x": -16,
      "y": 7,
      "z": 7,
      "name": "Empty"
    },
    {
      "x": -16,
      "y": 0,
      "z": 8,
      "name": "Empty"
    },
    {
      "x": -16,
      "y": 1,
      "z": 8,
      "name": "Empty"
    },
    {
      "x": -16,
      "y": 2,
      "z": 8,
      "name": "Empty"
    },
    {
      "x": -16,
      "y": 3,
      "z": 8,
      "name": "Empty"
    },
    {
      "x": -16,
      "y": 4,
      "z": 8,
      "name": "Empty"
    },
    {
      "x": -16,
      "y": 5,
      "z": 8,
      "name": "Empty"
    },
    {
      "x": -16,
      "y": 6,
      "z": 8,
      "name": "Empty"
    },
    {
      "x": -16,
      "y": 7,
      "z": 8,
      "name": "Empty"
    },
    {
      "x": -16,
      "y": 0,
      "z": 9,
      "name": "Rock_Marble_Brick",
      "rotation": 2
    },
    {
      "x": -16,
      "y": 1,
      "z": 9,
      "name": "Rock_Marble_Brick",
      "rotation": 2
    },
    {
      "x": -16,
      "y": 2,
      "z": 9,
      "name": "Rock_Marble_Brick",
      "rotation": 2
    },
    {
      "x": -16,
      "y": 3,
      "z": 9,
      "name": "Rock_Marble_Brick",
      "rotation": 2
    },
    {
      "x": -16,
      "y": 4,
      "z": 9,
      "name": "Rock_Marble_Brick",
      "rotation": 2
    },
    {
      "x": -16,
      "y": 5,
      "z": 9,
      "name": "Rock_Ice",
      "rotation": 2
    },
    {
      "x": -16,
      "y": 6,
      "z": 9,
      "name": "Rock_Ice",
      "rotation": 2
    },
    {
      "x": -16,
      "y": 7,
      "z": 9,
      "name": "Empty"
    },
    {
      "x": -16,
      "y": 0,
      "z": 10,
      "name": "Rock_Marble_Brick",
      "rotation": 2
    },
    {
      "x": -16,
      "y": 1,
      "z": 10,
      "name": "Rock_Marble_Brick_Decorative",
      "rotation": 2
    },
    {
      "x": -16,
      "y": 2,
      "z": 10,
      "name": "Rock_Ice",
      "rotation": 2
    },
    {
      "x": -16,
      "y": 3,
      "z": 10,
      "name": "Rock_Marble_Brick",
      "rotation": 2
    },
    {
      "x": -16,
      "y": 4,
      "z": 10,
      "name": "Rock_Marble_Brick",
      "rotation": 2
    },
    {
      "x": -16,
      "y": 5,
      "z": 10,
      "name": "Rock_Marble_Brick",
      "rotation": 2
    },
    {
      "x": -16,
      "y": 6,
      "z": 10,
      "name": "Rock_Marble_Brick",
      "rotation": 2
    },
    {
      "x": -16,
      "y": 7,
      "z": 10,
      "name": "Empty"
    },
    {
      "x": -16,
      "y": 0,
      "z": 11,
      "name": "Rock_Marble_Brick",
      "rotation": 2
    },
    {
      "x": -16,
      "y": 1,
      "z": 11,
      "name": "Rock_Marble_Brick_Decorative",
      "rotation": 2
    },
    {
      "x": -16,
      "y": 2,
      "z": 11,
      "name": "Rock_Marble_Brick",
      "rotation": 2
    },
    {
      "x": -16,
      "y": 3,
      "z": 11,
      "name": "Rock_Marble_Brick",
      "rotation": 2
    },
    {
      "x": -16,
      "y": 4,
      "z": 11,
      "name": "Rock_Marble_Brick",
      "rotation": 2
    },
    {
      "x": -16,
      "y": 5,
      "z": 11,
      "name": "Rock_Marble_Brick",
      "rotation": 2
    },
    {
      "x": -16,
      "y": 6,
      "z": 11,
      "name": "Rock_Ice",
      "rotation": 2
    },
    {
      "x": -16,
      "y": 7,
      "z": 11,
      "name": "Empty"
    },
    {
      "x": -16,
      "y": 0,
      "z": 12,
      "name": "Rock_Marble_Brick",
      "rotation": 2
    },
    {
      "x": -16,
      "y": 1,
      "z": 12,
      "name": "Rock_Marble_Brick_Decorative",
      "rotation": 2
    },
    {
      "x": -16,
      "y": 2,
      "z": 12,
      "name": "Rock_Marble_Brick",
      "rotation": 2
    },
    {
      "x": -16,
      "y": 3,
      "z": 12,
      "name": "Rock_Marble_Brick",
      "rotation": 2
    },
    {
      "x": -16,
      "y": 4,
      "z": 12,
      "name": "Rock_Marble_Brick",
      "rotation": 2
    },
    {
      "x": -16,
      "y": 5,
      "z": 12,
      "name": "Rock_Ice",
      "rotation": 2
    },
    {
      "x": -16,
      "y": 6,
      "z": 12,
      "name": "Rock_Ice",
      "rotation": 2
    },
    {
      "x": -16,
      "y": 7,
      "z": 12,
      "name": "Empty"
    },
    {
      "x": -16,
      "y": 0,
      "z": 13,
      "name": "Rock_Marble_Brick",
      "rotation": 2
    },
    {
      "x": -16,
      "y": 1,
      "z": 13,
      "name": "Rock_Marble_Brick_Decorative",
      "rotation": 2
    },
    {
      "x": -16,
      "y": 2,
      "z": 13,
      "name": "Rock_Marble_Brick",
      "rotation": 2
    },
    {
      "x": -16,
      "y": 3,
      "z": 13,
      "name": "Rock_Marble_Brick",
      "rotation": 2
    },
    {
      "x": -16,
      "y": 4,
      "z": 13,
      "name": "Rock_Marble_Brick",
      "rotation": 2
    },
    {
      "x": -16,
      "y": 5,
      "z": 13,
      "name": "Rock_Marble_Brick",
      "rotation": 2
    },
    {
      "x": -16,
      "y": 6,
      "z": 13,
      "name": "Rock_Marble_Brick",
      "rotation": 2
    },
    {
      "x": -16,
      "y": 7,
      "z": 13,
      "name": "Empty"
    },
    {
      "x": -16,
      "y": 0,
      "z": 14,
      "name": "Rock_Marble_Brick"
    },
    {
      "x": -16,
      "y": 1,
      "z": 14,
      "name": "Rock_Marble_Brick",
      "rotation": 2
    },
    {
      "x": -16,
      "y": 2,
      "z": 14,
      "name": "Rock_Marble_Brick",
      "rotation": 2
    },
    {
      "x": -16,
      "y": 3,
      "z": 14,
      "name": "Rock_Marble_Brick",
      "rotation": 2
    },
    {
      "x": -16,
      "y": 4,
      "z": 14,
      "name": "Rock_Ice",
      "rotation": 2
    },
    {
      "x": -16,
      "y": 5,
      "z": 14,
      "name": "Rock_Ice",
      "rotation": 2
    },
    {
      "x": -16,
      "y": 6,
      "z": 14,
      "name": "Rock_Marble_Brick"
    },
    {
      "x": -16,
      "y": 7,
      "z": 14,
      "name": "Empty"
    },
    {
      "x": -16,
      "y": 0,
      "z": 15,
      "name": "Cloth_Block_Wool_Red"
    },
    {
      "x": -16,
      "y": 1,
      "z": 15,
      "name": "Empty"
    },
    {
      "x": -16,
      "y": 2,
      "z": 15,
      "name": "Empty"
    },
    {
      "x": -16,
      "y": 3,
      "z": 15,
      "name": "Empty"
    },
    {
      "x": -16,
      "y": 4,
      "z": 15,
      "name": "Empty"
    },
    {
      "x": -16,
      "y": 5,
      "z": 15,
      "name": "Empty"
    },
    {
      "x": -16,
      "y": 6,
      "z": 15,
      "name": "Empty"
    },
    {
      "x": -16,
      "y": 7,
      "z": 15,
      "name": "Cloth_Block_Wool_Red"
    },
    {
      "x": -15,
      "y": 0,
      "z": -14,
      "name": "Rock_Marble_Brick"
    },
    {
      "x": -15,
      "y": 1,
      "z": -14,
      "name": "Rock_Marble_Brick_Decorative"
    },
    {
      "x": -15,
      "y": 2,
      "z": -14,
      "name": "Rock_Marble_Brick"
    },
    {
      "x": -15,
      "y": 3,
      "z": -14,
      "name": "Rock_Marble_Brick"
    },
    {
      "x": -15,
      "y": 4,
      "z": -14,
      "name": "Rock_Marble_Brick"
    },
    {
      "x": -15,
      "y": 5,
      "z": -14,
      "name": "Rock_Marble_Brick"
    },
    {
      "x": -15,
      "y": 6,
      "z": -14,
      "name": "Rock_Marble_Brick"
    },
    {
      "x": -15,
      "y": 7,
      "z": -14,
      "name": "Empty"
    },
    {
      "x": -15,
      "y": 0,
      "z": -13,
      "name": "Rock_Marble_Brick"
    },
    {
      "x": -15,
      "y": 1,
      "z": -13,
      "name": "Rock_Marble_Brick_Smooth_Half",
      "rotation": 4
    },
    {
      "x": -15,
      "y": 2,
      "z": -13,
      "name": "Rock_Marble_Brick_Smooth_Half",
      "rotation": 4
    },
    {
      "x": -15,
      "y": 3,
      "z": -13,
      "name": "Rock_Marble_Brick_Smooth_Half",
      "rotation": 4
    },
    {
      "x": -15,
      "y": 4,
      "z": -13,
      "name": "Rock_Marble_Brick_Smooth_Half",
      "rotation": 4
    },
    {
      "x": -15,
      "y": 5,
      "z": -13,
      "name": "Rock_Marble_Brick_Smooth"
    },
    {
      "x": -15,
      "y": 6,
      "z": -13,
      "name": "Rock_Marble_Brick"
    },
    {
      "x": -15,
      "y": 7,
      "z": -13,
      "name": "Empty"
    },
    {
      "x": -15,
      "y": 0,
      "z": -12,
      "name": "Rock_Marble_Brick"
    },
    {
      "x": -15,
      "y": 1,
      "z": -12,
      "name": "Empty"
    },
    {
      "x": -15,
      "y": 2,
      "z": -12,
      "name": "Empty"
    },
    {
      "x": -15,
      "y": 3,
      "z": -12,
      "name": "Empty"
    },
    {
      "x": -15,
      "y": 4,
      "z": -12,
      "name": "Empty"
    },
    {
      "x": -15,
      "y": 5,
      "z": -12,
      "name": "Rock_Marble_Brick_Smooth_Half",
      "rotation": 8
    },
    {
      "x": -15,
      "y": 6,
      "z": -12,
      "name": "Rock_Marble_Brick"
    },
    {
      "x": -15,
      "y": 7,
      "z": -12,
      "name": "Empty"
    },
    {
      "x": -15,
      "y": 0,
      "z": -11,
      "name": "Rock_Marble_Brick"
    },
    {
      "x": -15,
      "y": 1,
      "z": -11,
      "name": "Rubble_Ice_Medium",
      "support": 15
    },
    {
      "x": -15,
      "y": 2,
      "z": -11,
      "name": "Empty"
    },
    {
      "x": -15,
      "y": 3,
      "z": -11,
      "name": "Empty"
    },
    {
      "x": -15,
      "y": 4,
      "z": -11,
      "name": "Empty"
    },
    {
      "x": -15,
      "y": 5,
      "z": -11,
      "name": "Rock_Marble_Brick_Smooth_Half",
      "rotation": 8
    },
    {
      "x": -15,
      "y": 6,
      "z": -11,
      "name": "Rock_Marble_Brick"
    },
    {
      "x": -15,
      "y": 7,
      "z": -11,
      "name": "Empty"
    },
    {
      "x": -15,
      "y": 0,
      "z": -10,
      "name": "Rock_Ice"
    },
    {
      "x": -15,
      "y": 1,
      "z": -10,
      "name": "Rock_Marble_Brick_Smooth_Half",
      "rotation": 6
    },
    {
      "x": -15,
      "y": 2,
      "z": -10,
      "name": "Rock_Marble_Brick_Smooth_Half",
      "rotation": 6
    },
    {
      "x": -15,
      "y": 3,
      "z": -10,
      "name": "Rock_Marble_Brick_Smooth_Half",
      "rotation": 6
    },
    {
      "x": -15,
      "y": 4,
      "z": -10,
      "name": "Rock_Marble_Brick_Smooth_Half",
      "rotation": 6
    },
    {
      "x": -15,
      "y": 5,
      "z": -10,
      "name": "Rock_Marble_Brick_Smooth"
    },
    {
      "x": -15,
      "y": 6,
      "z": -10,
      "name": "Rock_Marble_Brick"
    },
    {
      "x": -15,
      "y": 7,
      "z": -10,
      "name": "Empty"
    },
    {
      "x": -15,
      "y": 0,
      "z": -9,
      "name": "Rock_Marble_Brick"
    },
    {
      "x": -15,
      "y": 1,
      "z": -9,
      "name": "Rock_Marble_Brick_Smooth"
    },
    {
      "x": -15,
      "y": 2,
      "z": -9,
      "name": "Rock_Marble_Brick_Smooth"
    },
    {
      "x": -15,
      "y": 3,
      "z": -9,
      "name": "Rock_Marble_Brick_Smooth"
    },
    {
      "x": -15,
      "y": 4,
      "z": -9,
      "name": "Rock_Marble_Brick_Smooth"
    },
    {
      "x": -15,
      "y": 5,
      "z": -9,
      "name": "Rock_Marble_Brick_Smooth"
    },
    {
      "x": -15,
      "y": 6,
      "z": -9,
      "name": "Rock_Marble_Brick"
    },
    {
      "x": -15,
      "y": 7,
      "z": -9,
      "name": "Empty"
    },
    {
      "x": -15,
      "y": 0,
      "z": -8,
      "name": "Rock_Marble_Brick"
    },
    {
      "x": -15,
      "y": 1,
      "z": -8,
      "name": "Rock_Marble_Brick_Decorative"
    },
    {
      "x": -15,
      "y": 2,
      "z": -8,
      "name": "Rock_Marble_Brick"
    },
    {
      "x": -15,
      "y": 3,
      "z": -8,
      "name": "Rock_Marble_Brick"
    },
    {
      "x": -15,
      "y": 4,
      "z": -8,
      "name": "Rock_Marble_Brick"
    },
    {
      "x": -15,
      "y": 5,
      "z": -8,
      "name": "Rock_Ice"
    },
    {
      "x": -15,
      "y": 6,
      "z": -8,
      "name": "Rock_Marble_Brick"
    },
    {
      "x": -15,
      "y": 7,
      "z": -8,
      "name": "Empty"
    },
    {
      "x": -15,
      "y": 0,
      "z": -7,
      "name": "Rock_Marble_Brick"
    },
    {
      "x": -15,
      "y": 1,
      "z": -7,
      "name": "Rock_Marble_Brick_Decorative"
    },
    {
      "x": -15,
      "y": 2,
      "z": -7,
      "name": "Rock_Marble_Brick"
    },
    {
      "x": -15,
      "y": 3,
      "z": -7,
      "name": "Rock_Marble_Brick"
    },
    {
      "x": -15,
      "y": 4,
      "z": -7,
      "name": "Rock_Marble_Brick"
    },
    {
      "x": -15,
      "y": 5,
      "z": -7,
      "name": "Rock_Marble_Brick"
    },
    {
      "x": -15,
      "y": 6,
      "z": -7,
      "name": "Rock_Marble_Brick"
    },
    {
      "x": -15,
      "y": 7,
      "z": -7,
      "name": "Empty"
    },
    {
      "x": -15,
      "y": 0,
      "z": -6,
      "name": "Rock_Marble_Brick"
    },
    {
      "x": -15,
      "y": 1,
      "z": -6,
      "name": "Rock_Marble_Brick_Decorative"
    },
    {
      "x": -15,
      "y": 2,
      "z": -6,
      "name": "Rock_Marble_Brick"
    },
    {
      "x": -15,
      "y": 3,
      "z": -6,
      "name": "Rock_Ice"
    },
    {
      "x": -15,
      "y": 4,
      "z": -6,
      "name": "Rock_Marble_Brick"
    },
    {
      "x": -15,
      "y": 5,
      "z": -6,
      "name": "Rock_Ice"
    },
    {
      "x": -15,
      "y": 6,
      "z": -6,
      "name": "Rock_Ice"
    },
    {
      "x": -15,
      "y": 7,
      "z": -6,
      "name": "Empty"
    },
    {
      "x": -15,
      "y": 0,
      "z": -5,
      "name": "Rock_Marble_Brick"
    },
    {
      "x": -15,
      "y": 1,
      "z": -5,
      "name": "Rock_Marble_Brick_Decorative"
    },
    {
      "x": -15,
      "y": 2,
      "z": -5,
      "name": "Rock_Ice"
    },
    {
      "x": -15,
      "y": 3,
      "z": -5,
      "name": "Rock_Ice"
    },
    {
      "x": -15,
      "y": 4,
      "z": -5,
      "name": "Rock_Marble_Brick"
    },
    {
      "x": -15,
      "y": 5,
      "z": -5,
      "name": "Rock_Ice"
    },
    {
      "x": -15,
      "y": 6,
      "z": -5,
      "name": "Rock_Ice"
    },
    {
      "x": -15,
      "y": 7,
      "z": -5,
      "name": "Empty"
    },
    {
      "x": -15,
      "y": 0,
      "z": -4,
      "name": "Rock_Marble_Brick"
    },
    {
      "x": -15,
      "y": 1,
      "z": -4,
      "name": "Rock_Marble_Brick_Decorative"
    },
    {
      "x": -15,
      "y": 2,
      "z": -4,
      "name": "Rock_Marble_Brick"
    },
    {
      "x": -15,
      "y": 3,
      "z": -4,
      "name": "Rock_Ice"
    },
    {
      "x": -15,
      "y": 4,
      "z": -4,
      "name": "Rock_Ice"
    },
    {
      "x": -15,
      "y": 5,
      "z": -4,
      "name": "Rock_Marble_Brick"
    },
    {
      "x": -15,
      "y": 6,
      "z": -4,
      "name": "Rock_Ice"
    },
    {
      "x": -15,
      "y": 7,
      "z": -4,
      "name": "Empty"
    },
    {
      "x": -15,
      "y": 0,
      "z": -3,
      "name": "Rock_Marble_Brick"
    },
    {
      "x": -15,
      "y": 1,
      "z": -3,
      "name": "Rock_Marble_Brick"
    },
    {
      "x": -15,
      "y": 2,
      "z": -3,
      "name": "Rock_Marble_Brick"
    },
    {
      "x": -15,
      "y": 3,
      "z": -3,
      "name": "Rock_Ice"
    },
    {
      "x": -15,
      "y": 4,
      "z": -3,
      "name": "Rock_Marble_Brick"
    },
    {
      "x": -15,
      "y": 5,
      "z": -3,
      "name": "Rock_Marble_Brick"
    },
    {
      "x": -15,
      "y": 6,
      "z": -3,
      "name": "Rock_Marble_Brick"
    },
    {
      "x": -15,
      "y": 7,
      "z": -3,
      "name": "Empty"
    },
    {
      "x": -15,
      "y": 0,
      "z": -2,
      "name": "Rock_Marble_Brick"
    },
    {
      "x": -15,
      "y": 1,
      "z": -2,
      "name": "Rock_Marble_Brick_Decorative"
    },
    {
      "x": -15,
      "y": 2,
      "z": -2,
      "name": "Rock_Ice"
    },
    {
      "x": -15,
      "y": 3,
      "z": -2,
      "name": "Rock_Ice"
    },
    {
      "x": -15,
      "y": 4,
      "z": -2,
      "name": "Rock_Marble_Brick"
    },
    {
      "x": -15,
      "y": 5,
      "z": -2,
      "name": "Rock_Ice"
    },
    {
      "x": -15,
      "y": 6,
      "z": -2,
      "name": "Rock_Marble_Brick"
    },
    {
      "x": -15,
      "y": 7,
      "z": -2,
      "name": "Empty"
    },
    {
      "x": -15,
      "y": 0,
      "z": -1,
      "name": "Rock_Marble_Brick"
    },
    {
      "x": -15,
      "y": 1,
      "z": -1,
      "name": "Rock_Marble_Brick_Decorative"
    },
    {
      "x": -15,
      "y": 2,
      "z": -1,
      "name": "Rock_Ice"
    },
    {
      "x": -15,
      "y": 3,
      "z": -1,
      "name": "Rock_Ice"
    },
    {
      "x": -15,
      "y": 4,
      "z": -1,
      "name": "Rock_Marble_Brick"
    },
    {
      "x": -15,
      "y": 5,
      "z": -1,
      "name": "Rock_Marble_Brick"
    },
    {
      "x": -15,
      "y": 6,
      "z": -1,
      "name": "Rock_Ice"
    },
    {
      "x": -15,
      "y": 7,
      "z": -1,
      "name": "Empty"
    },
    {
      "x": -15,
      "y": 0,
      "z": 0,
      "name": "Rock_Marble_Brick"
    },
    {
      "x": -15,
      "y": 1,
      "z": 0,
      "name": "Rock_Marble_Brick_Decorative"
    },
    {
      "x": -15,
      "y": 2,
      "z": 0,
      "name": "Rock_Marble_Brick"
    },
    {
      "x": -15,
      "y": 3,
      "z": 0,
      "name": "Rock_Ice"
    },
    {
      "x": -15,
      "y": 4,
      "z": 0,
      "name": "Rock_Marble_Brick"
    },
    {
      "x": -15,
      "y": 5,
      "z": 0,
      "name": "Rock_Ice"
    },
    {
      "x": -15,
      "y": 6,
      "z": 0,
      "name": "Rock_Marble_Brick"
    },
    {
      "x": -15,
      "y": 7,
      "z": 0,
      "name": "Empty"
    },
    {
      "x": -15,
      "y": 0,
      "z": 1,
      "name": "Rock_Marble_Brick"
    },
    {
      "x": -15,
      "y": 1,
      "z": 1,
      "name": "Rock_Marble_Brick_Decorative"
    },
    {
      "x": -15,
      "y": 2,
      "z": 1,
      "name": "Rock_Marble_Brick"
    },
    {
      "x": -15,
      "y": 3,
      "z": 1,
      "name": "Rock_Ice"
    },
    {
      "x": -15,
      "y": 4,
      "z": 1,
      "name": "Rock_Ice"
    },
    {
      "x": -15,
      "y": 5,
      "z": 1,
      "name": "Rock_Marble_Brick"
    },
    {
      "x": -15,
      "y": 6,
      "z": 1,
      "name": "Rock_Ice"
    },
    {
      "x": -15,
      "y": 7,
      "z": 1,
      "name": "Empty"
    },
    {
      "x": -15,
      "y": 0,
      "z": 2,
      "name": "Rock_Marble_Brick"
    },
    {
      "x": -15,
      "y": 1,
      "z": 2,
      "name": "Rock_Marble_Brick_Decorative"
    },
    {
      "x": -15,
      "y": 2,
      "z": 2,
      "name": "Rock_Marble_Brick"
    },
    {
      "x": -15,
      "y": 3,
      "z": 2,
      "name": "Rock_Marble_Brick"
    },
    {
      "x": -15,
      "y": 4,
      "z": 2,
      "name": "Rock_Marble_Brick"
    },
    {
      "x": -15,
      "y": 5,
      "z": 2,
      "name": "Rock_Marble_Brick"
    },
    {
      "x": -15,
      "y": 6,
      "z": 2,
      "name": "Rock_Ice"
    },
    {
      "x": -15,
      "y": 7,
      "z": 2,
      "name": "Empty"
    },
    {
      "x": -15,
      "y": 0,
      "z": 3,
      "name": "Rock_Marble_Brick"
    },
    {
      "x": -15,
      "y": 1,
      "z": 3,
      "name": "Rock_Ice"
    },
    {
      "x": -15,
      "y": 2,
      "z": 3,
      "name": "Rock_Ice"
    },
    {
      "x": -15,
      "y": 3,
      "z": 3,
      "name": "Rock_Marble_Brick"
    },
    {
      "x": -15,
      "y": 4,
      "z": 3,
      "name": "Rock_Marble_Brick"
    },
    {
      "x": -15,
      "y": 5,
      "z": 3,
      "name": "Rock_Marble_Brick"
    },
    {
      "x": -15,
      "y": 6,
      "z": 3,
      "name": "Rock_Marble_Brick"
    },
    {
      "x": -15,
      "y": 7,
      "z": 3,
      "name": "Empty"
    },
    {
      "x": -15,
      "y": 0,
      "z": 4,
      "name": "Rock_Marble_Brick"
    },
    {
      "x": -15,
      "y": 1,
      "z": 4,
      "name": "Rock_Marble_Brick_Decorative"
    },
    {
      "x": -15,
      "y": 2,
      "z": 4,
      "name": "Rock_Ice"
    },
    {
      "x": -15,
      "y": 3,
      "z": 4,
      "name": "Rock_Ice"
    },
    {
      "x": -15,
      "y": 4,
      "z": 4,
      "name": "Rock_Marble_Brick"
    },
    {
      "x": -15,
      "y": 5,
      "z": 4,
      "name": "Rock_Marble_Brick"
    },
    {
      "x": -15,
      "y": 6,
      "z": 4,
      "name": "Rock_Ice"
    },
    {
      "x": -15,
      "y": 7,
      "z": 4,
      "name": "Empty"
    },
    {
      "x": -15,
      "y": 0,
      "z": 5,
      "name": "Rock_Marble_Brick"
    },
    {
      "x": -15,
      "y": 1,
      "z": 5,
      "name": "Rock_Marble_Brick_Decorative"
    },
    {
      "x": -15,
      "y": 2,
      "z": 5,
      "name": "Rock_Marble_Brick"
    },
    {
      "x": -15,
      "y": 3,
      "z": 5,
      "name": "Rock_Marble_Brick"
    },
    {
      "x": -15,
      "y": 4,
      "z": 5,
      "name": "Rock_Marble_Brick"
    },
    {
      "x": -15,
      "y": 5,
      "z": 5,
      "name": "Rock_Marble_Brick"
    },
    {
      "x": -15,
      "y": 6,
      "z": 5,
      "name": "Rock_Marble_Brick"
    },
    {
      "x": -15,
      "y": 7,
      "z": 5,
      "name": "Empty"
    },
    {
      "x": -15,
      "y": 0,
      "z": 6,
      "name": "Rock_Marble_Brick"
    },
    {
      "x": -15,
      "y": 1,
      "z": 6,
      "name": "Rock_Marble_Brick_Decorative"
    },
    {
      "x": -15,
      "y": 2,
      "z": 6,
      "name": "Rock_Marble_Brick"
    },
    {
      "x": -15,
      "y": 3,
      "z": 6,
      "name": "Rock_Ice"
    },
    {
      "x": -15,
      "y": 4,
      "z": 6,
      "name": "Rock_Marble_Brick"
    },
    {
      "x": -15,
      "y": 5,
      "z": 6,
      "name": "Rock_Marble_Brick"
    },
    {
      "x": -15,
      "y": 6,
      "z": 6,
      "name": "Rock_Marble_Brick"
    },
    {
      "x": -15,
      "y": 7,
      "z": 6,
      "name": "Empty"
    },
    {
      "x": -15,
      "y": 0,
      "z": 7,
      "name": "Rock_Marble_Brick"
    },
    {
      "x": -15,
      "y": 1,
      "z": 7,
      "name": "Rock_Marble_Brick_Decorative"
    },
    {
      "x": -15,
      "y": 2,
      "z": 7,
      "name": "Rock_Ice"
    },
    {
      "x": -15,
      "y": 3,
      "z": 7,
      "name": "Rock_Ice"
    },
    {
      "x": -15,
      "y": 4,
      "z": 7,
      "name": "Rock_Marble_Brick"
    },
    {
      "x": -15,
      "y": 5,
      "z": 7,
      "name": "Rock_Marble_Brick"
    },
    {
      "x": -15,
      "y": 6,
      "z": 7,
      "name": "Rock_Ice"
    },
    {
      "x": -15,
      "y": 7,
      "z": 7,
      "name": "Empty"
    },
    {
      "x": -15,
      "y": 0,
      "z": 8,
      "name": "Rock_Marble_Brick"
    },
    {
      "x": -15,
      "y": 1,
      "z": 8,
      "name": "Rock_Marble_Brick_Decorative"
    },
    {
      "x": -15,
      "y": 2,
      "z": 8,
      "name": "Rock_Marble_Brick"
    },
    {
      "x": -15,
      "y": 3,
      "z": 8,
      "name": "Rock_Marble_Brick"
    },
    {
      "x": -15,
      "y": 4,
      "z": 8,
      "name": "Rock_Marble_Brick"
    },
    {
      "x": -15,
      "y": 5,
      "z": 8,
      "name": "Rock_Marble_Brick"
    },
    {
      "x": -15,
      "y": 6,
      "z": 8,
      "name": "Rock_Marble_Brick"
    },
    {
      "x": -15,
      "y": 7,
      "z": 8,
      "name": "Empty"
    },
    {
      "x": -15,
      "y": 0,
      "z": 9,
      "name": "Rock_Marble_Brick",
      "rotation": 2
    },
    {
      "x": -15,
      "y": 1,
      "z": 9,
      "name": "Rock_Marble_Brick_Smooth",
      "rotation": 2
    },
    {
      "x": -15,
      "y": 2,
      "z": 9,
      "name": "Rock_Marble_Brick_Smooth",
      "rotation": 2
    },
    {
      "x": -15,
      "y": 3,
      "z": 9,
      "name": "Rock_Marble_Brick_Smooth",
      "rotation": 2
    },
    {
      "x": -15,
      "y": 4,
      "z": 9,
      "name": "Rock_Marble_Brick_Smooth",
      "rotation": 2
    },
    {
      "x": -15,
      "y": 5,
      "z": 9,
      "name": "Rock_Marble_Brick_Smooth",
      "rotation": 2
    },
    {
      "x": -15,
      "y": 6,
      "z": 9,
      "name": "Rock_Marble_Brick",
      "rotation": 2
    },
    {
      "x": -15,
      "y": 7,
      "z": 9,
      "name": "Empty"
    },
    {
      "x": -15,
      "y": 0,
      "z": 10,
      "name": "Rock_Marble_Brick",
      "rotation": 2
    },
    {
      "x": -15,
      "y": 1,
      "z": 10,
      "name": "Rock_Marble_Brick_Smooth_Half",
      "rotation": 4
    },
    {
      "x": -15,
      "y": 2,
      "z": 10,
      "name": "Rock_Marble_Brick_Smooth_Half",
      "rotation": 4
    },
    {
      "x": -15,
      "y": 3,
      "z": 10,
      "name": "Rock_Marble_Brick_Smooth_Half",
      "rotation": 4
    },
    {
      "x": -15,
      "y": 4,
      "z": 10,
      "name": "Rock_Marble_Brick_Smooth_Half",
      "rotation": 4
    },
    {
      "x": -15,
      "y": 5,
      "z": 10,
      "name": "Rock_Marble_Brick_Smooth",
      "rotation": 2
    },
    {
      "x": -15,
      "y": 6,
      "z": 10,
      "name": "Rock_Marble_Brick",
      "rotation": 2
    },
    {
      "x": -15,
      "y": 7,
      "z": 10,
      "name": "Empty"
    },
    {
      "x": -15,
      "y": 0,
      "z": 11,
      "name": "Rock_Marble_Brick",
      "rotation": 2
    },
    {
      "x": -15,
      "y": 1,
      "z": 11,
      "name": "Empty"
    },
    {
      "x": -15,
      "y": 2,
      "z": 11,
      "name": "Empty"
    },
    {
      "x": -15,
      "y": 3,
      "z": 11,
      "name": "Empty"
    },
    {
      "x": -15,
      "y": 4,
      "z": 11,
      "name": "Empty"
    },
    {
      "x": -15,
      "y": 5,
      "z": 11,
      "name": "Rock_Marble_Brick_Smooth_Half",
      "rotation": 10
    },
    {
      "x": -15,
      "y": 6,
      "z": 11,
      "name": "Rock_Ice",
      "rotation": 2
    },
    {
      "x": -15,
      "y": 7,
      "z": 11,
      "name": "Empty"
    },
    {
      "x": -15,
      "y": 0,
      "z": 12,
      "name": "Rock_Marble_Brick",
      "rotation": 2
    },
    {
      "x": -15,
      "y": 1,
      "z": 12,
      "name": "Furniture_Temple_Light_Pot"
    },
    {
      "x": -15,
      "y": 2,
      "z": 12,
      "name": "Empty"
    },
    {
      "x": -15,
      "y": 3,
      "z": 12,
      "name": "Empty"
    },
    {
      "x": -15,
      "y": 4,
      "z": 12,
      "name": "Empty"
    },
    {
      "x": -15,
      "y": 5,
      "z": 12,
      "name": "Rock_Marble_Brick_Smooth_Half",
      "rotation": 10
    },
    {
      "x": -15,
      "y": 6,
      "z": 12,
      "name": "Rock_Marble_Brick",
      "rotation": 2
    },
    {
      "x": -15,
      "y": 7,
      "z": 12,
      "name": "Empty"
    },
    {
      "x": -15,
      "y": 0,
      "z": 13,
      "name": "Rock_Marble_Brick",
      "rotation": 2
    },
    {
      "x": -15,
      "y": 1,
      "z": 13,
      "name": "Rock_Marble_Brick_Smooth_Half",
      "rotation": 6
    },
    {
      "x": -15,
      "y": 2,
      "z": 13,
      "name": "Rock_Marble_Brick_Smooth_Half",
      "rotation": 6
    },
    {
      "x": -15,
      "y": 3,
      "z": 13,
      "name": "Rock_Marble_Brick_Smooth_Half",
      "rotation": 6
    },
    {
      "x": -15,
      "y": 4,
      "z": 13,
      "name": "Rock_Marble_Brick_Smooth_Half",
      "rotation": 6
    },
    {
      "x": -15,
      "y": 5,
      "z": 13,
      "name": "Rock_Marble_Brick_Smooth",
      "rotation": 2
    },
    {
      "x": -15,
      "y": 6,
      "z": 13,
      "name": "Rock_Marble_Brick",
      "rotation": 2
    },
    {
      "x": -15,
      "y": 7,
      "z": 13,
      "name": "Empty"
    },
    {
      "x": -15,
      "y": 0,
      "z": 14,
      "name": "Rock_Marble_Brick",
      "rotation": 2
    },
    {
      "x": -15,
      "y": 1,
      "z": 14,
      "name": "Rock_Marble_Brick_Decorative",
      "rotation": 2
    },
    {
      "x": -15,
      "y": 2,
      "z": 14,
      "name": "Rock_Marble_Brick",
      "rotation": 2
    },
    {
      "x": -15,
      "y": 3,
      "z": 14,
      "name": "Rock_Marble_Brick",
      "rotation": 2
    },
    {
      "x": -15,
      "y": 4,
      "z": 14,
      "name": "Rock_Marble_Brick",
      "rotation": 2
    },
    {
      "x": -15,
      "y": 5,
      "z": 14,
      "name": "Rock_Marble_Brick",
      "rotation": 2
    },
    {
      "x": -15,
      "y": 6,
      "z": 14,
      "name": "Rock_Marble_Brick",
      "rotation": 2
    },
    {
      "x": -15,
      "y": 7,
      "z": 14,
      "name": "Empty"
    },
    {
      "x": -15,
      "y": 0,
      "z": 15,
      "name": "Empty"
    },
    {
      "x": -15,
      "y": 1,
      "z": 15,
      "name": "Empty"
    },
    {
      "x": -15,
      "y": 2,
      "z": 15,
      "name": "Empty"
    },
    {
      "x": -15,
      "y": 3,
      "z": 15,
      "name": "Empty"
    },
    {
      "x": -15,
      "y": 4,
      "z": 15,
      "name": "Empty"
    },
    {
      "x": -15,
      "y": 5,
      "z": 15,
      "name": "Empty"
    },
    {
      "x": -15,
      "y": 6,
      "z": 15,
      "name": "Empty"
    },
    {
      "x": -15,
      "y": 7,
      "z": 15,
      "name": "Empty"
    },
    {
      "x": -14,
      "y": 0,
      "z": -14,
      "name": "Rock_Marble_Brick"
    },
    {
      "x": -14,
      "y": 1,
      "z": -14,
      "name": "Rock_Marble_Brick_Decorative"
    },
    {
      "x": -14,
      "y": 2,
      "z": -14,
      "name": "Rock_Marble_Brick"
    },
    {
      "x": -14,
      "y": 3,
      "z": -14,
      "name": "Rock_Marble_Brick"
    },
    {
      "x": -14,
      "y": 4,
      "z": -14,
      "name": "Rock_Ice"
    },
    {
      "x": -14,
      "y": 5,
      "z": -14,
      "name": "Rock_Marble_Brick"
    },
    {
      "x": -14,
      "y": 6,
      "z": -14,
      "name": "Rock_Marble_Brick"
    },
    {
      "x": -14,
      "y": 7,
      "z": -14,
      "name": "Empty"
    },
    {
      "x": -14,
      "y": 0,
      "z": -13,
      "name": "Rock_Marble_Brick"
    },
    {
      "x": -14,
      "y": 1,
      "z": -13,
      "name": "Empty"
    },
    {
      "x": -14,
      "y": 2,
      "z": -13,
      "name": "Empty"
    },
    {
      "x": -14,
      "y": 3,
      "z": -13,
      "name": "Empty"
    },
    {
      "x": -14,
      "y": 4,
      "z": -13,
      "name": "Empty"
    },
    {
      "x": -14,
      "y": 5,
      "z": -13,
      "name": "Rock_Marble_Brick_Smooth_Half",
      "rotation": 4
    },
    {
      "x": -14,
      "y": 6,
      "z": -13,
      "name": "Rock_Ice"
    },
    {
      "x": -14,
      "y": 7,
      "z": -13,
      "name": "Empty"
    },
    {
      "x": -14,
      "y": 0,
      "z": -12,
      "name": "Rock_Marble_Brick"
    },
    {
      "x": -14,
      "y": 1,
      "z": -12,
      "name": "Empty"
    },
    {
      "x": -14,
      "y": 2,
      "z": -12,
      "name": "Empty"
    },
    {
      "x": -14,
      "y": 3,
      "z": -12,
      "name": "Empty"
    },
    {
      "x": -14,
      "y": 4,
      "z": -12,
      "name": "Empty"
    },
    {
      "x": -14,
      "y": 5,
      "z": -12,
      "name": "Empty"
    },
    {
      "x": -14,
      "y": 6,
      "z": -12,
      "name": "Rock_Marble_Brick"
    },
    {
      "x": -14,
      "y": 7,
      "z": -12,
      "name": "Empty"
    },
    {
      "x": -14,
      "y": 0,
      "z": -11,
      "name": "Rock_Ice"
    },
    {
      "x": -14,
      "y": 1,
      "z": -11,
      "name": "Empty"
    },
    {
      "x": -14,
      "y": 2,
      "z": -11,
      "name": "Empty"
    },
    {
      "x": -14,
      "y": 3,
      "z": -11,
      "name": "Empty"
    },
    {
      "x": -14,
      "y": 4,
      "z": -11,
      "name": "Empty"
    },
    {
      "x": -14,
      "y": 5,
      "z": -11,
      "name": "Empty"
    },
    {
      "x": -14,
      "y": 6,
      "z": -11,
      "name": "Rock_Marble_Brick"
    },
    {
      "x": -14,
      "y": 7,
      "z": -11,
      "name": "Empty"
    },
    {
      "x": -14,
      "y": 0,
      "z": -10,
      "name": "Rock_Marble_Brick"
    },
    {
      "x": -14,
      "y": 1,
      "z": -10,
      "name": "Rubble_Ice",
      "support": 15
    },
    {
      "x": -14,
      "y": 2,
      "z": -10,
      "name": "Empty"
    },
    {
      "x": -14,
      "y": 3,
      "z": -10,
      "name": "Empty"
    },
    {
      "x": -14,
      "y": 4,
      "z": -10,
      "name": "Empty"
    },
    {
      "x": -14,
      "y": 5,
      "z": -10,
      "name": "Rock_Marble_Brick_Smooth_Half",
      "rotation": 6
    },
    {
      "x": -14,
      "y": 6,
      "z": -10,
      "name": "Rock_Marble_Brick"
    },
    {
      "x": -14,
      "y": 7,
      "z": -10,
      "name": "Empty"
    },
    {
      "x": -14,
      "y": 0,
      "z": -9,
      "name": "Rock_Marble_Brick"
    },
    {
      "x": -14,
      "y": 1,
      "z": -9,
      "name": "Rock_Calcite_Brick_Ornate"
    },
    {
      "x": -14,
      "y": 2,
      "z": -9,
      "name": "Rock_Calcite_Brick_Smooth"
    },
    {
      "x": -14,
      "y": 3,
      "z": -9,
      "name": "Rock_Calcite_Brick_Smooth"
    },
    {
      "x": -14,
      "y": 4,
      "z": -9,
      "name": "Rock_Calcite_Brick_Ornate"
    },
    {
      "x": -14,
      "y": 5,
      "z": -9,
      "name": "Rock_Calcite_Brick_Smooth"
    },
    {
      "x": -14,
      "y": 6,
      "z": -9,
      "name": "Rock_Marble_Brick"
    },
    {
      "x": -14,
      "y": 7,
      "z": -9,
      "name": "Empty"
    },
    {
      "x": -14,
      "y": 0,
      "z": -8,
      "name": "Rock_Ice"
    },
    {
      "x": -14,
      "y": 1,
      "z": -8,
      "name": "Empty"
    },
    {
      "x": -14,
      "y": 2,
      "z": -8,
      "name": "Empty"
    },
    {
      "x": -14,
      "y": 3,
      "z": -8,
      "name": "Empty"
    },
    {
      "x": -14,
      "y": 4,
      "z": -8,
      "name": "Empty"
    },
    {
      "x": -14,
      "y": 5,
      "z": -8,
      "name": "Rock_Marble_Brick_Smooth"
    },
    {
      "x": -14,
      "y": 6,
      "z": -8,
      "name": "Rock_Marble_Brick"
    },
    {
      "x": -14,
      "y": 7,
      "z": -8,
      "name": "Empty"
    },
    {
      "x": -14,
      "y": 0,
      "z": -7,
      "name": "Rock_Marble_Brick"
    },
    {
      "x": -14,
      "y": 1,
      "z": -7,
      "name": "Empty"
    },
    {
      "x": -14,
      "y": 2,
      "z": -7,
      "name": "Empty"
    },
    {
      "x": -14,
      "y": 3,
      "z": -7,
      "name": "Empty"
    },
    {
      "x": -14,
      "y": 4,
      "z": -7,
      "name": "Empty"
    },
    {
      "x": -14,
      "y": 5,
      "z": -7,
      "name": "Rock_Marble_Brick_Smooth_Half",
      "rotation": 5
    },
    {
      "x": -14,
      "y": 6,
      "z": -7,
      "name": "Rock_Ice"
    },
    {
      "x": -14,
      "y": 7,
      "z": -7,
      "name": "Empty"
    },
    {
      "x": -14,
      "y": 0,
      "z": -6,
      "name": "Rock_Ice"
    },
    {
      "x": -14,
      "y": 1,
      "z": -6,
      "name": "Rubble_Ice",
      "support": 15
    },
    {
      "x": -14,
      "y": 2,
      "z": -6,
      "name": "Empty"
    },
    {
      "x": -14,
      "y": 3,
      "z": -6,
      "name": "Empty"
    },
    {
      "x": -14,
      "y": 4,
      "z": -6,
      "name": "Empty"
    },
    {
      "x": -14,
      "y": 5,
      "z": -6,
      "name": "Rock_Marble_Brick_Smooth_Half",
      "rotation": 5
    },
    {
      "x": -14,
      "y": 6,
      "z": -6,
      "name": "Rock_Marble_Brick"
    },
    {
      "x": -14,
      "y": 7,
      "z": -6,
      "name": "Empty"
    },
    {
      "x": -14,
      "y": 0,
      "z": -5,
      "name": "Rock_Marble_Brick"
    },
    {
      "x": -14,
      "y": 1,
      "z": -5,
      "name": "Empty"
    },
    {
      "x": -14,
      "y": 2,
      "z": -5,
      "name": "Empty"
    },
    {
      "x": -14,
      "y": 3,
      "z": -5,
      "name": "Empty"
    },
    {
      "x": -14,
      "y": 4,
      "z": -5,
      "name": "Empty"
    },
    {
      "x": -14,
      "y": 5,
      "z": -5,
      "name": "Rock_Marble_Brick_Smooth_Half",
      "rotation": 5
    },
    {
      "x": -14,
      "y": 6,
      "z": -5,
      "name": "Rock_Ice"
    },
    {
      "x": -14,
      "y": 7,
      "z": -5,
      "name": "Empty"
    },
    {
      "x": -14,
      "y": 0,
      "z": -4,
      "name": "Rock_Marble_Brick"
    },
    {
      "x": -14,
      "y": 1,
      "z": -4,
      "name": "Empty"
    },
    {
      "x": -14,
      "y": 2,
      "z": -4,
      "name": "Empty"
    },
    {
      "x": -14,
      "y": 3,
      "z": -4,
      "name": "Empty"
    },
    {
      "x": -14,
      "y": 4,
      "z": -4,
      "name": "Empty"
    },
    {
      "x": -14,
      "y": 5,
      "z": -4,
      "name": "Rock_Marble_Brick_Smooth"
    },
    {
      "x": -14,
      "y": 6,
      "z": -4,
      "name": "Rock_Marble_Brick"
    },
    {
      "x": -14,
      "y": 7,
      "z": -4,
      "name": "Empty"
    },
    {
      "x": -14,
      "y": 0,
      "z": -3,
      "name": "Rock_Calcite_Brick_Smooth"
    },
    {
      "x": -14,
      "y": 1,
      "z": -3,
      "name": "Rock_Calcite_Brick_Ornate"
    },
    {
      "x": -14,
      "y": 2,
      "z": -3,
      "name": "Rock_Calcite_Brick_Smooth"
    },
    {
      "x": -14,
      "y": 3,
      "z": -3,
      "name": "Rock_Calcite_Brick_Smooth"
    },
    {
      "x": -14,
      "y": 4,
      "z": -3,
      "name": "Rock_Calcite_Brick_Ornate"
    },
    {
      "x": -14,
      "y": 5,
      "z": -3,
      "name": "Rock_Calcite_Brick_Smooth"
    },
    {
      "x": -14,
      "y": 6,
      "z": -3,
      "name": "Rock_Marble_Brick"
    },
    {
      "x": -14,
      "y": 7,
      "z": -3,
      "name": "Empty"
    },
    {
      "x": -14,
      "y": 0,
      "z": -2,
      "name": "Rock_Marble_Brick"
    },
    {
      "x": -14,
      "y": 1,
      "z": -2,
      "name": "Empty"
    },
    {
      "x": -14,
      "y": 2,
      "z": -2,
      "name": "Empty"
    },
    {
      "x": -14,
      "y": 3,
      "z": -2,
      "name": "Empty"
    },
    {
      "x": -14,
      "y": 4,
      "z": -2,
      "name": "Empty"
    },
    {
      "x": -14,
      "y": 5,
      "z": -2,
      "name": "Rock_Marble_Brick_Smooth"
    },
    {
      "x": -14,
      "y": 6,
      "z": -2,
      "name": "Rock_Marble_Brick"
    },
    {
      "x": -14,
      "y": 7,
      "z": -2,
      "name": "Empty"
    },
    {
      "x": -14,
      "y": 0,
      "z": -1,
      "name": "Rock_Ice"
    },
    {
      "x": -14,
      "y": 1,
      "z": -1,
      "name": "Rubble_Ice",
      "support": 15
    },
    {
      "x": -14,
      "y": 2,
      "z": -1,
      "name": "Empty"
    },
    {
      "x": -14,
      "y": 3,
      "z": -1,
      "name": "Empty"
    },
    {
      "x": -14,
      "y": 4,
      "z": -1,
      "name": "Empty"
    },
    {
      "x": -14,
      "y": 5,
      "z": -1,
      "name": "Rock_Marble_Brick_Smooth_Half",
      "rotation": 5
    },
    {
      "x": -14,
      "y": 6,
      "z": -1,
      "name": "Rock_Marble_Brick"
    },
    {
      "x": -14,
      "y": 7,
      "z": -1,
      "name": "Empty"
    },
    {
      "x": -14,
      "y": 0,
      "z": 0,
      "name": "Rock_Marble_Brick"
    },
    {
      "x": -14,
      "y": 1,
      "z": 0,
      "name": "Empty"
    },
    {
      "x": -14,
      "y": 2,
      "z": 0,
      "name": "Empty"
    },
    {
      "x": -14,
      "y": 3,
      "z": 0,
      "name": "Empty"
    },
    {
      "x": -14,
      "y": 4,
      "z": 0,
      "name": "Empty"
    },
    {
      "x": -14,
      "y": 5,
      "z": 0,
      "name": "Rock_Marble_Brick_Smooth_Half",
      "rotation": 5
    },
    {
      "x": -14,
      "y": 6,
      "z": 0,
      "name": "Rock_Marble_Brick"
    },
    {
      "x": -14,
      "y": 7,
      "z": 0,
      "name": "Empty"
    },
    {
      "x": -14,
      "y": 0,
      "z": 1,
      "name": "Rock_Marble_Brick"
    },
    {
      "x": -14,
      "y": 1,
      "z": 1,
      "name": "Empty"
    },
    {
      "x": -14,
      "y": 2,
      "z": 1,
      "name": "Empty"
    },
    {
      "x": -14,
      "y": 3,
      "z": 1,
      "name": "Empty"
    },
    {
      "x": -14,
      "y": 4,
      "z": 1,
      "name": "Empty"
    },
    {
      "x": -14,
      "y": 5,
      "z": 1,
      "name": "Rock_Marble_Brick_Smooth_Half",
      "rotation": 5
    },
    {
      "x": -14,
      "y": 6,
      "z": 1,
      "name": "Rock_Marble_Brick"
    },
    {
      "x": -14,
      "y": 7,
      "z": 1,
      "name": "Empty"
    },
    {
      "x": -14,
      "y": 0,
      "z": 2,
      "name": "Rock_Marble_Brick"
    },
    {
      "x": -14,
      "y": 1,
      "z": 2,
      "name": "Empty"
    },
    {
      "x": -14,
      "y": 2,
      "z": 2,
      "name": "Empty"
    },
    {
      "x": -14,
      "y": 3,
      "z": 2,
      "name": "Empty"
    },
    {
      "x": -14,
      "y": 4,
      "z": 2,
      "name": "Empty"
    },
    {
      "x": -14,
      "y": 5,
      "z": 2,
      "name": "Rock_Marble_Brick_Smooth"
    },
    {
      "x": -14,
      "y": 6,
      "z": 2,
      "name": "Rock_Marble_Brick"
    },
    {
      "x": -14,
      "y": 7,
      "z": 2,
      "name": "Empty"
    },
    {
      "x": -14,
      "y": 0,
      "z": 3,
      "name": "Rock_Calcite_Brick_Smooth"
    },
    {
      "x": -14,
      "y": 1,
      "z": 3,
      "name": "Rock_Calcite_Brick_Ornate"
    },
    {
      "x": -14,
      "y": 2,
      "z": 3,
      "name": "Rock_Calcite_Brick_Smooth"
    },
    {
      "x": -14,
      "y": 3,
      "z": 3,
      "name": "Rock_Calcite_Brick_Smooth"
    },
    {
      "x": -14,
      "y": 4,
      "z": 3,
      "name": "Rock_Calcite_Brick_Ornate"
    },
    {
      "x": -14,
      "y": 5,
      "z": 3,
      "name": "Rock_Calcite_Brick_Smooth"
    },
    {
      "x": -14,
      "y": 6,
      "z": 3,
      "name": "Rock_Marble_Brick"
    },
    {
      "x": -14,
      "y": 7,
      "z": 3,
      "name": "Empty"
    },
    {
      "x": -14,
      "y": 0,
      "z": 4,
      "name": "Rock_Marble_Brick"
    },
    {
      "x": -14,
      "y": 1,
      "z": 4,
      "name": "Empty"
    },
    {
      "x": -14,
      "y": 2,
      "z": 4,
      "name": "Empty"
    },
    {
      "x": -14,
      "y": 3,
      "z": 4,
      "name": "Empty"
    },
    {
      "x": -14,
      "y": 4,
      "z": 4,
      "name": "Empty"
    },
    {
      "x": -14,
      "y": 5,
      "z": 4,
      "name": "Rock_Marble_Brick_Smooth"
    },
    {
      "x": -14,
      "y": 6,
      "z": 4,
      "name": "Rock_Marble_Brick"
    },
    {
      "x": -14,
      "y": 7,
      "z": 4,
      "name": "Empty"
    },
    {
      "x": -14,
      "y": 0,
      "z": 5,
      "name": "Rock_Ice"
    },
    {
      "x": -14,
      "y": 1,
      "z": 5,
      "name": "Rubble_Ice",
      "support": 15
    },
    {
      "x": -14,
      "y": 2,
      "z": 5,
      "name": "Empty"
    },
    {
      "x": -14,
      "y": 3,
      "z": 5,
      "name": "Empty"
    },
    {
      "x": -14,
      "y": 4,
      "z": 5,
      "name": "Empty"
    },
    {
      "x": -14,
      "y": 5,
      "z": 5,
      "name": "Rock_Marble_Brick_Smooth_Half",
      "rotation": 5
    },
    {
      "x": -14,
      "y": 6,
      "z": 5,
      "name": "Rock_Marble_Brick"
    },
    {
      "x": -14,
      "y": 7,
      "z": 5,
      "name": "Empty"
    },
    {
      "x": -14,
      "y": 0,
      "z": 6,
      "name": "Rock_Marble_Brick"
    },
    {
      "x": -14,
      "y": 1,
      "z": 6,
      "name": "Empty"
    },
    {
      "x": -14,
      "y": 2,
      "z": 6,
      "name": "Empty"
    },
    {
      "x": -14,
      "y": 3,
      "z": 6,
      "name": "Empty"
    },
    {
      "x": -14,
      "y": 4,
      "z": 6,
      "name": "Empty"
    },
    {
      "x": -14,
      "y": 5,
      "z": 6,
      "name": "Rock_Marble_Brick_Smooth_Half",
      "rotation": 5
    },
    {
      "x": -14,
      "y": 6,
      "z": 6,
      "name": "Rock_Marble_Brick"
    },
    {
      "x": -14,
      "y": 7,
      "z": 6,
      "name": "Empty"
    },
    {
      "x": -14,
      "y": 0,
      "z": 7,
      "name": "Rock_Marble_Brick"
    },
    {
      "x": -14,
      "y": 1,
      "z": 7,
      "name": "Empty"
    },
    {
      "x": -14,
      "y": 2,
      "z": 7,
      "name": "Empty"
    },
    {
      "x": -14,
      "y": 3,
      "z": 7,
      "name": "Empty"
    },
    {
      "x": -14,
      "y": 4,
      "z": 7,
      "name": "Empty"
    },
    {
      "x": -14,
      "y": 5,
      "z": 7,
      "name": "Rock_Marble_Brick_Smooth_Half",
      "rotation": 5
    },
    {
      "x": -14,
      "y": 6,
      "z": 7,
      "name": "Rock_Marble_Brick"
    },
    {
      "x": -14,
      "y": 7,
      "z": 7,
      "name": "Empty"
    },
    {
      "x": -14,
      "y": 0,
      "z": 8,
      "name": "Rock_Marble_Brick"
    },
    {
      "x": -14,
      "y": 1,
      "z": 8,
      "name": "Empty"
    },
    {
      "x": -14,
      "y": 2,
      "z": 8,
      "name": "Empty"
    },
    {
      "x": -14,
      "y": 3,
      "z": 8,
      "name": "Empty"
    },
    {
      "x": -14,
      "y": 4,
      "z": 8,
      "name": "Empty"
    },
    {
      "x": -14,
      "y": 5,
      "z": 8,
      "name": "Rock_Marble_Brick_Smooth"
    },
    {
      "x": -14,
      "y": 6,
      "z": 8,
      "name": "Rock_Ice"
    },
    {
      "x": -14,
      "y": 7,
      "z": 8,
      "name": "Empty"
    },
    {
      "x": -14,
      "y": 0,
      "z": 9,
      "name": "Rock_Marble_Brick",
      "rotation": 2
    },
    {
      "x": -14,
      "y": 1,
      "z": 9,
      "name": "Rock_Calcite_Brick_Ornate",
      "rotation": 2
    },
    {
      "x": -14,
      "y": 2,
      "z": 9,
      "name": "Rock_Calcite_Brick_Smooth",
      "rotation": 2
    },
    {
      "x": -14,
      "y": 3,
      "z": 9,
      "name": "Rock_Calcite_Brick_Smooth",
      "rotation": 2
    },
    {
      "x": -14,
      "y": 4,
      "z": 9,
      "name": "Rock_Calcite_Brick_Ornate",
      "rotation": 2
    },
    {
      "x": -14,
      "y": 5,
      "z": 9,
      "name": "Rock_Calcite_Brick_Smooth",
      "rotation": 2
    },
    {
      "x": -14,
      "y": 6,
      "z": 9,
      "name": "Rock_Ice",
      "rotation": 2
    },
    {
      "x": -14,
      "y": 7,
      "z": 9,
      "name": "Empty"
    },
    {
      "x": -14,
      "y": 0,
      "z": 10,
      "name": "Rock_Ice",
      "rotation": 2
    },
    {
      "x": -14,
      "y": 1,
      "z": 10,
      "name": "Rubble_Ice",
      "support": 15
    },
    {
      "x": -14,
      "y": 2,
      "z": 10,
      "name": "Empty"
    },
    {
      "x": -14,
      "y": 3,
      "z": 10,
      "name": "Empty"
    },
    {
      "x": -14,
      "y": 4,
      "z": 10,
      "name": "Empty"
    },
    {
      "x": -14,
      "y": 5,
      "z": 10,
      "name": "Rock_Marble_Brick_Smooth_Half",
      "rotation": 4
    },
    {
      "x": -14,
      "y": 6,
      "z": 10,
      "name": "Rock_Marble_Brick",
      "rotation": 2
    },
    {
      "x": -14,
      "y": 7,
      "z": 10,
      "name": "Empty"
    },
    {
      "x": -14,
      "y": 0,
      "z": 11,
      "name": "Rock_Marble_Brick",
      "rotation": 2
    },
    {
      "x": -14,
      "y": 1,
      "z": 11,
      "name": "Empty"
    },
    {
      "x": -14,
      "y": 2,
      "z": 11,
      "name": "Empty"
    },
    {
      "x": -14,
      "y": 3,
      "z": 11,
      "name": "Empty"
    },
    {
      "x": -14,
      "y": 4,
      "z": 11,
      "name": "Empty"
    },
    {
      "x": -14,
      "y": 5,
      "z": 11,
      "name": "Empty"
    },
    {
      "x": -14,
      "y": 6,
      "z": 11,
      "name": "Rock_Marble_Brick",
      "rotation": 2
    },
    {
      "x": -14,
      "y": 7,
      "z": 11,
      "name": "Empty"
    },
    {
      "x": -14,
      "y": 0,
      "z": 12,
      "name": "Rock_Marble_Brick",
      "rotation": 2
    },
    {
      "x": -14,
      "y": 1,
      "z": 12,
      "name": "Empty"
    },
    {
      "x": -14,
      "y": 2,
      "z": 12,
      "name": "Empty"
    },
    {
      "x": -14,
      "y": 3,
      "z": 12,
      "name": "Empty"
    },
    {
      "x": -14,
      "y": 4,
      "z": 12,
      "name": "Empty"
    },
    {
      "x": -14,
      "y": 5,
      "z": 12,
      "name": "Empty"
    },
    {
      "x": -14,
      "y": 6,
      "z": 12,
      "name": "Rock_Marble_Brick",
      "rotation": 2
    },
    {
      "x": -14,
      "y": 7,
      "z": 12,
      "name": "Empty"
    },
    {
      "x": -14,
      "y": 0,
      "z": 13,
      "name": "Rock_Marble_Brick",
      "rotation": 2
    },
    {
      "x": -14,
      "y": 1,
      "z": 13,
      "name": "Furniture_Temple_Light_Pot"
    },
    {
      "x": -14,
      "y": 2,
      "z": 13,
      "name": "Empty"
    },
    {
      "x": -14,
      "y": 3,
      "z": 13,
      "name": "Empty"
    },
    {
      "x": -14,
      "y": 4,
      "z": 13,
      "name": "Empty"
    },
    {
      "x": -14,
      "y": 5,
      "z": 13,
      "name": "Rock_Marble_Brick_Smooth_Half",
      "rotation": 6
    },
    {
      "x": -14,
      "y": 6,
      "z": 13,
      "name": "Rock_Ice",
      "rotation": 2
    },
    {
      "x": -14,
      "y": 7,
      "z": 13,
      "name": "Empty"
    },
    {
      "x": -14,
      "y": 0,
      "z": 14,
      "name": "Rock_Marble_Brick",
      "rotation": 2
    },
    {
      "x": -14,
      "y": 1,
      "z": 14,
      "name": "Rock_Marble_Brick_Decorative",
      "rotation": 2
    },
    {
      "x": -14,
      "y": 2,
      "z": 14,
      "name": "Rock_Marble_Brick",
      "rotation": 2
    },
    {
      "x": -14,
      "y": 3,
      "z": 14,
      "name": "Rock_Marble_Brick",
      "rotation": 2
    },
    {
      "x": -14,
      "y": 4,
      "z": 14,
      "name": "Rock_Ice",
      "rotation": 2
    },
    {
      "x": -14,
      "y": 5,
      "z": 14,
      "name": "Rock_Marble_Brick",
      "rotation": 2
    },
    {
      "x": -14,
      "y": 6,
      "z": 14,
      "name": "Rock_Marble_Brick",
      "rotation": 2
    },
    {
      "x": -14,
      "y": 7,
      "z": 14,
      "name": "Empty"
    },
    {
      "x": -14,
      "y": 0,
      "z": 15,
      "name": "Empty"
    },
    {
      "x": -14,
      "y": 1,
      "z": 15,
      "name": "Empty"
    },
    {
      "x": -14,
      "y": 2,
      "z": 15,
      "name": "Empty"
    },
    {
      "x": -14,
      "y": 3,
      "z": 15,
      "name": "Empty"
    },
    {
      "x": -14,
      "y": 4,
      "z": 15,
      "name": "Empty"
    },
    {
      "x": -14,
      "y": 5,
      "z": 15,
      "name": "Empty"
    },
    {
      "x": -14,
      "y": 6,
      "z": 15,
      "name": "Empty"
    },
    {
      "x": -14,
      "y": 7,
      "z": 15,
      "name": "Empty"
    },
    {
      "x": -13,
      "y": 0,
      "z": -14,
      "name": "Rock_Marble_Brick"
    },
    {
      "x": -13,
      "y": 1,
      "z": -14,
      "name": "Rock_Marble_Brick_Decorative"
    },
    {
      "x": -13,
      "y": 2,
      "z": -14,
      "name": "Rock_Marble_Brick"
    },
    {
      "x": -13,
      "y": 3,
      "z": -14,
      "name": "Rock_Ice"
    },
    {
      "x": -13,
      "y": 4,
      "z": -14,
      "name": "Rock_Marble_Brick"
    },
    {
      "x": -13,
      "y": 5,
      "z": -14,
      "name": "Rock_Marble_Brick"
    },
    {
      "x": -13,
      "y": 6,
      "z": -14,
      "name": "Rock_Marble_Brick"
    },
    {
      "x": -13,
      "y": 7,
      "z": -14,
      "name": "Empty"
    },
    {
      "x": -13,
      "y": 0,
      "z": -13,
      "name": "Rock_Marble_Brick"
    },
    {
      "x": -13,
      "y": 1,
      "z": -13,
      "name": "Empty"
    },
    {
      "x": -13,
      "y": 2,
      "z": -13,
      "name": "Empty"
    },
    {
      "x": -13,
      "y": 3,
      "z": -13,
      "name": "Empty"
    },
    {
      "x": -13,
      "y": 4,
      "z": -13,
      "name": "Empty"
    },
    {
      "x": -13,
      "y": 5,
      "z": -13,
      "name": "Rock_Marble_Brick_Smooth_Half",
      "rotation": 4
    },
    {
      "x": -13,
      "y": 6,
      "z": -13,
      "name": "Rock_Ice"
    },
    {
      "x": -13,
      "y": 7,
      "z": -13,
      "name": "Empty"
    },
    {
      "x": -13,
      "y": 0,
      "z": -12,
      "name": "Rock_Marble_Brick"
    },
    {
      "x": -13,
      "y": 1,
      "z": -12,
      "name": "Empty"
    },
    {
      "x": -13,
      "y": 2,
      "z": -12,
      "name": "Empty"
    },
    {
      "x": -13,
      "y": 3,
      "z": -12,
      "name": "Empty"
    },
    {
      "x": -13,
      "y": 4,
      "z": -12,
      "name": "Empty"
    },
    {
      "x": -13,
      "y": 5,
      "z": -12,
      "name": "Empty"
    },
    {
      "x": -13,
      "y": 6,
      "z": -12,
      "name": "Rock_Marble_Brick"
    },
    {
      "x": -13,
      "y": 7,
      "z": -12,
      "name": "Empty"
    },
    {
      "x": -13,
      "y": 0,
      "z": -11,
      "name": "Rock_Marble_Brick"
    },
    {
      "x": -13,
      "y": 1,
      "z": -11,
      "name": "Empty"
    },
    {
      "x": -13,
      "y": 2,
      "z": -11,
      "name": "Empty"
    },
    {
      "x": -13,
      "y": 3,
      "z": -11,
      "name": "Empty"
    },
    {
      "x": -13,
      "y": 4,
      "z": -11,
      "name": "Empty"
    },
    {
      "x": -13,
      "y": 5,
      "z": -11,
      "name": "Empty"
    },
    {
      "x": -13,
      "y": 6,
      "z": -11,
      "name": "Rock_Marble_Brick"
    },
    {
      "x": -13,
      "y": 7,
      "z": -11,
      "name": "Empty"
    },
    {
      "x": -13,
      "y": 0,
      "z": -10,
      "name": "Rock_Ice"
    },
    {
      "x": -13,
      "y": 1,
      "z": -10,
      "name": "Empty"
    },
    {
      "x": -13,
      "y": 2,
      "z": -10,
      "name": "Empty"
    },
    {
      "x": -13,
      "y": 3,
      "z": -10,
      "name": "Empty"
    },
    {
      "x": -13,
      "y": 4,
      "z": -10,
      "name": "Empty"
    },
    {
      "x": -13,
      "y": 5,
      "z": -10,
      "name": "Rock_Marble_Brick_Smooth_Half",
      "rotation": 6
    },
    {
      "x": -13,
      "y": 6,
      "z": -10,
      "name": "Rock_Marble_Brick"
    },
    {
      "x": -13,
      "y": 7,
      "z": -10,
      "name": "Empty"
    },
    {
      "x": -13,
      "y": 0,
      "z": -9,
      "name": "Rock_Calcite_Brick_Smooth"
    },
    {
      "x": -13,
      "y": 1,
      "z": -9,
      "name": "PuzzleBlockSapphireSolid"
    },
    {
      "x": -13,
      "y": 2,
      "z": -9,
      "name": "PuzzleBlockSapphireSolid"
    },
    {
      "x": -13,
      "y": 3,
      "z": -9,
      "name": "PuzzleBlockSapphireSolid"
    },
    {
      "x": -13,
      "y": 4,
      "z": -9,
      "name": "PuzzleBlockSapphireSolid"
    },
    {
      "x": -13,
      "y": 5,
      "z": -9,
      "name": "Rock_Calcite_Brick_Smooth"
    },
    {
      "x": -13,
      "y": 6,
      "z": -9,
      "name": "Rock_Marble_Brick"
    },
    {
      "x": -13,
      "y": 7,
      "z": -9,
      "name": "Empty"
    },
    {
      "x": -13,
      "y": 0,
      "z": -8,
      "name": "Rock_Marble_Brick"
    },
    {
      "x": -13,
      "y": 1,
      "z": -8,
      "name": "Empty"
    },
    {
      "x": -13,
      "y": 2,
      "z": -8,
      "name": "Empty"
    },
    {
      "x": -13,
      "y": 3,
      "z": -8,
      "name": "Empty"
    },
    {
      "x": -13,
      "y": 4,
      "z": -8,
      "name": "Empty"
    },
    {
      "x": -13,
      "y": 5,
      "z": -8,
      "name": "Rock_Marble_Brick_Smooth_Half",
      "rotation": 4
    },
    {
      "x": -13,
      "y": 6,
      "z": -8,
      "name": "Rock_Marble_Brick"
    },
    {
      "x": -13,
      "y": 7,
      "z": -8,
      "name": "Empty"
    },
    {
      "x": -13,
      "y": 0,
      "z": -7,
      "name": "Rock_Marble_Brick"
    },
    {
      "x": -13,
      "y": 1,
      "z": -7,
      "name": "Empty"
    },
    {
      "x": -13,
      "y": 2,
      "z": -7,
      "name": "Empty"
    },
    {
      "x": -13,
      "y": 3,
      "z": -7,
      "name": "Empty"
    },
    {
      "x": -13,
      "y": 4,
      "z": -7,
      "name": "Empty"
    },
    {
      "x": -13,
      "y": 5,
      "z": -7,
      "name": "Empty"
    },
    {
      "x": -13,
      "y": 6,
      "z": -7,
      "name": "Rock_Marble_Brick"
    },
    {
      "x": -13,
      "y": 7,
      "z": -7,
      "name": "Empty"
    },
    {
      "x": -13,
      "y": 0,
      "z": -6,
      "name": "Rock_Marble_Brick"
    },
    {
      "x": -13,
      "y": 1,
      "z": -6,
      "name": "Empty"
    },
    {
      "x": -13,
      "y": 2,
      "z": -6,
      "name": "Empty"
    },
    {
      "x": -13,
      "y": 3,
      "z": -6,
      "name": "Empty"
    },
    {
      "x": -13,
      "y": 4,
      "z": -6,
      "name": "Rock_Ice_Stalactite_Large",
      "filler": 31744,
      "rotation": 8
    },
    {
      "x": -13,
      "y": 5,
      "z": -6,
      "name": "Rock_Ice_Stalactite_Large",
      "rotation": 8
    },
    {
      "x": -13,
      "y": 6,
      "z": -6,
      "name": "Rock_Ice"
    },
    {
      "x": -13,
      "y": 7,
      "z": -6,
      "name": "Empty"
    },
    {
      "x": -13,
      "y": 0,
      "z": -5,
      "name": "Rock_Ice"
    },
    {
      "x": -13,
      "y": 1,
      "z": -5,
      "name": "Rubble_Ice_Medium",
      "support": 15
    },
    {
      "x": -13,
      "y": 2,
      "z": -5,
      "name": "Empty"
    },
    {
      "x": -13,
      "y": 3,
      "z": -5,
      "name": "Empty"
    },
    {
      "x": -13,
      "y": 4,
      "z": -5,
      "name": "Empty"
    },
    {
      "x": -13,
      "y": 5,
      "z": -5,
      "name": "Empty"
    },
    {
      "x": -13,
      "y": 6,
      "z": -5,
      "name": "Rock_Marble_Brick"
    },
    {
      "x": -13,
      "y": 7,
      "z": -5,
      "name": "Empty"
    },
    {
      "x": -13,
      "y": 0,
      "z": -4,
      "name": "Rock_Marble_Brick"
    },
    {
      "x": -13,
      "y": 1,
      "z": -4,
      "name": "Empty"
    },
    {
      "x": -13,
      "y": 2,
      "z": -4,
      "name": "Empty"
    },
    {
      "x": -13,
      "y": 3,
      "z": -4,
      "name": "Empty"
    },
    {
      "x": -13,
      "y": 4,
      "z": -4,
      "name": "Empty"
    },
    {
      "x": -13,
      "y": 5,
      "z": -4,
      "name": "Rock_Marble_Brick_Smooth_Half",
      "rotation": 6
    },
    {
      "x": -13,
      "y": 6,
      "z": -4,
      "name": "Rock_Marble_Brick"
    },
    {
      "x": -13,
      "y": 7,
      "z": -4,
      "name": "Empty"
    },
    {
      "x": -13,
      "y": 0,
      "z": -3,
      "name": "Rock_Calcite_Brick_Smooth"
    },
    {
      "x": -13,
      "y": 1,
      "z": -3,
      "name": "PuzzleBlockSapphireEmpty"
    },
    {
      "x": -13,
      "y": 2,
      "z": -3,
      "name": "PuzzleBlockSapphireEmpty"
    },
    {
      "x": -13,
      "y": 3,
      "z": -3,
      "name": "PuzzleBlockSapphireEmpty"
    },
    {
      "x": -13,
      "y": 4,
      "z": -3,
      "name": "PuzzleBlockSapphireEmpty"
    },
    {
      "x": -13,
      "y": 5,
      "z": -3,
      "name": "Rock_Calcite_Brick_Smooth"
    },
    {
      "x": -13,
      "y": 6,
      "z": -3,
      "name": "Rock_Marble_Brick"
    },
    {
      "x": -13,
      "y": 7,
      "z": -3,
      "name": "Empty"
    },
    {
      "x": -13,
      "y": 0,
      "z": -2,
      "name": "Rock_Marble_Brick"
    },
    {
      "x": -13,
      "y": 1,
      "z": -2,
      "name": "Empty"
    },
    {
      "x": -13,
      "y": 2,
      "z": -2,
      "name": "Empty"
    },
    {
      "x": -13,
      "y": 3,
      "z": -2,
      "name": "Empty"
    },
    {
      "x": -13,
      "y": 4,
      "z": -2,
      "name": "Empty"
    },
    {
      "x": -13,
      "y": 5,
      "z": -2,
      "name": "Rock_Marble_Brick_Smooth_Half",
      "rotation": 4
    },
    {
      "x": -13,
      "y": 6,
      "z": -2,
      "name": "Rock_Marble_Brick"
    },
    {
      "x": -13,
      "y": 7,
      "z": -2,
      "name": "Empty"
    },
    {
      "x": -13,
      "y": 0,
      "z": -1,
      "name": "Rock_Ice"
    },
    {
      "x": -13,
      "y": 1,
      "z": -1,
      "name": "Empty"
    },
    {
      "x": -13,
      "y": 2,
      "z": -1,
      "name": "Empty"
    },
    {
      "x": -13,
      "y": 3,
      "z": -1,
      "name": "Empty"
    },
    {
      "x": -13,
      "y": 4,
      "z": -1,
      "name": "Empty"
    },
    {
      "x": -13,
      "y": 5,
      "z": -1,
      "name": "Empty"
    },
    {
      "x": -13,
      "y": 6,
      "z": -1,
      "name": "Rock_Marble_Brick"
    },
    {
      "x": -13,
      "y": 7,
      "z": -1,
      "name": "Empty"
    },
    {
      "x": -13,
      "y": 0,
      "z": 0,
      "name": "Rock_Marble_Brick"
    },
    {
      "x": -13,
      "y": 1,
      "z": 0,
      "name": "Empty"
    },
    {
      "x": -13,
      "y": 2,
      "z": 0,
      "name": "Empty"
    },
    {
      "x": -13,
      "y": 3,
      "z": 0,
      "name": "Empty"
    },
    {
      "x": -13,
      "y": 4,
      "z": 0,
      "name": "Empty"
    },
    {
      "x": -13,
      "y": 5,
      "z": 0,
      "name": "Rock_Ice_Icicles",
      "rotation": 8
    },
    {
      "x": -13,
      "y": 6,
      "z": 0,
      "name": "Rock_Ice"
    },
    {
      "x": -13,
      "y": 7,
      "z": 0,
      "name": "Empty"
    },
    {
      "x": -13,
      "y": 0,
      "z": 1,
      "name": "Rock_Marble_Brick"
    },
    {
      "x": -13,
      "y": 1,
      "z": 1,
      "name": "Empty"
    },
    {
      "x": -13,
      "y": 2,
      "z": 1,
      "name": "Empty"
    },
    {
      "x": -13,
      "y": 3,
      "z": 1,
      "name": "Empty"
    },
    {
      "x": -13,
      "y": 4,
      "z": 1,
      "name": "Rock_Ice_Stalactite_Large",
      "filler": 31744,
      "rotation": 8
    },
    {
      "x": -13,
      "y": 5,
      "z": 1,
      "name": "Rock_Ice_Stalactite_Large",
      "rotation": 8
    },
    {
      "x": -13,
      "y": 6,
      "z": 1,
      "name": "Rock_Ice"
    },
    {
      "x": -13,
      "y": 7,
      "z": 1,
      "name": "Empty"
    },
    {
      "x": -13,
      "y": 0,
      "z": 2,
      "name": "Rock_Marble_Brick"
    },
    {
      "x": -13,
      "y": 1,
      "z": 2,
      "name": "Empty"
    },
    {
      "x": -13,
      "y": 2,
      "z": 2,
      "name": "Empty"
    },
    {
      "x": -13,
      "y": 3,
      "z": 2,
      "name": "Empty"
    },
    {
      "x": -13,
      "y": 4,
      "z": 2,
      "name": "Empty"
    },
    {
      "x": -13,
      "y": 5,
      "z": 2,
      "name": "Rock_Marble_Brick_Smooth_Half",
      "rotation": 6
    },
    {
      "x": -13,
      "y": 6,
      "z": 2,
      "name": "Rock_Marble_Brick"
    },
    {
      "x": -13,
      "y": 7,
      "z": 2,
      "name": "Empty"
    },
    {
      "x": -13,
      "y": 0,
      "z": 3,
      "name": "Rock_Calcite_Brick_Smooth"
    },
    {
      "x": -13,
      "y": 1,
      "z": 3,
      "name": "PuzzleBlockSapphireSolid"
    },
    {
      "x": -13,
      "y": 2,
      "z": 3,
      "name": "PuzzleBlockSapphireSolid"
    },
    {
      "x": -13,
      "y": 3,
      "z": 3,
      "name": "PuzzleBlockSapphireSolid"
    },
    {
      "x": -13,
      "y": 4,
      "z": 3,
      "name": "PuzzleBlockSapphireSolid"
    },
    {
      "x": -13,
      "y": 5,
      "z": 3,
      "name": "Rock_Calcite_Brick_Smooth"
    },
    {
      "x": -13,
      "y": 6,
      "z": 3,
      "name": "Rock_Marble_Brick"
    },
    {
      "x": -13,
      "y": 7,
      "z": 3,
      "name": "Empty"
    },
    {
      "x": -13,
      "y": 0,
      "z": 4,
      "name": "Rock_Marble_Brick"
    },
    {
      "x": -13,
      "y": 1,
      "z": 4,
      "name": "Empty"
    },
    {
      "x": -13,
      "y": 2,
      "z": 4,
      "name": "Empty"
    },
    {
      "x": -13,
      "y": 3,
      "z": 4,
      "name": "Empty"
    },
    {
      "x": -13,
      "y": 4,
      "z": 4,
      "name": "Empty"
    },
    {
      "x": -13,
      "y": 5,
      "z": 4,
      "name": "Rock_Marble_Brick_Smooth_Half",
      "rotation": 4
    },
    {
      "x": -13,
      "y": 6,
      "z": 4,
      "name": "Rock_Marble_Brick"
    },
    {
      "x": -13,
      "y": 7,
      "z": 4,
      "name": "Empty"
    },
    {
      "x": -13,
      "y": 0,
      "z": 5,
      "name": "Rock_Ice"
    },
    {
      "x": -13,
      "y": 1,
      "z": 5,
      "name": "Empty"
    },
    {
      "x": -13,
      "y": 2,
      "z": 5,
      "name": "Empty"
    },
    {
      "x": -13,
      "y": 3,
      "z": 5,
      "name": "Empty"
    },
    {
      "x": -13,
      "y": 4,
      "z": 5,
      "name": "Rock_Ice_Stalactite_Large",
      "filler": 31744,
      "rotation": 8
    },
    {
      "x": -13,
      "y": 5,
      "z": 5,
      "name": "Rock_Ice_Stalactite_Large",
      "rotation": 8
    },
    {
      "x": -13,
      "y": 6,
      "z": 5,
      "name": "Rock_Ice"
    },
    {
      "x": -13,
      "y": 7,
      "z": 5,
      "name": "Empty"
    },
    {
      "x": -13,
      "y": 0,
      "z": 6,
      "name": "Rock_Marble_Brick"
    },
    {
      "x": -13,
      "y": 1,
      "z": 6,
      "name": "Empty"
    },
    {
      "x": -13,
      "y": 2,
      "z": 6,
      "name": "Empty"
    },
    {
      "x": -13,
      "y": 3,
      "z": 6,
      "name": "Empty"
    },
    {
      "x": -13,
      "y": 4,
      "z": 6,
      "name": "Empty"
    },
    {
      "x": -13,
      "y": 5,
      "z": 6,
      "name": "Empty"
    },
    {
      "x": -13,
      "y": 6,
      "z": 6,
      "name": "Rock_Marble_Brick"
    },
    {
      "x": -13,
      "y": 7,
      "z": 6,
      "name": "Empty"
    },
    {
      "x": -13,
      "y": 0,
      "z": 7,
      "name": "Rock_Marble_Brick"
    },
    {
      "x": -13,
      "y": 1,
      "z": 7,
      "name": "Empty"
    },
    {
      "x": -13,
      "y": 2,
      "z": 7,
      "name": "Empty"
    },
    {
      "x": -13,
      "y": 3,
      "z": 7,
      "name": "Empty"
    },
    {
      "x": -13,
      "y": 4,
      "z": 7,
      "name": "Empty"
    },
    {
      "x": -13,
      "y": 5,
      "z": 7,
      "name": "Empty"
    },
    {
      "x": -13,
      "y": 6,
      "z": 7,
      "name": "Rock_Marble_Brick"
    },
    {
      "x": -13,
      "y": 7,
      "z": 7,
      "name": "Empty"
    },
    {
      "x": -13,
      "y": 0,
      "z": 8,
      "name": "Rock_Ice"
    },
    {
      "x": -13,
      "y": 1,
      "z": 8,
      "name": "Empty"
    },
    {
      "x": -13,
      "y": 2,
      "z": 8,
      "name": "Empty"
    },
    {
      "x": -13,
      "y": 3,
      "z": 8,
      "name": "Empty"
    },
    {
      "x": -13,
      "y": 4,
      "z": 8,
      "name": "Empty"
    },
    {
      "x": -13,
      "y": 5,
      "z": 8,
      "name": "Rock_Marble_Brick_Smooth_Half",
      "rotation": 6
    },
    {
      "x": -13,
      "y": 6,
      "z": 8,
      "name": "Rock_Marble_Brick"
    },
    {
      "x": -13,
      "y": 7,
      "z": 8,
      "name": "Empty"
    },
    {
      "x": -13,
      "y": 0,
      "z": 9,
      "name": "Rock_Calcite_Brick_Smooth",
      "rotation": 2
    },
    {
      "x": -13,
      "y": 1,
      "z": 9,
      "name": "PuzzleBlockSapphireEmpty"
    },
    {
      "x": -13,
      "y": 2,
      "z": 9,
      "name": "PuzzleBlockSapphireEmpty"
    },
    {
      "x": -13,
      "y": 3,
      "z": 9,
      "name": "PuzzleBlockSapphireEmpty"
    },
    {
      "x": -13,
      "y": 4,
      "z": 9,
      "name": "PuzzleBlockSapphireEmpty"
    },
    {
      "x": -13,
      "y": 5,
      "z": 9,
      "name": "Rock_Calcite_Brick_Smooth",
      "rotation": 2
    },
    {
      "x": -13,
      "y": 6,
      "z": 9,
      "name": "Rock_Marble_Brick",
      "rotation": 2
    },
    {
      "x": -13,
      "y": 7,
      "z": 9,
      "name": "Empty"
    },
    {
      "x": -13,
      "y": 0,
      "z": 10,
      "name": "Rock_Marble_Brick",
      "rotation": 2
    },
    {
      "x": -13,
      "y": 1,
      "z": 10,
      "name": "Empty"
    },
    {
      "x": -13,
      "y": 2,
      "z": 10,
      "name": "Empty"
    },
    {
      "x": -13,
      "y": 3,
      "z": 10,
      "name": "Empty"
    },
    {
      "x": -13,
      "y": 4,
      "z": 10,
      "name": "Empty"
    },
    {
      "x": -13,
      "y": 5,
      "z": 10,
      "name": "Rock_Marble_Brick_Smooth_Half",
      "rotation": 4
    },
    {
      "x": -13,
      "y": 6,
      "z": 10,
      "name": "Rock_Marble_Brick",
      "rotation": 2
    },
    {
      "x": -13,
      "y": 7,
      "z": 10,
      "name": "Empty"
    },
    {
      "x": -13,
      "y": 0,
      "z": 11,
      "name": "Rock_Ice",
      "rotation": 2
    },
    {
      "x": -13,
      "y": 1,
      "z": 11,
      "name": "Empty"
    },
    {
      "x": -13,
      "y": 2,
      "z": 11,
      "name": "Empty"
    },
    {
      "x": -13,
      "y": 3,
      "z": 11,
      "name": "Empty"
    },
    {
      "x": -13,
      "y": 4,
      "z": 11,
      "name": "Empty"
    },
    {
      "x": -13,
      "y": 5,
      "z": 11,
      "name": "Empty"
    },
    {
      "x": -13,
      "y": 6,
      "z": 11,
      "name": "Rock_Marble_Brick",
      "rotation": 2
    },
    {
      "x": -13,
      "y": 7,
      "z": 11,
      "name": "Empty"
    },
    {
      "x": -13,
      "y": 0,
      "z": 12,
      "name": "Rock_Ice",
      "rotation": 2
    },
    {
      "x": -13,
      "y": 1,
      "z": 12,
      "name": "Empty"
    },
    {
      "x": -13,
      "y": 2,
      "z": 12,
      "name": "Empty"
    },
    {
      "x": -13,
      "y": 3,
      "z": 12,
      "name": "Empty"
    },
    {
      "x": -13,
      "y": 4,
      "z": 12,
      "name": "Empty"
    },
    {
      "x": -13,
      "y": 5,
      "z": 12,
      "name": "Empty"
    },
    {
      "x": -13,
      "y": 6,
      "z": 12,
      "name": "Rock_Marble_Brick",
      "rotation": 2
    },
    {
      "x": -13,
      "y": 7,
      "z": 12,
      "name": "Empty"
    },
    {
      "x": -13,
      "y": 0,
      "z": 13,
      "name": "Rock_Marble_Brick",
      "rotation": 2
    },
    {
      "x": -13,
      "y": 1,
      "z": 13,
      "name": "Empty"
    },
    {
      "x": -13,
      "y": 2,
      "z": 13,
      "name": "Empty"
    },
    {
      "x": -13,
      "y": 3,
      "z": 13,
      "name": "Empty"
    },
    {
      "x": -13,
      "y": 4,
      "z": 13,
      "name": "Empty"
    },
    {
      "x": -13,
      "y": 5,
      "z": 13,
      "name": "Rock_Marble_Brick_Smooth_Half",
      "rotation": 6
    },
    {
      "x": -13,
      "y": 6,
      "z": 13,
      "name": "Rock_Ice",
      "rotation": 2
    },
    {
      "x": -13,
      "y": 7,
      "z": 13,
      "name": "Empty"
    },
    {
      "x": -13,
      "y": 0,
      "z": 14,
      "name": "Rock_Marble_Brick",
      "rotation": 2
    },
    {
      "x": -13,
      "y": 1,
      "z": 14,
      "name": "Rock_Marble_Brick_Decorative",
      "rotation": 2
    },
    {
      "x": -13,
      "y": 2,
      "z": 14,
      "name": "Rock_Marble_Brick",
      "rotation": 2
    },
    {
      "x": -13,
      "y": 3,
      "z": 14,
      "name": "Rock_Marble_Brick",
      "rotation": 2
    },
    {
      "x": -13,
      "y": 4,
      "z": 14,
      "name": "Rock_Marble_Brick",
      "rotation": 2
    },
    {
      "x": -13,
      "y": 5,
      "z": 14,
      "name": "Rock_Marble_Brick",
      "rotation": 2
    },
    {
      "x": -13,
      "y": 6,
      "z": 14,
      "name": "Rock_Marble_Brick",
      "rotation": 2
    },
    {
      "x": -13,
      "y": 7,
      "z": 14,
      "name": "Empty"
    },
    {
      "x": -13,
      "y": 0,
      "z": 15,
      "name": "Empty"
    },
    {
      "x": -13,
      "y": 1,
      "z": 15,
      "name": "Empty"
    },
    {
      "x": -13,
      "y": 2,
      "z": 15,
      "name": "Empty"
    },
    {
      "x": -13,
      "y": 3,
      "z": 15,
      "name": "Empty"
    },
    {
      "x": -13,
      "y": 4,
      "z": 15,
      "name": "Empty"
    },
    {
      "x": -13,
      "y": 5,
      "z": 15,
      "name": "Empty"
    },
    {
      "x": -13,
      "y": 6,
      "z": 15,
      "name": "Empty"
    },
    {
      "x": -13,
      "y": 7,
      "z": 15,
      "name": "Empty"
    },
    {
      "x": -12,
      "y": 0,
      "z": -14,
      "name": "Rock_Marble_Brick"
    },
    {
      "x": -12,
      "y": 1,
      "z": -14,
      "name": "Rock_Marble_Brick_Decorative"
    },
    {
      "x": -12,
      "y": 2,
      "z": -14,
      "name": "Rock_Marble_Brick"
    },
    {
      "x": -12,
      "y": 3,
      "z": -14,
      "name": "Rock_Marble_Brick"
    },
    {
      "x": -12,
      "y": 4,
      "z": -14,
      "name": "Rock_Ice"
    },
    {
      "x": -12,
      "y": 5,
      "z": -14,
      "name": "Rock_Marble_Brick"
    },
    {
      "x": -12,
      "y": 6,
      "z": -14,
      "name": "Rock_Marble_Brick"
    },
    {
      "x": -12,
      "y": 7,
      "z": -14,
      "name": "Empty"
    },
    {
      "x": -12,
      "y": 0,
      "z": -13,
      "name": "Rock_Marble_Brick"
    },
    {
      "x": -12,
      "y": 1,
      "z": -13,
      "name": "Rock_Marble_Brick_Pillar_Base"
    },
    {
      "x": -12,
      "y": 2,
      "z": -13,
      "name": "Furniture_Temple_Light_Lantern"
    },
    {
      "x": -12,
      "y": 3,
      "z": -13,
      "name": "Empty"
    },
    {
      "x": -12,
      "y": 4,
      "z": -13,
      "name": "Empty"
    },
    {
      "x": -12,
      "y": 5,
      "z": -13,
      "name": "Rock_Marble_Brick_Smooth_Half",
      "rotation": 4
    },
    {
      "x": -12,
      "y": 6,
      "z": -13,
      "name": "Rock_Ice"
    },
    {
      "x": -12,
      "y": 7,
      "z": -13,
      "name": "Empty"
    },
    {
      "x": -12,
      "y": 0,
      "z": -12,
      "name": "Rock_Ice"
    },
    {
      "x": -12,
      "y": 1,
      "z": -12,
      "name": "Empty"
    },
    {
      "x": -12,
      "y": 2,
      "z": -12,
      "name": "Empty"
    },
    {
      "x": -12,
      "y": 3,
      "z": -12,
      "name": "Empty"
    },
    {
      "x": -12,
      "y": 4,
      "z": -12,
      "name": "Rock_Ice_Stalactite_Large",
      "filler": 31744,
      "rotation": 8
    },
    {
      "x": -12,
      "y": 5,
      "z": -12,
      "name": "Rock_Ice_Stalactite_Large",
      "rotation": 8
    },
    {
      "x": -12,
      "y": 6,
      "z": -12,
      "name": "Rock_Ice"
    },
    {
      "x": -12,
      "y": 7,
      "z": -12,
      "name": "Empty"
    },
    {
      "x": -12,
      "y": 0,
      "z": -11,
      "name": "Rock_Marble_Brick"
    },
    {
      "x": -12,
      "y": 1,
      "z": -11,
      "name": "Empty"
    },
    {
      "x": -12,
      "y": 2,
      "z": -11,
      "name": "Empty"
    },
    {
      "x": -12,
      "y": 3,
      "z": -11,
      "name": "Empty"
    },
    {
      "x": -12,
      "y": 4,
      "z": -11,
      "name": "Empty"
    },
    {
      "x": -12,
      "y": 5,
      "z": -11,
      "name": "Rock_Ice_Icicles",
      "rotation": 8
    },
    {
      "x": -12,
      "y": 6,
      "z": -11,
      "name": "Rock_Ice"
    },
    {
      "x": -12,
      "y": 7,
      "z": -11,
      "name": "Empty"
    },
    {
      "x": -12,
      "y": 0,
      "z": -10,
      "name": "Rock_Marble_Brick"
    },
    {
      "x": -12,
      "y": 1,
      "z": -10,
      "name": "Empty"
    },
    {
      "x": -12,
      "y": 2,
      "z": -10,
      "name": "Empty"
    },
    {
      "x": -12,
      "y": 3,
      "z": -10,
      "name": "Empty"
    },
    {
      "x": -12,
      "y": 4,
      "z": -10,
      "name": "Empty"
    },
    {
      "x": -12,
      "y": 5,
      "z": -10,
      "name": "Rock_Marble_Brick_Smooth_Half",
      "rotation": 6
    },
    {
      "x": -12,
      "y": 6,
      "z": -10,
      "name": "Rock_Marble_Brick"
    },
    {
      "x": -12,
      "y": 7,
      "z": -10,
      "name": "Empty"
    },
    {
      "x": -12,
      "y": 0,
      "z": -9,
      "name": "Rock_Calcite_Brick_Decorative"
    },
    {
      "x": -12,
      "y": 1,
      "z": -9,
      "name": "PuzzleBlockSapphireSolid"
    },
    {
      "x": -12,
      "y": 2,
      "z": -9,
      "name": "PuzzleBlockSapphireSolid"
    },
    {
      "x": -12,
      "y": 3,
      "z": -9,
      "name": "PuzzleBlockSapphireSolid"
    },
    {
      "x": -12,
      "y": 4,
      "z": -9,
      "name": "PuzzleBlockSapphireSolid"
    },
    {
      "x": -12,
      "y": 5,
      "z": -9,
      "name": "Rock_Calcite_Brick_Decorative"
    },
    {
      "x": -12,
      "y": 6,
      "z": -9,
      "name": "Rock_Marble_Brick"
    },
    {
      "x": -12,
      "y": 7,
      "z": -9,
      "name": "Empty"
    },
    {
      "x": -12,
      "y": 0,
      "z": -8,
      "name": "Rock_Ice"
    },
    {
      "x": -12,
      "y": 1,
      "z": -8,
      "name": "Empty"
    },
    {
      "x": -12,
      "y": 2,
      "z": -8,
      "name": "Empty"
    },
    {
      "x": -12,
      "y": 3,
      "z": -8,
      "name": "Empty"
    },
    {
      "x": -12,
      "y": 4,
      "z": -8,
      "name": "Empty"
    },
    {
      "x": -12,
      "y": 5,
      "z": -8,
      "name": "Rock_Marble_Brick_Smooth_Half",
      "rotation": 4
    },
    {
      "x": -12,
      "y": 6,
      "z": -8,
      "name": "Rock_Marble_Brick"
    },
    {
      "x": -12,
      "y": 7,
      "z": -8,
      "name": "Empty"
    },
    {
      "x": -12,
      "y": 0,
      "z": -7,
      "name": "Rock_Ice"
    },
    {
      "x": -12,
      "y": 1,
      "z": -7,
      "name": "Empty"
    },
    {
      "x": -12,
      "y": 2,
      "z": -7,
      "name": "Empty"
    },
    {
      "x": -12,
      "y": 3,
      "z": -7,
      "name": "Empty"
    },
    {
      "x": -12,
      "y": 4,
      "z": -7,
      "name": "Empty"
    },
    {
      "x": -12,
      "y": 5,
      "z": -7,
      "name": "Empty"
    },
    {
      "x": -12,
      "y": 6,
      "z": -7,
      "name": "Rock_Marble_Brick"
    },
    {
      "x": -12,
      "y": 7,
      "z": -7,
      "name": "Empty"
    },
    {
      "x": -12,
      "y": 0,
      "z": -6,
      "name": "Rock_Marble_Brick_Ornate"
    },
    {
      "x": -12,
      "y": 1,
      "z": -6,
      "name": "Furniture_Temple_Light_Chest_Small",
      "components": {
        "Components": {
          "container": {
            "Position": {
              "X": 3,
              "Y": 85,
              "Z": 3
            },
            "Custom": false,
            "AllowViewing": true,
            "ItemContainer": {
              "Capacity": 18,
              "Items": {
                "0": {
                  "Id": "Potion_Empty_Small",
                  "Quantity": 2,
                  "Durability": 0.0,
                  "MaxDurability": 0.0,
                  "OverrideDroppedItemAnimation": false
                },
                "1": {
                  "Id": "Potion_Signature_Greater",
                  "Quantity": 1,
                  "Durability": 0.0,
                  "MaxDurability": 0.0,
                  "OverrideDroppedItemAnimation": false
                }
              }
            }
          }
        }
      },
      "rotation": 2
    },
    {
      "x": -12,
      "y": 2,
      "z": -6,
      "name": "Empty"
    },
    {
      "x": -12,
      "y": 3,
      "z": -6,
      "name": "Empty"
    },
    {
      "x": -12,
      "y": 4,
      "z": -6,
      "name": "Empty"
    },
    {
      "x": -12,
      "y": 5,
      "z": -6,
      "name": "Furniture_Temple_Light_Lantern_Ceiling"
    },
    {
      "x": -12,
      "y": 6,
      "z": -6,
      "name": "Rock_Marble_Brick"
    },
    {
      "x": -12,
      "y": 7,
      "z": -6,
      "name": "Empty"
    },
    {
      "x": -12,
      "y": 0,
      "z": -5,
      "name": "Rock_Marble_Brick"
    },
    {
      "x": -12,
      "y": 1,
      "z": -5,
      "name": "Empty"
    },
    {
      "x": -12,
      "y": 2,
      "z": -5,
      "name": "Empty"
    },
    {
      "x": -12,
      "y": 3,
      "z": -5,
      "name": "Empty"
    },
    {
      "x": -12,
      "y": 4,
      "z": -5,
      "name": "Rock_Ice_Stalactite_Large",
      "filler": 31744,
      "rotation": 8
    },
    {
      "x": -12,
      "y": 5,
      "z": -5,
      "name": "Rock_Ice_Stalactite_Large",
      "rotation": 8
    },
    {
      "x": -12,
      "y": 6,
      "z": -5,
      "name": "Rock_Ice"
    },
    {
      "x": -12,
      "y": 7,
      "z": -5,
      "name": "Empty"
    },
    {
      "x": -12,
      "y": 0,
      "z": -4,
      "name": "Rock_Marble_Brick"
    },
    {
      "x": -12,
      "y": 1,
      "z": -4,
      "name": "Empty"
    },
    {
      "x": -12,
      "y": 2,
      "z": -4,
      "name": "Empty"
    },
    {
      "x": -12,
      "y": 3,
      "z": -4,
      "name": "Empty"
    },
    {
      "x": -12,
      "y": 4,
      "z": -4,
      "name": "Empty"
    },
    {
      "x": -12,
      "y": 5,
      "z": -4,
      "name": "Rock_Marble_Brick_Smooth_Half",
      "rotation": 6
    },
    {
      "x": -12,
      "y": 6,
      "z": -4,
      "name": "Rock_Marble_Brick"
    },
    {
      "x": -12,
      "y": 7,
      "z": -4,
      "name": "Empty"
    },
    {
      "x": -12,
      "y": 0,
      "z": -3,
      "name": "Rock_Calcite_Brick_Decorative"
    },
    {
      "x": -12,
      "y": 1,
      "z": -3,
      "name": "PuzzleBlockSapphireEmpty"
    },
    {
      "x": -12,
      "y": 2,
      "z": -3,
      "name": "PuzzleBlockSapphireEmpty"
    },
    {
      "x": -12,
      "y": 3,
      "z": -3,
      "name": "PuzzleBlockSapphireEmpty"
    },
    {
      "x": -12,
      "y": 4,
      "z": -3,
      "name": "PuzzleBlockSapphireEmpty"
    },
    {
      "x": -12,
      "y": 5,
      "z": -3,
      "name": "Rock_Calcite_Brick_Ornate"
    },
    {
      "x": -12,
      "y": 6,
      "z": -3,
      "name": "Rock_Marble_Brick"
    },
    {
      "x": -12,
      "y": 7,
      "z": -3,
      "name": "Empty"
    },
    {
      "x": -12,
      "y": 0,
      "z": -2,
      "name": "Rock_Ice"
    },
    {
      "x": -12,
      "y": 1,
      "z": -2,
      "name": "Empty"
    },
    {
      "x": -12,
      "y": 2,
      "z": -2,
      "name": "Empty"
    },
    {
      "x": -12,
      "y": 3,
      "z": -2,
      "name": "Empty"
    },
    {
      "x": -12,
      "y": 4,
      "z": -2,
      "name": "Empty"
    },
    {
      "x": -12,
      "y": 5,
      "z": -2,
      "name": "Rock_Marble_Brick_Smooth_Half",
      "rotation": 4
    },
    {
      "x": -12,
      "y": 6,
      "z": -2,
      "name": "Rock_Marble_Brick"
    },
    {
      "x": -12,
      "y": 7,
      "z": -2,
      "name": "Empty"
    },
    {
      "x": -12,
      "y": 0,
      "z": -1,
      "name": "Rock_Marble_Brick"
    },
    {
      "x": -12,
      "y": 1,
      "z": -1,
      "name": "Empty"
    },
    {
      "x": -12,
      "y": 2,
      "z": -1,
      "name": "Empty"
    },
    {
      "x": -12,
      "y": 3,
      "z": -1,
      "name": "Empty"
    },
    {
      "x": -12,
      "y": 4,
      "z": -1,
      "name": "Empty"
    },
    {
      "x": -12,
      "y": 5,
      "z": -1,
      "name": "Rock_Ice_Icicles",
      "rotation": 8
    },
    {
      "x": -12,
      "y": 6,
      "z": -1,
      "name": "Rock_Ice"
    },
    {
      "x": -12,
      "y": 7,
      "z": -1,
      "name": "Empty"
    },
    {
      "x": -12,
      "y": 0,
      "z": 0,
      "name": "Rock_Marble_Brick_Ornate"
    },
    {
      "x": -12,
      "y": 1,
      "z": 0,
      "name": "Empty"
    },
    {
      "x": -12,
      "y": 2,
      "z": 0,
      "name": "Empty"
    },
    {
      "x": -12,
      "y": 3,
      "z": 0,
      "name": "Empty"
    },
    {
      "x": -12,
      "y": 4,
      "z": 0,
      "name": "Empty"
    },
    {
      "x": -12,
      "y": 5,
      "z": 0,
      "name": "Furniture_Temple_Light_Lantern_Ceiling"
    },
    {
      "x": -12,
      "y": 6,
      "z": 0,
      "name": "Rock_Marble_Brick"
    },
    {
      "x": -12,
      "y": 7,
      "z": 0,
      "name": "Empty"
    },
    {
      "x": -12,
      "y": 0,
      "z": 1,
      "name": "Rock_Marble_Brick"
    },
    {
      "x": -12,
      "y": 1,
      "z": 1,
      "name": "Empty"
    },
    {
      "x": -12,
      "y": 2,
      "z": 1,
      "name": "Empty"
    },
    {
      "x": -12,
      "y": 3,
      "z": 1,
      "name": "Empty"
    },
    {
      "x": -12,
      "y": 4,
      "z": 1,
      "name": "Empty"
    },
    {
      "x": -12,
      "y": 5,
      "z": 1,
      "name": "Empty"
    },
    {
      "x": -12,
      "y": 6,
      "z": 1,
      "name": "Rock_Marble_Brick"
    },
    {
      "x": -12,
      "y": 7,
      "z": 1,
      "name": "Empty"
    },
    {
      "x": -12,
      "y": 0,
      "z": 2,
      "name": "Rock_Marble_Brick"
    },
    {
      "x": -12,
      "y": 1,
      "z": 2,
      "name": "Empty"
    },
    {
      "x": -12,
      "y": 2,
      "z": 2,
      "name": "Empty"
    },
    {
      "x": -12,
      "y": 3,
      "z": 2,
      "name": "Empty"
    },
    {
      "x": -12,
      "y": 4,
      "z": 2,
      "name": "Empty"
    },
    {
      "x": -12,
      "y": 5,
      "z": 2,
      "name": "Rock_Marble_Brick_Smooth_Half",
      "rotation": 6
    },
    {
      "x": -12,
      "y": 6,
      "z": 2,
      "name": "Rock_Ice"
    },
    {
      "x": -12,
      "y": 7,
      "z": 2,
      "name": "Empty"
    },
    {
      "x": -12,
      "y": 0,
      "z": 3,
