{
  "version": 8,
  "blockIdVersion": 11,
  "anchorX": 0,
  "anchorY": 0,
  "anchorZ": 0,
  "blocks": [
    {
      "x": -16,
      "y": 0,
      "z": -14,
      "name": "Cloth_Block_Wool_Red"
    },
    {
      "x": -16,
      "y": 1,
      "z": -14,
      "name": "Rock_Marble_Brick"
    },
    {
      "x": -16,
      "y": 2,
      "z": -14,
      "name": "Rock_Marble_Brick"
    },
    {
      "x": -16,
      "y": 3,
      "z": -14,
      "name": "Rock_Marble_Brick"
    },
    {
      "x": -16,
      "y": 4,
      "z": -14,
      "name": "Rock_Marble_Brick"
    },
    {
      "x": -16,
      "y": 5,
      "z": -14,
      "name": "Rock_Ice"
    },
    {
      "x": -16,
      "y": 6,
      "z": -14,
      "name": "Rock_Marble_Brick"
    },
    {
      "x": -16,
      "y": 7,
      "z": -14,
      "name": "Rock_Ice"
    },
    {
      "x": -16,
      "y": 8,
      "z": -14,
      "name": "Rock_Ice"
    },
    {
      "x": -16,
      "y": 9,
      "z": -14,
      "name": "Rock_Marble_Brick"
    },
    {
      "x": -16,
      "y": 10,
      "z": -14,
      "name": "Rock_Marble_Brick"
    },
    {
      "x": -16,
      "y": 11,
      "z": -14,
      "name": "Cloth_Block_Wool_Red"
    },
    {
      "x": -16,
      "y": 0,
      "z": -13,
      "name": "Rock_Marble_Brick"
    },
    {
      "x": -16,
      "y": 1,
      "z": -13,
      "name": "Rock_Marble_Brick"
    },
    {
      "x": -16,
      "y": 2,
      "z": -13,
      "name": "Rock_Marble_Brick"
    },
    {
      "x": -16,
      "y": 3,
      "z": -13,
      "name": "Rock_Marble_Brick"
    },
    {
      "x": -16,
      "y": 4,
      "z": -13,
      "name": "Rock_Marble_Brick"
    },
    {
      "x": -16,
      "y": 5,
      "z": -13,
      "name": "Rock_Marble_Brick_Decorative"
    },
    {
      "x": -16,
      "y": 6,
      "z": -13,
      "name": "Rock_Marble_Brick"
    },
    {
      "x": -16,
      "y": 7,
      "z": -13,
      "name": "Rock_Marble_Brick"
    },
    {
      "x": -16,
      "y": 8,
      "z": -13,
      "name": "Rock_Marble_Brick"
    },
    {
      "x": -16,
      "y": 9,
      "z": -13,
      "name": "Rock_Marble_Brick"
    },
    {
      "x": -16,
      "y": 10,
      "z": -13,
      "name": "Rock_Marble_Brick"
    },
    {
      "x": -16,
      "y": 11,
      "z": -13,
      "name": "Empty"
    },
    {
      "x": -16,
      "y": 0,
      "z": -12,
      "name": "Rock_Marble_Brick"
    },
    {
      "x": -16,
      "y": 1,
      "z": -12,
      "name": "Rock_Marble_Brick"
    },
    {
      "x": -16,
      "y": 2,
      "z": -12,
      "name": "Rock_Marble_Brick"
    },
    {
      "x": -16,
      "y": 3,
      "z": -12,
      "name": "Rock_Marble_Brick"
    },
    {
      "x": -16,
      "y": 4,
      "z": -12,
      "name": "Rock_Marble_Brick"
    },
    {
      "x": -16,
      "y": 5,
      "z": -12,
      "name": "Rock_Marble_Brick_Decorative"
    },
    {
      "x": -16,
      "y": 6,
      "z": -12,
      "name": "Rock_Ice"
    },
    {
      "x": -16,
      "y": 7,
      "z": -12,
      "name": "Rock_Marble_Brick"
    },
    {
      "x": -16,
      "y": 8,
      "z": -12,
      "name": "Rock_Marble_Brick"
    },
    {
      "x": -16,
      "y": 9,
      "z": -12,
      "name": "Rock_Marble_Brick"
    },
    {
      "x": -16,
      "y": 10,
      "z": -12,
      "name": "Rock_Marble_Brick"
    },
    {
      "x": -16,
      "y": 11,
      "z": -12,
      "name": "Empty"
    },
    {
      "x": -16,
      "y": 0,
      "z": -11,
      "name": "Rock_Marble_Brick"
    },
    {
      "x": -16,
      "y": 1,
      "z": -11,
      "name": "Rock_Marble_Brick"
    },
    {
      "x": -16,
      "y": 2,
      "z": -11,
      "name": "Rock_Marble_Brick"
    },
    {
      "x": -16,
      "y": 3,
      "z": -11,
      "name": "Rock_Marble_Brick"
    },
    {
      "x": -16,
      "y": 4,
      "z": -11,
      "name": "Rock_Marble_Brick"
    },
    {
      "x": -16,
      "y": 5,
      "z": -11,
      "name": "Rock_Marble_Brick_Decorative"
    },
    {
      "x": -16,
      "y": 6,
      "z": -11,
      "name": "Rock_Marble_Brick"
    },
    {
      "x": -16,
      "y": 7,
      "z": -11,
      "name": "Rock_Ice"
    },
    {
      "x": -16,
      "y": 8,
      "z": -11,
      "name": "Rock_Marble_Brick"
    },
    {
      "x": -16,
      "y": 9,
      "z": -11,
      "name": "Rock_Marble_Brick"
    },
    {
      "x": -16,
      "y": 10,
      "z": -11,
      "name": "Rock_Marble_Brick"
    },
    {
      "x": -16,
      "y": 11,
      "z": -11,
      "name": "Empty"
    },
    {
      "x": -16,
      "y": 0,
      "z": -10,
      "name": "Rock_Marble_Brick"
    },
    {
      "x": -16,
      "y": 1,
      "z": -10,
      "name": "Rock_Marble_Brick"
    },
    {
      "x": -16,
      "y": 2,
      "z": -10,
      "name": "Rock_Marble_Brick"
    },
    {
      "x": -16,
      "y": 3,
      "z": -10,
      "name": "Rock_Marble_Brick"
    },
    {
      "x": -16,
      "y": 4,
      "z": -10,
      "name": "Rock_Marble_Brick"
    },
    {
      "x": -16,
      "y": 5,
      "z": -10,
      "name": "Rock_Marble_Brick_Decorative"
    },
    {
      "x": -16,
      "y": 6,
      "z": -10,
      "name": "Rock_Marble_Brick"
    },
    {
      "x": -16,
      "y": 7,
      "z": -10,
      "name": "Rock_Marble_Brick"
    },
    {
      "x": -16,
      "y": 8,
      "z": -10,
      "name": "Rock_Marble_Brick"
    },
    {
      "x": -16,
      "y": 9,
      "z": -10,
      "name": "Rock_Ice"
    },
    {
      "x": -16,
      "y": 10,
      "z": -10,
      "name": "Rock_Marble_Brick"
    },
    {
      "x": -16,
      "y": 11,
      "z": -10,
      "name": "Empty"
    },
    {
      "x": -16,
      "y": 0,
      "z": -9,
      "name": "Rock_Marble_Brick"
    },
    {
      "x": -16,
      "y": 1,
      "z": -9,
      "name": "Rock_Marble_Brick"
    },
    {
      "x": -16,
      "y": 2,
      "z": -9,
      "name": "Rock_Marble_Brick"
    },
    {
      "x": -16,
      "y": 3,
      "z": -9,
      "name": "Rock_Marble_Brick"
    },
    {
      "x": -16,
      "y": 4,
      "z": -9,
      "name": "Rock_Marble_Brick"
    },
    {
      "x": -16,
      "y": 5,
      "z": -9,
      "name": "Rock_Marble_Brick"
    },
    {
      "x": -16,
      "y": 6,
      "z": -9,
      "name": "Rock_Marble_Brick"
    },
    {
      "x": -16,
      "y": 7,
      "z": -9,
      "name": "Rock_Marble_Brick"
    },
    {
      "x": -16,
      "y": 8,
      "z": -9,
      "name": "Rock_Ice"
    },
    {
      "x": -16,
      "y": 9,
      "z": -9,
      "name": "Rock_Ice"
    },
    {
      "x": -16,
      "y": 10,
      "z": -9,
      "name": "Rock_Ice"
    },
    {
      "x": -16,
      "y": 11,
      "z": -9,
      "name": "Empty"
    },
    {
      "x": -16,
      "y": 0,
      "z": -8,
      "name": "Rock_Marble_Brick"
    },
    {
      "x": -16,
      "y": 1,
      "z": -8,
      "name": "Rock_Marble_Brick"
    },
    {
      "x": -16,
      "y": 2,
      "z": -8,
      "name": "Rock_Marble_Brick"
    },
    {
      "x": -16,
      "y": 3,
      "z": -8,
      "name": "Rock_Marble_Brick"
    },
    {
      "x": -16,
      "y": 4,
      "z": -8,
      "name": "Empty"
    },
    {
      "x": -16,
      "y": 5,
      "z": -8,
      "name": "Empty"
    },
    {
      "x": -16,
      "y": 6,
      "z": -8,
      "name": "Empty"
    },
    {
      "x": -16,
      "y": 7,
      "z": -8,
      "name": "Empty"
    },
    {
      "x": -16,
      "y": 8,
      "z": -8,
      "name": "Empty"
    },
    {
      "x": -16,
      "y": 9,
      "z": -8,
      "name": "Empty"
    },
    {
      "x": -16,
      "y": 10,
      "z": -8,
      "name": "Empty"
    },
    {
      "x": -16,
      "y": 11,
      "z": -8,
      "name": "Empty"
    },
    {
      "x": -16,
      "y": 0,
      "z": -7,
      "name": "Rock_Marble_Brick"
    },
    {
      "x": -16,
      "y": 1,
      "z": -7,
      "name": "Rock_Marble_Brick"
    },
    {
      "x": -16,
      "y": 2,
      "z": -7,
      "name": "Rock_Marble_Brick"
    },
    {
      "x": -16,
      "y": 3,
      "z": -7,
      "name": "Rock_Marble_Brick"
    },
    {
      "x": -16,
      "y": 4,
      "z": -7,
      "name": "Empty"
    },
    {
      "x": -16,
      "y": 5,
      "z": -7,
      "name": "Empty"
    },
    {
      "x": -16,
      "y": 6,
      "z": -7,
      "name": "Empty"
    },
    {
      "x": -16,
      "y": 7,
      "z": -7,
      "name": "Empty"
    },
    {
      "x": -16,
      "y": 8,
      "z": -7,
      "name": "Empty"
    },
    {
      "x": -16,
      "y": 9,
      "z": -7,
      "name": "Empty"
    },
    {
      "x": -16,
      "y": 10,
      "z": -7,
      "name": "Empty"
    },
    {
      "x": -16,
      "y": 11,
      "z": -7,
      "name": "Empty"
    },
    {
      "x": -16,
      "y": 0,
      "z": -6,
      "name": "Rock_Marble_Brick"
    },
    {
      "x": -16,
      "y": 1,
      "z": -6,
      "name": "Rock_Marble_Brick"
    },
    {
      "x": -16,
      "y": 2,
      "z": -6,
      "name": "Rock_Marble_Brick"
    },
    {
      "x": -16,
      "y": 3,
      "z": -6,
      "name": "Rock_Marble_Brick"
    },
    {
      "x": -16,
      "y": 4,
      "z": -6,
      "name": "Empty"
    },
    {
      "x": -16,
      "y": 5,
      "z": -6,
      "name": "Empty"
    },
    {
      "x": -16,
      "y": 6,
      "z": -6,
      "name": "Empty"
    },
    {
      "x": -16,
      "y": 7,
      "z": -6,
      "name": "Empty"
    },
    {
      "x": -16,
      "y": 8,
      "z": -6,
      "name": "Empty"
    },
    {
      "x": -16,
      "y": 9,
      "z": -6,
      "name": "Empty"
    },
    {
      "x": -16,
      "y": 10,
      "z": -6,
      "name": "Empty"
    },
    {
      "x": -16,
      "y": 11,
      "z": -6,
      "name": "Empty"
    },
    {
      "x": -16,
      "y": 0,
      "z": -5,
      "name": "Rock_Marble_Brick"
    },
    {
      "x": -16,
      "y": 1,
      "z": -5,
      "name": "Rock_Marble_Brick"
    },
    {
      "x": -16,
      "y": 2,
      "z": -5,
      "name": "Rock_Marble_Brick"
    },
    {
      "x": -16,
      "y": 3,
      "z": -5,
      "name": "Rock_Marble_Brick"
    },
    {
      "x": -16,
      "y": 4,
      "z": -5,
      "name": "Empty"
    },
    {
      "x": -16,
      "y": 5,
      "z": -5,
      "name": "Empty"
    },
    {
      "x": -16,
      "y": 6,
      "z": -5,
      "name": "Empty"
    },
    {
      "x": -16,
      "y": 7,
      "z": -5,
      "name": "Empty"
    },
    {
      "x": -16,
      "y": 8,
      "z": -5,
      "name": "Empty"
    },
    {
      "x": -16,
      "y": 9,
      "z": -5,
      "name": "Empty"
    },
    {
      "x": -16,
      "y": 10,
      "z": -5,
      "name": "Empty"
    },
    {
      "x": -16,
      "y": 11,
      "z": -5,
      "name": "Empty"
    },
    {
      "x": -16,
      "y": 0,
      "z": -4,
      "name": "Rock_Marble_Brick"
    },
    {
      "x": -16,
      "y": 1,
      "z": -4,
      "name": "Rock_Marble_Brick"
    },
    {
      "x": -16,
      "y": 2,
      "z": -4,
      "name": "Rock_Marble_Brick"
    },
    {
      "x": -16,
      "y": 3,
      "z": -4,
      "name": "Rock_Marble_Brick"
    },
    {
      "x": -16,
      "y": 4,
      "z": -4,
      "name": "Empty"
    },
    {
      "x": -16,
      "y": 5,
      "z": -4,
      "name": "Empty"
    },
    {
      "x": -16,
      "y": 6,
      "z": -4,
      "name": "Empty"
    },
    {
      "x": -16,
      "y": 7,
      "z": -4,
      "name": "Empty"
    },
    {
      "x": -16,
      "y": 8,
      "z": -4,
      "name": "Empty"
    },
    {
      "x": -16,
      "y": 9,
      "z": -4,
      "name": "Empty"
    },
    {
      "x": -16,
      "y": 10,
      "z": -4,
      "name": "Empty"
    },
    {
      "x": -16,
      "y": 11,
      "z": -4,
      "name": "Empty"
    },
    {
      "x": -16,
      "y": 0,
      "z": -3,
      "name": "Rock_Marble_Brick"
    },
    {
      "x": -16,
      "y": 1,
      "z": -3,
      "name": "Rock_Marble_Brick"
    },
    {
      "x": -16,
      "y": 2,
      "z": -3,
      "name": "Rock_Marble_Brick"
    },
    {
      "x": -16,
      "y": 3,
      "z": -3,
      "name": "Rock_Marble_Brick"
    },
    {
      "x": -16,
      "y": 4,
      "z": -3,
      "name": "Empty"
    },
    {
      "x": -16,
      "y": 5,
      "z": -3,
      "name": "Empty"
    },
    {
      "x": -16,
      "y": 6,
      "z": -3,
      "name": "Empty"
    },
    {
      "x": -16,
      "y": 7,
      "z": -3,
      "name": "Empty"
    },
    {
      "x": -16,
      "y": 8,
      "z": -3,
      "name": "Empty"
    },
    {
      "x": -16,
      "y": 9,
      "z": -3,
      "name": "Empty"
    },
    {
      "x": -16,
      "y": 10,
      "z": -3,
      "name": "Empty"
    },
    {
      "x": -16,
      "y": 11,
      "z": -3,
      "name": "Empty"
    },
    {
      "x": -16,
      "y": 0,
      "z": -2,
      "name": "Rock_Marble_Brick"
    },
    {
      "x": -16,
      "y": 1,
      "z": -2,
      "name": "Rock_Marble_Brick"
    },
    {
      "x": -16,
      "y": 2,
      "z": -2,
      "name": "Rock_Marble_Brick"
    },
    {
      "x": -16,
      "y": 3,
      "z": -2,
      "name": "Rock_Marble_Brick"
    },
    {
      "x": -16,
      "y": 4,
      "z": -2,
      "name": "Empty"
    },
    {
      "x": -16,
      "y": 5,
      "z": -2,
      "name": "Empty"
    },
    {
      "x": -16,
      "y": 6,
      "z": -2,
      "name": "Empty"
    },
    {
      "x": -16,
      "y": 7,
      "z": -2,
      "name": "Empty"
    },
    {
      "x": -16,
      "y": 8,
      "z": -2,
      "name": "Empty"
    },
    {
      "x": -16,
      "y": 9,
      "z": -2,
      "name": "Empty"
    },
    {
      "x": -16,
      "y": 10,
      "z": -2,
      "name": "Empty"
    },
    {
      "x": -16,
      "y": 11,
      "z": -2,
      "name": "Empty"
    },
    {
      "x": -16,
      "y": 0,
      "z": -1,
      "name": "Rock_Marble_Brick"
    },
    {
      "x": -16,
      "y": 1,
      "z": -1,
      "name": "Rock_Marble_Brick"
    },
    {
      "x": -16,
      "y": 2,
      "z": -1,
      "name": "Rock_Marble_Brick"
    },
    {
      "x": -16,
      "y": 3,
      "z": -1,
      "name": "Rock_Marble_Brick"
    },
    {
      "x": -16,
      "y": 4,
      "z": -1,
      "name": "Empty"
    },
    {
      "x": -16,
      "y": 5,
      "z": -1,
      "name": "Empty"
    },
    {
      "x": -16,
      "y": 6,
      "z": -1,
      "name": "Empty"
    },
    {
      "x": -16,
      "y": 7,
      "z": -1,
      "name": "Empty"
    },
    {
      "x": -16,
      "y": 8,
      "z": -1,
      "name": "Empty"
    },
    {
      "x": -16,
      "y": 9,
      "z": -1,
      "name": "Empty"
    },
    {
      "x": -16,
      "y": 10,
      "z": -1,
      "name": "Empty"
    },
    {
      "x": -16,
      "y": 11,
      "z": -1,
      "name": "Empty"
    },
    {
      "x": -16,
      "y": 0,
      "z": 0,
      "name": "Rock_Marble_Brick"
    },
    {
      "x": -16,
      "y": 1,
      "z": 0,
      "name": "Rock_Marble_Brick"
    },
    {
      "x": -16,
      "y": 2,
      "z": 0,
      "name": "Rock_Marble_Brick"
    },
    {
      "x": -16,
      "y": 3,
      "z": 0,
      "name": "Rock_Marble_Brick"
    },
    {
      "x": -16,
      "y": 4,
      "z": 0,
      "name": "Empty"
    },
    {
      "x": -16,
      "y": 5,
      "z": 0,
      "name": "Empty"
    },
    {
      "x": -16,
      "y": 6,
      "z": 0,
      "name": "Empty"
    },
    {
      "x": -16,
      "y": 7,
      "z": 0,
      "name": "Empty"
    },
    {
      "x": -16,
      "y": 8,
      "z": 0,
      "name": "Empty"
    },
    {
      "x": -16,
      "y": 9,
      "z": 0,
      "name": "Empty"
    },
    {
      "x": -16,
      "y": 10,
      "z": 0,
      "name": "Empty"
    },
    {
      "x": -16,
      "y": 11,
      "z": 0,
      "name": "Empty"
    },
    {
      "x": -16,
      "y": 0,
      "z": 1,
      "name": "Rock_Marble_Brick"
    },
    {
      "x": -16,
      "y": 1,
      "z": 1,
      "name": "Rock_Marble_Brick"
    },
    {
      "x": -16,
      "y": 2,
      "z": 1,
      "name": "Rock_Marble_Brick"
    },
    {
      "x": -16,
      "y": 3,
      "z": 1,
      "name": "Rock_Marble_Brick"
    },
    {
      "x": -16,
      "y": 4,
      "z": 1,
      "name": "Empty"
    },
    {
      "x": -16,
      "y": 5,
      "z": 1,
      "name": "Empty"
    },
    {
      "x": -16,
      "y": 6,
      "z": 1,
      "name": "Empty"
    },
    {
      "x": -16,
      "y": 7,
      "z": 1,
      "name": "Empty"
    },
    {
      "x": -16,
      "y": 8,
      "z": 1,
      "name": "Empty"
    },
    {
      "x": -16,
      "y": 9,
      "z": 1,
      "name": "Empty"
    },
    {
      "x": -16,
      "y": 10,
      "z": 1,
      "name": "Empty"
    },
    {
      "x": -16,
      "y": 11,
      "z": 1,
      "name": "Empty"
    },
    {
      "x": -16,
      "y": 0,
      "z": 2,
      "name": "Rock_Marble_Brick"
    },
    {
      "x": -16,
      "y": 1,
      "z": 2,
      "name": "Rock_Marble_Brick"
    },
    {
      "x": -16,
      "y": 2,
      "z": 2,
      "name": "Rock_Marble_Brick"
    },
    {
      "x": -16,
      "y": 3,
      "z": 2,
      "name": "Rock_Marble_Brick"
    },
    {
      "x": -16,
      "y": 4,
      "z": 2,
      "name": "Empty"
    },
    {
      "x": -16,
      "y": 5,
      "z": 2,
      "name": "Empty"
    },
    {
      "x": -16,
      "y": 6,
      "z": 2,
      "name": "Empty"
    },
    {
      "x": -16,
      "y": 7,
      "z": 2,
      "name": "Empty"
    },
    {
      "x": -16,
      "y": 8,
      "z": 2,
      "name": "Empty"
    },
    {
      "x": -16,
      "y": 9,
      "z": 2,
      "name": "Empty"
    },
    {
      "x": -16,
      "y": 10,
      "z": 2,
      "name": "Empty"
    },
    {
      "x": -16,
      "y": 11,
      "z": 2,
      "name": "Empty"
    },
    {
      "x": -16,
      "y": 0,
      "z": 3,
      "name": "Rock_Marble_Brick"
    },
    {
      "x": -16,
      "y": 1,
      "z": 3,
      "name": "Rock_Marble_Brick"
    },
    {
      "x": -16,
      "y": 2,
      "z": 3,
      "name": "Rock_Marble_Brick"
    },
    {
      "x": -16,
      "y": 3,
      "z": 3,
      "name": "Rock_Marble_Brick"
    },
    {
      "x": -16,
      "y": 4,
      "z": 3,
      "name": "Empty"
    },
    {
      "x": -16,
      "y": 5,
      "z": 3,
      "name": "Empty"
    },
    {
      "x": -16,
      "y": 6,
      "z": 3,
      "name": "Empty"
    },
    {
      "x": -16,
      "y": 7,
      "z": 3,
      "name": "Empty"
    },
    {
      "x": -16,
      "y": 8,
      "z": 3,
      "name": "Empty"
    },
    {
      "x": -16,
      "y": 9,
      "z": 3,
      "name": "Empty"
    },
    {
      "x": -16,
      "y": 10,
      "z": 3,
      "name": "Empty"
    },
    {
      "x": -16,
      "y": 11,
      "z": 3,
      "name": "Empty"
    },
    {
      "x": -16,
      "y": 0,
      "z": 4,
      "name": "Rock_Marble_Brick"
    },
    {
      "x": -16,
      "y": 1,
      "z": 4,
      "name": "Rock_Marble_Brick"
    },
    {
      "x": -16,
      "y": 2,
      "z": 4,
      "name": "Rock_Marble_Brick"
    },
    {
      "x": -16,
      "y": 3,
      "z": 4,
      "name": "Rock_Marble_Brick"
    },
    {
      "x": -16,
      "y": 4,
      "z": 4,
      "name": "Empty"
    },
    {
      "x": -16,
      "y": 5,
      "z": 4,
      "name": "Empty"
    },
    {
      "x": -16,
      "y": 6,
      "z": 4,
      "name": "Empty"
    },
    {
      "x": -16,
      "y": 7,
      "z": 4,
      "name": "Empty"
    },
    {
      "x": -16,
      "y": 8,
      "z": 4,
      "name": "Empty"
    },
    {
      "x": -16,
      "y": 9,
      "z": 4,
      "name": "Empty"
    },
    {
      "x": -16,
      "y": 10,
      "z": 4,
      "name": "Empty"
    },
    {
      "x": -16,
      "y": 11,
      "z": 4,
      "name": "Empty"
    },
    {
      "x": -16,
      "y": 0,
      "z": 5,
      "name": "Rock_Marble_Brick"
    },
    {
      "x": -16,
      "y": 1,
      "z": 5,
      "name": "Rock_Marble_Brick"
    },
    {
      "x": -16,
      "y": 2,
      "z": 5,
      "name": "Rock_Marble_Brick"
    },
    {
      "x": -16,
      "y": 3,
      "z": 5,
      "name": "Rock_Marble_Brick"
    },
    {
      "x": -16,
      "y": 4,
      "z": 5,
      "name": "Empty"
    },
    {
      "x": -16,
      "y": 5,
      "z": 5,
      "name": "Empty"
    },
    {
      "x": -16,
      "y": 6,
      "z": 5,
      "name": "Empty"
    },
    {
      "x": -16,
      "y": 7,
      "z": 5,
      "name": "Empty"
    },
    {
      "x": -16,
      "y": 8,
      "z": 5,
      "name": "Empty"
    },
    {
      "x": -16,
      "y": 9,
      "z": 5,
      "name": "Empty"
    },
    {
      "x": -16,
      "y": 10,
      "z": 5,
      "name": "Empty"
    },
    {
      "x": -16,
      "y": 11,
      "z": 5,
      "name": "Empty"
    },
    {
      "x": -16,
      "y": 0,
      "z": 6,
      "name": "Rock_Marble_Brick"
    },
    {
      "x": -16,
      "y": 1,
      "z": 6,
      "name": "Rock_Marble_Brick"
    },
    {
      "x": -16,
      "y": 2,
      "z": 6,
      "name": "Rock_Marble_Brick"
    },
    {
      "x": -16,
      "y": 3,
      "z": 6,
      "name": "Rock_Marble_Brick"
    },
    {
      "x": -16,
      "y": 4,
      "z": 6,
      "name": "Empty"
    },
    {
      "x": -16,
      "y": 5,
      "z": 6,
      "name": "Empty"
    },
    {
      "x": -16,
      "y": 6,
      "z": 6,
      "name": "Empty"
    },
    {
      "x": -16,
      "y": 7,
      "z": 6,
      "name": "Empty"
    },
    {
      "x": -16,
      "y": 8,
      "z": 6,
      "name": "Empty"
    },
    {
      "x": -16,
      "y": 9,
      "z": 6,
      "name": "Empty"
    },
    {
      "x": -16,
      "y": 10,
      "z": 6,
      "name": "Empty"
    },
    {
      "x": -16,
      "y": 11,
      "z": 6,
      "name": "Empty"
    },
    {
      "x": -16,
      "y": 0,
      "z": 7,
      "name": "Rock_Marble_Brick"
    },
    {
      "x": -16,
      "y": 1,
      "z": 7,
      "name": "Rock_Marble_Brick"
    },
    {
      "x": -16,
      "y": 2,
      "z": 7,
      "name": "Rock_Marble_Brick"
    },
    {
      "x": -16,
      "y": 3,
      "z": 7,
      "name": "Rock_Marble_Brick"
    },
    {
      "x": -16,
      "y": 4,
      "z": 7,
      "name": "Empty"
    },
    {
      "x": -16,
      "y": 5,
      "z": 7,
      "name": "Empty"
    },
    {
      "x": -16,
      "y": 6,
      "z": 7,
      "name": "Empty"
    },
    {
      "x": -16,
      "y": 7,
      "z": 7,
      "name": "Empty"
    },
    {
      "x": -16,
      "y": 8,
      "z": 7,
      "name": "Empty"
    },
    {
      "x": -16,
      "y": 9,
      "z": 7,
      "name": "Empty"
    },
    {
      "x": -16,
      "y": 10,
      "z": 7,
      "name": "Empty"
    },
    {
      "x": -16,
      "y": 11,
      "z": 7,
      "name": "Empty"
    },
    {
      "x": -16,
      "y": 0,
      "z": 8,
      "name": "Rock_Marble_Brick"
    },
    {
      "x": -16,
      "y": 1,
      "z": 8,
      "name": "Rock_Marble_Brick"
    },
    {
      "x": -16,
      "y": 2,
      "z": 8,
      "name": "Rock_Marble_Brick"
    },
    {
      "x": -16,
      "y": 3,
      "z": 8,
      "name": "Rock_Marble_Brick"
    },
    {
      "x": -16,
      "y": 4,
      "z": 8,
      "name": "Empty"
    },
    {
      "x": -16,
      "y": 5,
      "z": 8,
      "name": "Empty"
    },
    {
      "x": -16,
      "y": 6,
      "z": 8,
      "name": "Empty"
    },
    {
      "x": -16,
      "y": 7,
      "z": 8,
      "name": "Empty"
    },
    {
      "x": -16,
      "y": 8,
      "z": 8,
      "name": "Empty"
    },
    {
      "x": -16,
      "y": 9,
      "z": 8,
      "name": "Empty"
    },
    {
      "x": -16,
      "y": 10,
      "z": 8,
      "name": "Empty"
    },
    {
      "x": -16,
      "y": 11,
      "z": 8,
      "name": "Empty"
    },
    {
      "x": -16,
      "y": 0,
      "z": 9,
      "name": "Rock_Marble_Brick"
    },
    {
      "x": -16,
      "y": 1,
      "z": 9,
      "name": "Rock_Marble_Brick"
    },
    {
      "x": -16,
      "y": 2,
      "z": 9,
      "name": "Rock_Marble_Brick"
    },
    {
      "x": -16,
      "y": 3,
      "z": 9,
      "name": "Rock_Marble_Brick"
    },
    {
      "x": -16,
      "y": 4,
      "z": 9,
      "name": "Rock_Marble_Brick",
      "rotation": 2
    },
    {
      "x": -16,
      "y": 5,
      "z": 9,
      "name": "Rock_Marble_Brick",
      "rotation": 2
    },
    {
      "x": -16,
      "y": 6,
      "z": 9,
      "name": "Rock_Marble_Brick",
      "rotation": 2
    },
    {
      "x": -16,
      "y": 7,
      "z": 9,
      "name": "Rock_Marble_Brick",
      "rotation": 2
    },
    {
      "x": -16,
      "y": 8,
      "z": 9,
      "name": "Rock_Marble_Brick",
      "rotation": 2
    },
    {
      "x": -16,
      "y": 9,
      "z": 9,
      "name": "Rock_Ice",
      "rotation": 2
    },
    {
      "x": -16,
      "y": 10,
      "z": 9,
      "name": "Rock_Ice",
      "rotation": 2
    },
    {
      "x": -16,
      "y": 11,
      "z": 9,
      "name": "Empty"
    },
    {
      "x": -16,
      "y": 0,
      "z": 10,
      "name": "Rock_Marble_Brick"
    },
    {
      "x": -16,
      "y": 1,
      "z": 10,
      "name": "Rock_Marble_Brick"
    },
    {
      "x": -16,
      "y": 2,
      "z": 10,
      "name": "Rock_Marble_Brick"
    },
    {
      "x": -16,
      "y": 3,
      "z": 10,
      "name": "Rock_Marble_Brick"
    },
    {
      "x": -16,
      "y": 4,
      "z": 10,
      "name": "Rock_Marble_Brick",
      "rotation": 2
    },
    {
      "x": -16,
      "y": 5,
      "z": 10,
      "name": "Rock_Marble_Brick_Decorative",
      "rotation": 2
    },
    {
      "x": -16,
      "y": 6,
      "z": 10,
      "name": "Rock_Ice",
      "rotation": 2
    },
    {
      "x": -16,
      "y": 7,
      "z": 10,
      "name": "Rock_Marble_Brick",
      "rotation": 2
    },
    {
      "x": -16,
      "y": 8,
      "z": 10,
      "name": "Rock_Marble_Brick",
      "rotation": 2
    },
    {
      "x": -16,
      "y": 9,
      "z": 10,
      "name": "Rock_Marble_Brick",
      "rotation": 2
    },
    {
      "x": -16,
      "y": 10,
      "z": 10,
      "name": "Rock_Marble_Brick",
      "rotation": 2
    },
    {
      "x": -16,
      "y": 11,
      "z": 10,
      "name": "Empty"
    },
    {
      "x": -16,
      "y": 0,
      "z": 11,
      "name": "Rock_Marble_Brick"
    },
    {
      "x": -16,
      "y": 1,
      "z": 11,
      "name": "Rock_Marble_Brick"
    },
    {
      "x": -16,
      "y": 2,
      "z": 11,
      "name": "Rock_Marble_Brick"
    },
    {
      "x": -16,
      "y": 3,
      "z": 11,
      "name": "Rock_Marble_Brick"
    },
    {
      "x": -16,
      "y": 4,
      "z": 11,
      "name": "Rock_Marble_Brick",
      "rotation": 2
    },
    {
      "x": -16,
      "y": 5,
      "z": 11,
      "name": "Rock_Marble_Brick_Decorative",
      "rotation": 2
    },
    {
      "x": -16,
      "y": 6,
      "z": 11,
      "name": "Rock_Marble_Brick",
      "rotation": 2
    },
    {
      "x": -16,
      "y": 7,
      "z": 11,
      "name": "Rock_Marble_Brick",
      "rotation": 2
    },
    {
      "x": -16,
      "y": 8,
      "z": 11,
      "name": "Rock_Marble_Brick",
      "rotation": 2
    },
    {
      "x": -16,
      "y": 9,
      "z": 11,
      "name": "Rock_Marble_Brick",
      "rotation": 2
    },
    {
      "x": -16,
      "y": 10,
      "z": 11,
      "name": "Rock_Ice",
      "rotation": 2
    },
    {
      "x": -16,
      "y": 11,
      "z": 11,
      "name": "Empty"
    },
    {
      "x": -16,
      "y": 0,
      "z": 12,
      "name": "Rock_Marble_Brick"
    },
    {
      "x": -16,
      "y": 1,
      "z": 12,
      "name": "Rock_Marble_Brick"
    },
    {
      "x": -16,
      "y": 2,
      "z": 12,
      "name": "Rock_Marble_Brick"
    },
    {
      "x": -16,
      "y": 3,
      "z": 12,
      "name": "Rock_Marble_Brick"
    },
    {
      "x": -16,
      "y": 4,
      "z": 12,
      "name": "Rock_Marble_Brick",
      "rotation": 2
    },
    {
      "x": -16,
      "y": 5,
      "z": 12,
      "name": "Rock_Marble_Brick_Decorative",
      "rotation": 2
    },
    {
      "x": -16,
      "y": 6,
      "z": 12,
      "name": "Rock_Marble_Brick",
      "rotation": 2
    },
    {
      "x": -16,
      "y": 7,
      "z": 12,
      "name": "Rock_Marble_Brick",
      "rotation": 2
    },
    {
      "x": -16,
      "y": 8,
      "z": 12,
      "name": "Rock_Marble_Brick",
      "rotation": 2
    },
    {
      "x": -16,
      "y": 9,
      "z": 12,
      "name": "Rock_Ice",
      "rotation": 2
    },
    {
      "x": -16,
      "y": 10,
      "z": 12,
      "name": "Rock_Ice",
      "rotation": 2
    },
    {
      "x": -16,
      "y": 11,
      "z": 12,
      "name": "Empty"
    },
    {
      "x": -16,
      "y": 0,
      "z": 13,
      "name": "Rock_Marble_Brick"
    },
    {
      "x": -16,
      "y": 1,
      "z": 13,
      "name": "Rock_Marble_Brick"
    },
    {
      "x": -16,
      "y": 2,
      "z": 13,
      "name": "Rock_Marble_Brick"
    },
    {
      "x": -16,
      "y": 3,
      "z": 13,
      "name": "Rock_Marble_Brick"
    },
    {
      "x": -16,
      "y": 4,
      "z": 13,
      "name": "Rock_Marble_Brick",
      "rotation": 2
    },
    {
      "x": -16,
      "y": 5,
      "z": 13,
      "name": "Rock_Marble_Brick_Decorative",
      "rotation": 2
    },
    {
      "x": -16,
      "y": 6,
      "z": 13,
      "name": "Rock_Marble_Brick",
      "rotation": 2
    },
    {
      "x": -16,
      "y": 7,
      "z": 13,
      "name": "Rock_Marble_Brick",
      "rotation": 2
    },
    {
      "x": -16,
      "y": 8,
      "z": 13,
      "name": "Rock_Marble_Brick",
      "rotation": 2
    },
    {
      "x": -16,
      "y": 9,
      "z": 13,
      "name": "Rock_Marble_Brick",
      "rotation": 2
    },
    {
      "x": -16,
      "y": 10,
      "z": 13,
      "name": "Rock_Marble_Brick",
      "rotation": 2
    },
    {
      "x": -16,
      "y": 11,
      "z": 13,
      "name": "Empty"
    },
    {
      "x": -16,
      "y": 0,
      "z": 14,
      "name": "Rock_Marble_Brick"
    },
    {
      "x": -16,
      "y": 1,
      "z": 14,
      "name": "Rock_Marble_Brick"
    },
    {
      "x": -16,
      "y": 2,
      "z": 14,
      "name": "Rock_Marble_Brick"
    },
    {
      "x": -16,
      "y": 3,
      "z": 14,
      "name": "Rock_Marble_Brick"
    },
    {
      "x": -16,
      "y": 4,
      "z": 14,
      "name": "Rock_Marble_Brick"
    },
    {
      "x": -16,
      "y": 5,
      "z": 14,
      "name": "Rock_Marble_Brick",
      "rotation": 2
    },
    {
      "x": -16,
      "y": 6,
      "z": 14,
      "name": "Rock_Marble_Brick",
      "rotation": 2
    },
    {
      "x": -16,
      "y": 7,
      "z": 14,
      "name": "Rock_Marble_Brick",
      "rotation": 2
    },
    {
      "x": -16,
      "y": 8,
      "z": 14,
      "name": "Rock_Ice",
      "rotation": 2
    },
    {
      "x": -16,
      "y": 9,
      "z": 14,
      "name": "Rock_Ice",
      "rotation": 2
    },
    {
      "x": -16,
      "y": 10,
      "z": 14,
      "name": "Rock_Marble_Brick"
    },
    {
      "x": -16,
      "y": 11,
      "z": 14,
      "name": "Empty"
    },
    {
      "x": -16,
      "y": 0,
      "z": 15,
      "name": "Cloth_Block_Wool_Red"
    },
    {
      "x": -16,
      "y": 1,
      "z": 15,
      "name": "Rock_Marble_Brick"
    },
    {
      "x": -16,
      "y": 2,
      "z": 15,
      "name": "Rock_Marble_Brick"
    },
    {
      "x": -16,
      "y": 3,
      "z": 15,
      "name": "Rock_Marble_Brick"
    },
    {
      "x": -16,
      "y": 4,
      "z": 15,
      "name": "Empty"
    },
    {
      "x": -16,
      "y": 5,
      "z": 15,
      "name": "Empty"
    },
    {
      "x": -16,
      "y": 6,
      "z": 15,
      "name": "Empty"
    },
    {
      "x": -16,
      "y": 7,
      "z": 15,
      "name": "Empty"
    },
    {
      "x": -16,
      "y": 8,
      "z": 15,
      "name": "Empty"
    },
    {
      "x": -16,
      "y": 9,
      "z": 15,
      "name": "Empty"
    },
    {
      "x": -16,
      "y": 10,
      "z": 15,
      "name": "Empty"
    },
    {
      "x": -16,
      "y": 11,
      "z": 15,
      "name": "Cloth_Block_Wool_Red"
    },
    {
      "x": -15,
      "y": 0,
      "z": -14,
      "name": "Rock_Marble_Brick"
    },
    {
      "x": -15,
      "y": 1,
      "z": -14,
      "name": "Rock_Marble_Brick"
    },
    {
      "x": -15,
      "y": 2,
      "z": -14,
      "name": "Rock_Marble_Brick"
    },
    {
      "x": -15,
      "y": 3,
      "z": -14,
      "name": "Rock_Marble_Brick"
    },
    {
      "x": -15,
      "y": 4,
      "z": -14,
      "name": "Rock_Marble_Brick"
    },
    {
      "x": -15,
      "y": 5,
      "z": -14,
      "name": "Rock_Marble_Brick_Decorative"
    },
    {
      "x": -15,
      "y": 6,
      "z": -14,
      "name": "Rock_Marble_Brick"
    },
    {
      "x": -15,
      "y": 7,
      "z": -14,
      "name": "Rock_Marble_Brick"
    },
    {
      "x": -15,
      "y": 8,
      "z": -14,
      "name": "Rock_Marble_Brick"
    },
    {
      "x": -15,
      "y": 9,
      "z": -14,
      "name": "Rock_Marble_Brick"
    },
    {
      "x": -15,
      "y": 10,
      "z": -14,
      "name": "Rock_Marble_Brick"
    },
    {
      "x": -15,
      "y": 11,
      "z": -14,
      "name": "Empty"
    },
    {
      "x": -15,
      "y": 0,
      "z": -13,
      "name": "Rock_Marble_Brick"
    },
    {
      "x": -15,
      "y": 1,
      "z": -13,
      "name": "Rock_Marble_Brick"
    },
    {
      "x": -15,
      "y": 2,
      "z": -13,
      "name": "Rock_Marble_Brick"
    },
    {
      "x": -15,
      "y": 3,
      "z": -13,
      "name": "Rock_Marble_Brick"
    },
    {
      "x": -15,
      "y": 4,
      "z": -13,
      "name": "Rock_Marble_Brick"
    },
    {
      "x": -15,
      "y": 5,
      "z": -13,
      "name": "Rock_Marble_Brick_Smooth_Half",
      "rotation": 4
    },
    {
      "x": -15,
      "y": 6,
      "z": -13,
      "name": "Rock_Marble_Brick_Smooth_Half",
      "rotation": 4
    },
    {
      "x": -15,
      "y": 7,
      "z": -13,
      "name": "Rock_Marble_Brick_Smooth_Half",
      "rotation": 4
    },
    {
      "x": -15,
      "y": 8,
      "z": -13,
      "name": "Rock_Marble_Brick_Smooth_Half",
      "rotation": 4
    },
    {
      "x": -15,
      "y": 9,
      "z": -13,
      "name": "Rock_Marble_Brick_Smooth"
    },
    {
      "x": -15,
      "y": 10,
      "z": -13,
      "name": "Rock_Marble_Brick"
    },
    {
      "x": -15,
      "y": 11,
      "z": -13,
      "name": "Empty"
    },
    {
      "x": -15,
      "y": 0,
      "z": -12,
      "name": "Rock_Marble_Brick"
    },
    {
      "x": -15,
      "y": 1,
      "z": -12,
      "name": "Rock_Marble_Brick"
    },
    {
      "x": -15,
      "y": 2,
      "z": -12,
      "name": "Rock_Marble_Brick"
    },
    {
      "x": -15,
      "y": 3,
      "z": -12,
      "name": "Rock_Marble_Brick"
    },
    {
      "x": -15,
      "y": 4,
      "z": -12,
      "name": "Rock_Marble_Brick"
    },
    {
      "x": -15,
      "y": 5,
      "z": -12,
      "name": "Empty"
    },
    {
      "x": -15,
      "y": 6,
      "z": -12,
      "name": "Empty"
    },
    {
      "x": -15,
      "y": 7,
      "z": -12,
      "name": "Empty"
    },
    {
      "x": -15,
      "y": 8,
      "z": -12,
      "name": "Empty"
    },
    {
      "x": -15,
      "y": 9,
      "z": -12,
      "name": "Rock_Marble_Brick_Smooth_Half",
      "rotation": 8
    },
    {
      "x": -15,
      "y": 10,
      "z": -12,
      "name": "Rock_Marble_Brick"
    },
    {
      "x": -15,
      "y": 11,
      "z": -12,
      "name": "Empty"
    },
    {
      "x": -15,
      "y": 0,
      "z": -11,
      "name": "Rock_Marble_Brick"
    },
    {
      "x": -15,
      "y": 1,
      "z": -11,
      "name": "Rock_Marble_Brick"
    },
    {
      "x": -15,
      "y": 2,
      "z": -11,
      "name": "Rock_Marble_Brick"
    },
    {
      "x": -15,
      "y": 3,
      "z": -11,
      "name": "Rock_Marble_Brick"
    },
    {
      "x": -15,
      "y": 4,
      "z": -11,
      "name": "Rock_Marble_Brick"
    },
    {
      "x": -15,
      "y": 5,
      "z": -11,
      "name": "Rubble_Ice_Medium",
      "support": 15
    },
    {
      "x": -15,
      "y": 6,
      "z": -11,
      "name": "Empty"
    },
    {
      "x": -15,
      "y": 7,
      "z": -11,
      "name": "Empty"
    },
    {
      "x": -15,
      "y": 8,
      "z": -11,
      "name": "Empty"
    },
    {
      "x": -15,
      "y": 9,
      "z": -11,
      "name": "Rock_Marble_Brick_Smooth_Half",
      "rotation": 8
    },
    {
      "x": -15,
      "y": 10,
      "z": -11,
      "name": "Rock_Marble_Brick"
    },
    {
      "x": -15,
      "y": 11,
      "z": -11,
      "name": "Empty"
    },
    {
      "x": -15,
      "y": 0,
      "z": -10,
      "name": "Rock_Marble_Brick"
    },
    {
      "x": -15,
      "y": 1,
      "z": -10,
      "name": "Rock_Marble_Brick"
    },
    {
      "x": -15,
      "y": 2,
      "z": -10,
      "name": "Rock_Marble_Brick"
    },
    {
      "x": -15,
      "y": 3,
      "z": -10,
      "name": "Rock_Marble_Brick"
    },
    {
      "x": -15,
      "y": 4,
      "z": -10,
      "name": "Rock_Ice"
    },
    {
      "x": -15,
      "y": 5,
      "z": -10,
      "name": "Rock_Marble_Brick_Smooth_Half",
      "rotation": 6
    },
    {
      "x": -15,
      "y": 6,
      "z": -10,
      "name": "Rock_Marble_Brick_Smooth_Half",
      "rotation": 6
    },
    {
      "x": -15,
      "y": 7,
      "z": -10,
      "name": "Rock_Marble_Brick_Smooth_Half",
      "rotation": 6
    },
    {
      "x": -15,
      "y": 8,
      "z": -10,
      "name": "Rock_Marble_Brick_Smooth_Half",
      "rotation": 6
    },
    {
      "x": -15,
      "y": 9,
      "z": -10,
      "name": "Rock_Marble_Brick_Smooth"
    },
    {
      "x": -15,
      "y": 10,
      "z": -10,
      "name": "Rock_Marble_Brick"
    },
    {
      "x": -15,
      "y": 11,
      "z": -10,
      "name": "Empty"
    },
    {
      "x": -15,
      "y": 0,
      "z": -9,
      "name": "Rock_Marble_Brick"
    },
    {
      "x": -15,
      "y": 1,
      "z": -9,
      "name": "Rock_Marble_Brick"
    },
    {
      "x": -15,
      "y": 2,
      "z": -9,
      "name": "Rock_Marble_Brick"
    },
    {
      "x": -15,
      "y": 3,
      "z": -9,
      "name": "Rock_Marble_Brick"
    },
    {
      "x": -15,
      "y": 4,
      "z": -9,
      "name": "Rock_Marble_Brick"
    },
    {
      "x": -15,
      "y": 5,
      "z": -9,
      "name": "Rock_Marble_Brick_Smooth"
    },
    {
      "x": -15,
      "y": 6,
      "z": -9,
      "name": "Rock_Marble_Brick_Smooth"
    },
    {
      "x": -15,
      "y": 7,
      "z": -9,
      "name": "Rock_Marble_Brick_Smooth"
    },
    {
      "x": -15,
      "y": 8,
      "z": -9,
      "name": "Rock_Marble_Brick_Smooth"
    },
    {
      "x": -15,
      "y": 9,
      "z": -9,
      "name": "Rock_Marble_Brick_Smooth"
    },
    {
      "x": -15,
      "y": 10,
      "z": -9,
      "name": "Rock_Marble_Brick"
    },
    {
      "x": -15,
      "y": 11,
      "z": -9,
      "name": "Empty"
    },
    {
      "x": -15,
      "y": 0,
      "z": -8,
      "name": "Rock_Marble_Brick"
    },
    {
      "x": -15,
      "y": 1,
      "z": -8,
      "name": "Rock_Marble_Brick"
    },
    {
      "x": -15,
      "y": 2,
      "z": -8,
      "name": "Rock_Marble_Brick"
    },
    {
      "x": -15,
      "y": 3,
      "z": -8,
      "name": "Rock_Marble_Brick"
    },
    {
      "x": -15,
      "y": 4,
      "z": -8,
      "name": "Rock_Marble_Brick"
    },
    {
      "x": -15,
      "y": 5,
      "z": -8,
      "name": "Rock_Marble_Brick_Decorative"
    },
    {
      "x": -15,
      "y": 6,
      "z": -8,
      "name": "Rock_Marble_Brick"
    },
    {
      "x": -15,
      "y": 7,
      "z": -8,
      "name": "Rock_Marble_Brick"
    },
    {
      "x": -15,
      "y": 8,
      "z": -8,
      "name": "Rock_Marble_Brick"
    },
    {
      "x": -15,
      "y": 9,
      "z": -8,
      "name": "Rock_Ice"
    },
    {
      "x": -15,
      "y": 10,
      "z": -8,
      "name": "Rock_Marble_Brick"
    },
    {
      "x": -15,
      "y": 11,
      "z": -8,
      "name": "Empty"
    },
    {
      "x": -15,
      "y": 0,
      "z": -7,
      "name": "Rock_Marble_Brick"
    },
    {
      "x": -15,
      "y": 1,
      "z": -7,
      "name": "Rock_Marble_Brick"
    },
    {
      "x": -15,
      "y": 2,
      "z": -7,
      "name": "Rock_Marble_Brick"
    },
    {
      "x": -15,
      "y": 3,
      "z": -7,
      "name": "Rock_Marble_Brick"
    },
    {
      "x": -15,
      "y": 4,
      "z": -7,
      "name": "Rock_Marble_Brick"
    },
    {
      "x": -15,
      "y": 5,
      "z": -7,
      "name": "Rock_Marble_Brick_Decorative"
    },
    {
      "x": -15,
      "y": 6,
      "z": -7,
      "name": "Rock_Marble_Brick"
    },
    {
      "x": -15,
      "y": 7,
      "z": -7,
      "name": "Rock_Marble_Brick"
    },
    {
      "x": -15,
      "y": 8,
      "z": -7,
      "name": "Rock_Marble_Brick"
    },
    {
      "x": -15,
      "y": 9,
      "z": -7,
      "name": "Rock_Marble_Brick"
    },
    {
      "x": -15,
      "y": 10,
      "z": -7,
      "name": "Rock_Marble_Brick"
    },
    {
      "x": -15,
      "y": 11,
      "z": -7,
      "name": "Empty"
    },
    {
      "x": -15,
      "y": 0,
      "z": -6,
      "name": "Rock_Marble_Brick"
    },
    {
      "x": -15,
      "y": 1,
      "z": -6,
      "name": "Rock_Marble_Brick"
    },
    {
      "x": -15,
      "y": 2,
      "z": -6,
      "name": "Rock_Marble_Brick"
    },
    {
      "x": -15,
      "y": 3,
      "z": -6,
      "name": "Rock_Marble_Brick"
    },
    {
      "x": -15,
      "y": 4,
      "z": -6,
      "name": "Rock_Marble_Brick"
    },
    {
      "x": -15,
      "y": 5,
      "z": -6,
      "name": "Rock_Marble_Brick_Decorative"
    },
    {
      "x": -15,
      "y": 6,
      "z": -6,
      "name": "Rock_Marble_Brick"
    },
    {
      "x": -15,
      "y": 7,
      "z": -6,
      "name": "Rock_Ice"
    },
    {
      "x": -15,
      "y": 8,
      "z": -6,
      "name": "Rock_Marble_Brick"
    },
    {
      "x": -15,
      "y": 9,
      "z": -6,
      "name": "Rock_Ice"
    },
    {
      "x": -15,
      "y": 10,
      "z": -6,
      "name": "Rock_Ice"
    },
    {
      "x": -15,
      "y": 11,
      "z": -6,
      "name": "Empty"
    },
    {
      "x": -15,
      "y": 0,
      "z": -5,
      "name": "Rock_Marble_Brick"
    },
    {
      "x": -15,
      "y": 1,
      "z": -5,
      "name": "Rock_Marble_Brick"
    },
    {
      "x": -15,
      "y": 2,
      "z": -5,
      "name": "Rock_Marble_Brick"
    },
    {
      "x": -15,
      "y": 3,
      "z": -5,
      "name": "Rock_Marble_Brick"
    },
    {
      "x": -15,
      "y": 4,
      "z": -5,
      "name": "Rock_Marble_Brick"
    },
    {
      "x": -15,
      "y": 5,
      "z": -5,
      "name": "Rock_Marble_Brick_Decorative"
    },
    {
      "x": -15,
      "y": 6,
      "z": -5,
      "name": "Rock_Ice"
    },
    {
      "x": -15,
      "y": 7,
      "z": -5,
      "name": "Rock_Ice"
    },
    {
      "x": -15,
      "y": 8,
      "z": -5,
      "name": "Rock_Marble_Brick"
    },
    {
      "x": -15,
      "y": 9,
      "z": -5,
      "name": "Rock_Ice"
    },
    {
      "x": -15,
      "y": 10,
      "z": -5,
      "name": "Rock_Ice"
    },
    {
      "x": -15,
      "y": 11,
      "z": -5,
      "name": "Empty"
    },
    {
      "x": -15,
      "y": 0,
      "z": -4,
      "name": "Rock_Marble_Brick"
    },
    {
      "x": -15,
      "y": 1,
      "z": -4,
      "name": "Rock_Marble_Brick"
    },
    {
      "x": -15,
      "y": 2,
      "z": -4,
      "name": "Rock_Marble_Brick"
    },
    {
      "x": -15,
      "y": 3,
      "z": -4,
      "name": "Rock_Marble_Brick"
    },
    {
      "x": -15,
      "y": 4,
      "z": -4,
      "name": "Rock_Marble_Brick"
    },
    {
      "x": -15,
      "y": 5,
      "z": -4,
      "name": "Rock_Marble_Brick_Decorative"
    },
    {
      "x": -15,
      "y": 6,
      "z": -4,
      "name": "Rock_Marble_Brick"
    },
    {
      "x": -15,
      "y": 7,
      "z": -4,
      "name": "Rock_Ice"
    },
    {
      "x": -15,
      "y": 8,
      "z": -4,
      "name": "Rock_Ice"
    },
    {
      "x": -15,
      "y": 9,
      "z": -4,
      "name": "Rock_Marble_Brick"
    },
    {
      "x": -15,
      "y": 10,
      "z": -4,
      "name": "Rock_Ice"
    },
    {
      "x": -15,
      "y": 11,
      "z": -4,
      "name": "Empty"
    },
    {
      "x": -15,
      "y": 0,
      "z": -3,
      "name": "Rock_Marble_Brick"
    },
    {
      "x": -15,
      "y": 1,
      "z": -3,
      "name": "Rock_Marble_Brick"
    },
    {
      "x": -15,
      "y": 2,
      "z": -3,
      "name": "Rock_Marble_Brick"
    },
    {
      "x": -15,
      "y": 3,
      "z": -3,
      "name": "Rock_Marble_Brick"
    },
    {
      "x": -15,
      "y": 4,
      "z": -3,
      "name": "Rock_Marble_Brick"
    },
    {
      "x": -15,
      "y": 5,
      "z": -3,
      "name": "Rock_Marble_Brick"
    },
    {
      "x": -15,
      "y": 6,
      "z": -3,
      "name": "Rock_Marble_Brick"
    },
    {
      "x": -15,
      "y": 7,
      "z": -3,
      "name": "Rock_Ice"
    },
    {
      "x": -15,
      "y": 8,
      "z": -3,
      "name": "Rock_Marble_Brick"
    },
    {
      "x": -15,
      "y": 9,
      "z": -3,
      "name": "Rock_Marble_Brick"
    },
    {
      "x": -15,
      "y": 10,
      "z": -3,
      "name": "Rock_Marble_Brick"
    },
    {
      "x": -15,
      "y": 11,
      "z": -3,
      "name": "Empty"
    },
    {
      "x": -15,
      "y": 0,
      "z": -2,
      "name": "Rock_Marble_Brick"
    },
    {
      "x": -15,
      "y": 1,
      "z": -2,
      "name": "Rock_Marble_Brick"
    },
    {
      "x": -15,
      "y": 2,
      "z": -2,
      "name": "Rock_Marble_Brick"
    },
    {
      "x": -15,
      "y": 3,
      "z": -2,
      "name": "Rock_Marble_Brick"
    },
    {
      "x": -15,
      "y": 4,
      "z": -2,
      "name": "Rock_Marble_Brick"
    },
    {
      "x": -15,
      "y": 5,
      "z": -2,
      "name": "Rock_Marble_Brick_Decorative"
    },
    {
      "x": -15,
      "y": 6,
      "z": -2,
      "name": "Rock_Ice"
    },
    {
      "x": -15,
      "y": 7,
      "z": -2,
      "name": "Rock_Ice"
    },
    {
      "x": -15,
      "y": 8,
      "z": -2,
      "name": "Rock_Marble_Brick"
    },
    {
      "x": -15,
      "y": 9,
      "z": -2,
      "name": "Rock_Ice"
    },
    {
      "x": -15,
      "y": 10,
      "z": -2,
      "name": "Rock_Marble_Brick"
    },
    {
      "x": -15,
      "y": 11,
      "z": -2,
      "name": "Empty"
    },
    {
      "x": -15,
      "y": 0,
      "z": -1,
      "name": "Rock_Marble_Brick"
    },
    {
      "x": -15,
      "y": 1,
      "z": -1,
      "name": "Rock_Marble_Brick"
    },
    {
      "x": -15,
      "y": 2,
      "z": -1,
      "name": "Rock_Marble_Brick"
    },
    {
      "x": -15,
      "y": 3,
      "z": -1,
      "name": "Rock_Marble_Brick"
    },
    {
      "x": -15,
      "y": 4,
      "z": -1,
      "name": "Rock_Marble_Brick"
    },
    {
      "x": -15,
      "y": 5,
      "z": -1,
      "name": "Rock_Marble_Brick_Decorative"
    },
    {
      "x": -15,
      "y": 6,
      "z": -1,
      "name": "Rock_Ice"
    },
    {
      "x": -15,
      "y": 7,
      "z": -1,
      "name": "Rock_Ice"
    },
    {
      "x": -15,
      "y": 8,
      "z": -1,
      "name": "Rock_Marble_Brick"
    },
    {
      "x": -15,
      "y": 9,
      "z": -1,
      "name": "Rock_Marble_Brick"
    },
    {
      "x": -15,
      "y": 10,
      "z": -1,
      "name": "Rock_Ice"
    },
    {
      "x": -15,
      "y": 11,
      "z": -1,
      "name": "Empty"
    },
    {
      "x": -15,
      "y": 0,
      "z": 0,
      "name": "Rock_Marble_Brick"
    },
    {
      "x": -15,
      "y": 1,
      "z": 0,
      "name": "Rock_Marble_Brick"
    },
    {
      "x": -15,
      "y": 2,
      "z": 0,
      "name": "Rock_Marble_Brick"
    },
    {
      "x": -15,
      "y": 3,
      "z": 0,
      "name": "Rock_Marble_Brick"
    },
    {
      "x": -15,
      "y": 4,
      "z": 0,
      "name": "Rock_Marble_Brick"
    },
    {
      "x": -15,
      "y": 5,
      "z": 0,
      "name": "Rock_Marble_Brick_Decorative"
    },
    {
      "x": -15,
      "y": 6,
      "z": 0,
      "name": "Rock_Marble_Brick"
    },
    {
      "x": -15,
      "y": 7,
      "z": 0,
      "name": "Rock_Ice"
    },
    {
      "x": -15,
      "y": 8,
      "z": 0,
      "name": "Rock_Marble_Brick"
    },
    {
      "x": -15,
      "y": 9,
      "z": 0,
      "name": "Rock_Ice"
    },
    {
      "x": -15,
      "y": 10,
      "z": 0,
      "name": "Rock_Marble_Brick"
    },
    {
      "x": -15,
      "y": 11,
      "z": 0,
      "name": "Empty"
    },
    {
      "x": -15,
      "y": 0,
      "z": 1,
      "name": "Rock_Marble_Brick"
    },
    {
      "x": -15,
      "y": 1,
      "z": 1,
      "name": "Rock_Marble_Brick"
    },
    {
      "x": -15,
      "y": 2,
      "z": 1,
      "name": "Rock_Marble_Brick"
    },
    {
      "x": -15,
      "y": 3,
      "z": 1,
      "name": "Rock_Marble_Brick"
    },
    {
      "x": -15,
      "y": 4,
      "z": 1,
      "name": "Rock_Marble_Brick"
    },
    {
      "x": -15,
      "y": 5,
      "z": 1,
      "name": "Rock_Marble_Brick_Decorative"
    },
    {
      "x": -15,
      "y": 6,
      "z": 1,
      "name": "Rock_Marble_Brick"
    },
    {
      "x": -15,
      "y": 7,
      "z": 1,
      "name": "Rock_Ice"
    },
    {
      "x": -15,
      "y": 8,
      "z": 1,
      "name": "Rock_Ice"
    },
    {
      "x": -15,
      "y": 9,
      "z": 1,
      "name": "Rock_Marble_Brick"
    },
    {
      "x": -15,
      "y": 10,
      "z": 1,
      "name": "Rock_Ice"
    },
    {
      "x": -15,
      "y": 11,
      "z": 1,
      "name": "Empty"
    },
    {
      "x": -15,
      "y": 0,
      "z": 2,
      "name": "Rock_Marble_Brick"
    },
    {
      "x": -15,
      "y": 1,
      "z": 2,
      "name": "Rock_Marble_Brick"
    },
    {
      "x": -15,
      "y": 2,
      "z": 2,
      "name": "Rock_Marble_Brick"
    },
    {
      "x": -15,
      "y": 3,
      "z": 2,
      "name": "Rock_Marble_Brick"
    },
    {
      "x": -15,
      "y": 4,
      "z": 2,
      "name": "Rock_Marble_Brick"
    },
    {
      "x": -15,
      "y": 5,
      "z": 2,
      "name": "Rock_Marble_Brick_Decorative"
    },
    {
      "x": -15,
      "y": 6,
      "z": 2,
      "name": "Rock_Marble_Brick"
    },
    {
      "x": -15,
      "y": 7,
      "z": 2,
      "name": "Rock_Marble_Brick"
    },
    {
      "x": -15,
      "y": 8,
      "z": 2,
      "name": "Rock_Marble_Brick"
    },
    {
      "x": -15,
      "y": 9,
      "z": 2,
      "name": "Rock_Marble_Brick"
    },
    {
      "x": -15,
      "y": 10,
      "z": 2,
      "name": "Rock_Ice"
    },
    {
      "x": -15,
      "y": 11,
      "z": 2,
      "name": "Empty"
    },
    {
      "x": -15,
      "y": 0,
      "z": 3,
      "name": "Rock_Marble_Brick"
    },
    {
      "x": -15,
      "y": 1,
      "z": 3,
      "name": "Rock_Marble_Brick"
    },
    {
      "x": -15,
      "y": 2,
      "z": 3,
      "name": "Rock_Marble_Brick"
    },
    {
      "x": -15,
      "y": 3,
      "z": 3,
      "name": "Rock_Marble_Brick"
    },
    {
      "x": -15,
      "y": 4,
      "z": 3,
      "name": "Rock_Marble_Brick"
    },
    {
      "x": -15,
      "y": 5,
      "z": 3,
      "name": "Rock_Ice"
    },
    {
      "x": -15,
      "y": 6,
      "z": 3,
      "name": "Rock_Ice"
    },
    {
      "x": -15,
      "y": 7,
      "z": 3,
      "name": "Rock_Marble_Brick"
    },
    {
      "x": -15,
      "y": 8,
      "z": 3,
      "name": "Rock_Marble_Brick"
    },
    {
      "x": -15,
      "y": 9,
      "z": 3,
      "name": "Rock_Marble_Brick"
    },
    {
      "x": -15,
      "y": 10,
      "z": 3,
      "name": "Rock_Marble_Brick"
    },
    {
      "x": -15,
      "y": 11,
      "z": 3,
      "name": "Empty"
    },
    {
      "x": -15,
      "y": 0,
      "z": 4,
      "name": "Rock_Marble_Brick"
    },
    {
      "x": -15,
      "y": 1,
      "z": 4,
      "name": "Rock_Marble_Brick"
    },
    {
      "x": -15,
      "y": 2,
      "z": 4,
      "name": "Rock_Marble_Brick"
    },
    {
      "x": -15,
      "y": 3,
      "z": 4,
      "name": "Rock_Marble_Brick"
    },
    {
      "x": -15,
      "y": 4,
      "z": 4,
      "name": "Rock_Marble_Brick"
    },
    {
      "x": -15,
      "y": 5,
      "z": 4,
      "name": "Rock_Marble_Brick_Decorative"
    },
    {
      "x": -15,
      "y": 6,
      "z": 4,
      "name": "Rock_Ice"
    },
    {
      "x": -15,
      "y": 7,
      "z": 4,
      "name": "Rock_Ice"
    },
    {
      "x": -15,
      "y": 8,
      "z": 4,
      "name": "Rock_Marble_Brick"
    },
    {
      "x": -15,
      "y": 9,
      "z": 4,
      "name": "Rock_Marble_Brick"
    },
    {
      "x": -15,
      "y": 10,
      "z": 4,
      "name": "Rock_Ice"
    },
    {
      "x": -15,
      "y": 11,
      "z": 4,
      "name": "Empty"
    },
    {
      "x": -15,
      "y": 0,
      "z": 5,
      "name": "Rock_Marble_Brick"
    },
    {
      "x": -15,
      "y": 1,
      "z": 5,
      "name": "Rock_Marble_Brick"
    },
    {
      "x": -15,
      "y": 2,
      "z": 5,
      "name": "Rock_Marble_Brick"
    },
    {
      "x": -15,
      "y": 3,
      "z": 5,
      "name": "Rock_Marble_Brick"
    },
    {
      "x": -15,
      "y": 4,
      "z": 5,
      "name": "Rock_Marble_Brick"
    },
    {
      "x": -15,
      "y": 5,
      "z": 5,
      "name": "Rock_Marble_Brick_Decorative"
    },
    {
      "x": -15,
      "y": 6,
      "z": 5,
      "name": "Rock_Marble_Brick"
    },
    {
      "x": -15,
      "y": 7,
      "z": 5,
      "name": "Rock_Marble_Brick"
    },
    {
      "x": -15,
      "y": 8,
      "z": 5,
      "name": "Rock_Marble_Brick"
    },
    {
      "x": -15,
      "y": 9,
      "z": 5,
      "name": "Rock_Marble_Brick"
    },
    {
      "x": -15,
      "y": 10,
      "z": 5,
      "name": "Rock_Marble_Brick"
    },
    {
      "x": -15,
      "y": 11,
      "z": 5,
      "name": "Empty"
    },
    {
      "x": -15,
      "y": 0,
      "z": 6,
      "name": "Rock_Marble_Brick"
    },
    {
      "x": -15,
      "y": 1,
      "z": 6,
      "name": "Rock_Marble_Brick"
    },
    {
      "x": -15,
      "y": 2,
      "z": 6,
      "name": "Rock_Marble_Brick"
    },
    {
      "x": -15,
      "y": 3,
      "z": 6,
      "name": "Rock_Marble_Brick"
    },
    {
      "x": -15,
      "y": 4,
      "z": 6,
      "name": "Rock_Marble_Brick"
    },
    {
      "x": -15,
      "y": 5,
      "z": 6,
      "name": "Rock_Marble_Brick_Decorative"
    },
    {
      "x": -15,
      "y": 6,
      "z": 6,
      "name": "Rock_Marble_Brick"
    },
    {
      "x": -15,
      "y": 7,
      "z": 6,
      "name": "Rock_Ice"
    },
    {
      "x": -15,
      "y": 8,
      "z": 6,
      "name": "Rock_Marble_Brick"
    },
    {
      "x": -15,
      "y": 9,
      "z": 6,
      "name": "Rock_Marble_Brick"
    },
    {
      "x": -15,
      "y": 10,
      "z": 6,
      "name": "Rock_Marble_Brick"
    },
    {
      "x": -15,
      "y": 11,
      "z": 6,
      "name": "Empty"
    },
    {
      "x": -15,
      "y": 0,
      "z": 7,
      "name": "Rock_Marble_Brick"
    },
    {
      "x": -15,
      "y": 1,
      "z": 7,
      "name": "Rock_Marble_Brick"
    },
    {
      "x": -15,
      "y": 2,
      "z": 7,
      "name": "Rock_Marble_Brick"
    },
    {
      "x": -15,
      "y": 3,
      "z": 7,
      "name": "Rock_Marble_Brick"
    },
    {
      "x": -15,
      "y": 4,
      "z": 7,
      "name": "Rock_Marble_Brick"
    },
    {
      "x": -15,
      "y": 5,
      "z": 7,
      "name": "Rock_Marble_Brick_Decorative"
    },
    {
      "x": -15,
      "y": 6,
      "z": 7,
      "name": "Rock_Ice"
    },
    {
      "x": -15,
      "y": 7,
      "z": 7,
      "name": "Rock_Ice"
    },
    {
      "x": -15,
      "y": 8,
      "z": 7,
      "name": "Rock_Marble_Brick"
    },
    {
      "x": -15,
      "y": 9,
      "z": 7,
      "name": "Rock_Marble_Brick"
    },
    {
      "x": -15,
      "y": 10,
      "z": 7,
      "name": "Rock_Ice"
    },
    {
      "x": -15,
      "y": 11,
      "z": 7,
      "name": "Empty"
    },
    {
      "x": -15,
      "y": 0,
      "z": 8,
      "name": "Rock_Marble_Brick"
    },
    {
      "x": -15,
      "y": 1,
      "z": 8,
      "name": "Rock_Marble_Brick"
    },
    {
      "x": -15,
      "y": 2,
      "z": 8,
      "name": "Rock_Marble_Brick"
    },
    {
      "x": -15,
      "y": 3,
      "z": 8,
      "name": "Rock_Marble_Brick"
    },
    {
      "x": -15,
      "y": 4,
      "z": 8,
      "name": "Rock_Marble_Brick"
    },
    {
      "x": -15,
      "y": 5,
      "z": 8,
      "name": "Rock_Marble_Brick_Decorative"
    },
    {
      "x": -15,
      "y": 6,
      "z": 8,
      "name": "Rock_Marble_Brick"
    },
    {
      "x": -15,
      "y": 7,
      "z": 8,
      "name": "Rock_Marble_Brick"
    },
    {
      "x": -15,
      "y": 8,
      "z": 8,
      "name": "Rock_Marble_Brick"
    },
    {
      "x": -15,
      "y": 9,
      "z": 8,
      "name": "Rock_Marble_Brick"
    },
    {
      "x": -15,
      "y": 10,
      "z": 8,
      "name": "Rock_Marble_Brick"
    },
    {
      "x": -15,
      "y": 11,
      "z": 8,
      "name": "Empty"
    },
    {
      "x": -15,
      "y": 0,
      "z": 9,
      "name": "Rock_Marble_Brick"
    },
    {
      "x": -15,
      "y": 1,
      "z": 9,
      "name": "Rock_Marble_Brick"
    },
    {
      "x": -15,
      "y": 2,
      "z": 9,
      "name": "Rock_Marble_Brick"
    },
    {
      "x": -15,
      "y": 3,
      "z": 9,
      "name": "Rock_Marble_Brick"
    },
    {
      "x": -15,
      "y": 4,
      "z": 9,
      "name": "Rock_Marble_Brick",
      "rotation": 2
    },
    {
      "x": -15,
      "y": 5,
      "z": 9,
      "name": "Rock_Marble_Brick_Smooth",
      "rotation": 2
    },
    {
      "x": -15,
      "y": 6,
      "z": 9,
      "name": "Rock_Marble_Brick_Smooth",
      "rotation": 2
    },
    {
      "x": -15,
      "y": 7,
      "z": 9,
      "name": "Rock_Marble_Brick_Smooth",
      "rotation": 2
    },
    {
      "x": -15,
      "y": 8,
      "z": 9,
      "name": "Rock_Marble_Brick_Smooth",
      "rotation": 2
    },
    {
      "x": -15,
      "y": 9,
      "z": 9,
      "name": "Rock_Marble_Brick_Smooth",
      "rotation": 2
    },
    {
      "x": -15,
      "y": 10,
      "z": 9,
      "name": "Rock_Marble_Brick",
      "rotation": 2
    },
    {
      "x": -15,
      "y": 11,
      "z": 9,
      "name": "Empty"
    },
    {
      "x": -15,
      "y": 0,
      "z": 10,
      "name": "Rock_Marble_Brick"
    },
    {
      "x": -15,
      "y": 1,
      "z": 10,
      "name": "Rock_Marble_Brick"
    },
    {
      "x": -15,
      "y": 2,
      "z": 10,
      "name": "Rock_Marble_Brick"
    },
    {
      "x": -15,
      "y": 3,
      "z": 10,
      "name": "Rock_Marble_Brick"
    },
    {
      "x": -15,
      "y": 4,
      "z": 10,
      "name": "Rock_Marble_Brick",
      "rotation": 2
    },
    {
      "x": -15,
      "y": 5,
      "z": 10,
      "name": "Rock_Marble_Brick_Smooth_Half",
      "rotation": 4
    },
    {
      "x": -15,
      "y": 6,
      "z": 10,
      "name": "Rock_Marble_Brick_Smooth_Half",
      "rotation": 4
    },
    {
      "x": -15,
      "y": 7,
      "z": 10,
      "name": "Rock_Marble_Brick_Smooth_Half",
      "rotation": 4
    },
    {
      "x": -15,
      "y": 8,
      "z": 10,
      "name": "Rock_Marble_Brick_Smooth_Half",
      "rotation": 4
    },
    {
      "x": -15,
      "y": 9,
      "z": 10,
      "name": "Rock_Marble_Brick_Smooth",
      "rotation": 2
    },
    {
      "x": -15,
      "y": 10,
      "z": 10,
      "name": "Rock_Marble_Brick",
      "rotation": 2
    },
    {
      "x": -15,
      "y": 11,
      "z": 10,
      "name": "Empty"
    },
    {
      "x": -15,
      "y": 0,
      "z": 11,
      "name": "Rock_Marble_Brick"
    },
    {
      "x": -15,
      "y": 1,
      "z": 11,
      "name": "Rock_Marble_Brick"
    },
    {
      "x": -15,
      "y": 2,
      "z": 11,
      "name": "Rock_Marble_Brick"
    },
    {
      "x": -15,
      "y": 3,
      "z": 11,
      "name": "Rock_Marble_Brick"
    },
    {
      "x": -15,
      "y": 4,
      "z": 11,
      "name": "Rock_Marble_Brick",
      "rotation": 2
    },
    {
      "x": -15,
      "y": 5,
      "z": 11,
      "name": "Empty"
    },
    {
      "x": -15,
      "y": 6,
      "z": 11,
      "name": "Empty"
    },
    {
      "x": -15,
      "y": 7,
      "z": 11,
      "name": "Empty"
    },
    {
      "x": -15,
      "y": 8,
      "z": 11,
      "name": "Empty"
    },
    {
      "x": -15,
      "y": 9,
      "z": 11,
      "name": "Rock_Marble_Brick_Smooth_Half",
      "rotation": 10
    },
    {
      "x": -15,
      "y": 10,
      "z": 11,
      "name": "Rock_Ice",
      "rotation": 2
    },
    {
      "x": -15,
      "y": 11,
      "z": 11,
      "name": "Empty"
    },
    {
      "x": -15,
      "y": 0,
      "z": 12,
      "name": "Rock_Marble_Brick"
    },
    {
      "x": -15,
      "y": 1,
      "z": 12,
      "name": "Rock_Marble_Brick"
    },
    {
      "x": -15,
      "y": 2,
      "z": 12,
      "name": "Rock_Marble_Brick"
    },
    {
      "x": -15,
      "y": 3,
      "z": 12,
      "name": "Rock_Marble_Brick"
    },
    {
      "x": -15,
      "y": 4,
      "z": 12,
      "name": "Rock_Marble_Brick",
      "rotation": 2
    },
    {
      "x": -15,
      "y": 5,
      "z": 12,
      "name": "Furniture_Temple_Light_Pot"
    },
    {
      "x": -15,
      "y": 6,
      "z": 12,
      "name": "Empty"
    },
    {
      "x": -15,
      "y": 7,
      "z": 12,
      "name": "Empty"
    },
    {
      "x": -15,
      "y": 8,
      "z": 12,
      "name": "Empty"
    },
    {
      "x": -15,
      "y": 9,
      "z": 12,
      "name": "Rock_Marble_Brick_Smooth_Half",
      "rotation": 10
    },
    {
      "x": -15,
      "y": 10,
      "z": 12,
      "name": "Rock_Marble_Brick",
      "rotation": 2
    },
    {
      "x": -15,
      "y": 11,
      "z": 12,
      "name": "Empty"
    },
    {
      "x": -15,
      "y": 0,
      "z": 13,
      "name": "Rock_Marble_Brick"
    },
    {
      "x": -15,
      "y": 1,
      "z": 13,
      "name": "Rock_Marble_Brick"
    },
    {
      "x": -15,
      "y": 2,
      "z": 13,
      "name": "Rock_Marble_Brick"
    },
    {
      "x": -15,
      "y": 3,
      "z": 13,
      "name": "Rock_Marble_Brick"
    },
    {
      "x": -15,
      "y": 4,
      "z": 13,
      "name": "Rock_Marble_Brick",
      "rotation": 2
    },
    {
      "x": -15,
      "y": 5,
      "z": 13,
      "name": "Rock_Marble_Brick_Smooth_Half",
      "rotation": 6
    },
    {
      "x": -15,
      "y": 6,
      "z": 13,
      "name": "Rock_Marble_Brick_Smooth_Half",
      "rotation": 6
    },
    {
      "x": -15,
      "y": 7,
      "z": 13,
      "name": "Rock_Marble_Brick_Smooth_Half",
      "rotation": 6
    },
    {
      "x": -15,
      "y": 8,
      "z": 13,
      "name": "Rock_Marble_Brick_Smooth_Half",
      "rotation": 6
    },
    {
      "x": -15,
      "y": 9,
      "z": 13,
      "name": "Rock_Marble_Brick_Smooth",
      "rotation": 2
    },
    {
      "x": -15,
      "y": 10,
      "z": 13,
      "name": "Rock_Marble_Brick",
      "rotation": 2
    },
    {
      "x": -15,
      "y": 11,
      "z": 13,
      "name": "Empty"
    },
    {
      "x": -15,
      "y": 0,
      "z": 14,
      "name": "Rock_Marble_Brick"
    },
    {
      "x": -15,
      "y": 1,
      "z": 14,
      "name": "Rock_Marble_Brick"
    },
    {
      "x": -15,
      "y": 2,
      "z": 14,
      "name": "Rock_Marble_Brick"
    },
    {
      "x": -15,
      "y": 3,
      "z": 14,
      "name": "Rock_Marble_Brick"
    },
    {
      "x": -15,
      "y": 4,
      "z": 14,
      "name": "Rock_Marble_Brick",
      "rotation": 2
    },
    {
      "x": -15,
      "y": 5,
      "z": 14,
      "name": "Rock_Marble_Brick_Decorative",
      "rotation": 2
    },
    {
      "x": -15,
      "y": 6,
      "z": 14,
      "name": "Rock_Marble_Brick",
      "rotation": 2
    },
    {
      "x": -15,
      "y": 7,
      "z": 14,
      "name": "Rock_Marble_Brick",
      "rotation": 2
    },
    {
      "x": -15,
      "y": 8,
      "z": 14,
      "name": "Rock_Marble_Brick",
      "rotation": 2
    },
    {
      "x": -15,
      "y": 9,
      "z": 14,
      "name": "Rock_Marble_Brick",
      "rotation": 2
    },
    {
      "x": -15,
      "y": 10,
      "z": 14,
      "name": "Rock_Marble_Brick",
      "rotation": 2
    },
    {
      "x": -15,
      "y": 11,
      "z": 14,
      "name": "Empty"
    },
    {
      "x": -15,
      "y": 0,
      "z": 15,
      "name": "Rock_Marble_Brick"
    },
    {
      "x": -15,
      "y": 1,
      "z": 15,
      "name": "Rock_Marble_Brick"
    },
    {
      "x": -15,
      "y": 2,
      "z": 15,
      "name": "Rock_Marble_Brick"
    },
    {
      "x": -15,
      "y": 3,
      "z": 15,
      "name": "Rock_Marble_Brick"
    },
    {
      "x": -15,
      "y": 4,
      "z": 15,
      "name": "Empty"
    },
    {
      "x": -15,
      "y": 5,
      "z": 15,
      "name": "Empty"
    },
    {
      "x": -15,
      "y": 6,
      "z": 15,
      "name": "Empty"
    },
    {
      "x": -15,
      "y": 7,
      "z": 15,
      "name": "Empty"
    },
    {
      "x": -15,
      "y": 8,
      "z": 15,
      "name": "Empty"
    },
    {
      "x": -15,
      "y": 9,
      "z": 15,
      "name": "Empty"
    },
    {
      "x": -15,
      "y": 10,
      "z": 15,
      "name": "Empty"
    },
    {
      "x": -15,
      "y": 11,
      "z": 15,
      "name": "Empty"
    },
    {
      "x": -14,
      "y": 0,
      "z": -14,
      "name": "Rock_Marble_Brick"
    },
    {
      "x": -14,
      "y": 1,
      "z": -14,
      "name": "Rock_Marble_Brick"
    },
    {
      "x": -14,
      "y": 2,
      "z": -14,
      "name": "Rock_Marble_Brick"
    },
    {
      "x": -14,
      "y": 3,
      "z": -14,
      "name": "Rock_Marble_Brick"
    },
    {
      "x": -14,
      "y": 4,
      "z": -14,
      "name": "Rock_Marble_Brick"
    },
    {
      "x": -14,
      "y": 5,
      "z": -14,
      "name": "Rock_Marble_Brick_Decorative"
    },
    {
      "x": -14,
      "y": 6,
      "z": -14,
      "name": "Rock_Marble_Brick"
    },
    {
      "x": -14,
      "y": 7,
      "z": -14,
      "name": "Rock_Marble_Brick"
    },
    {
      "x": -14,
      "y": 8,
      "z": -14,
      "name": "Rock_Ice"
    },
    {
      "x": -14,
      "y": 9,
      "z": -14,
      "name": "Rock_Marble_Brick"
    },
    {
      "x": -14,
      "y": 10,
      "z": -14,
      "name": "Rock_Marble_Brick"
    },
    {
      "x": -14,
      "y": 11,
      "z": -14,
      "name": "Empty"
    },
    {
      "x": -14,
      "y": 0,
      "z": -13,
      "name": "Rock_Marble_Brick"
    },
    {
      "x": -14,
      "y": 1,
      "z": -13,
      "name": "Rock_Marble_Brick"
    },
    {
      "x": -14,
      "y": 2,
      "z": -13,
      "name": "Rock_Marble_Brick"
    },
    {
      "x": -14,
      "y": 3,
      "z": -13,
      "name": "Rock_Marble_Brick"
    },
    {
      "x": -14,
      "y": 4,
      "z": -13,
      "name": "Rock_Marble_Brick"
    },
    {
      "x": -14,
      "y": 5,
      "z": -13,
      "name": "Empty"
    },
    {
      "x": -14,
      "y": 6,
      "z": -13,
      "name": "Empty"
    },
    {
      "x": -14,
      "y": 7,
      "z": -13,
      "name": "Empty"
    },
    {
      "x": -14,
      "y": 8,
      "z": -13,
      "name": "Empty"
    },
    {
      "x": -14,
      "y": 9,
      "z": -13,
      "name": "Rock_Marble_Brick_Smooth_Half",
      "rotation": 4
    },
    {
      "x": -14,
      "y": 10,
      "z": -13,
      "name": "Rock_Ice"
    },
    {
      "x": -14,
      "y": 11,
      "z": -13,
      "name": "Empty"
    },
    {
      "x": -14,
      "y": 0,
      "z": -12,
      "name": "Rock_Marble_Brick"
    },
    {
      "x": -14,
      "y": 1,
      "z": -12,
      "name": "Rock_Marble_Brick"
    },
    {
      "x": -14,
      "y": 2,
      "z": -12,
      "name": "Rock_Marble_Brick"
    },
    {
      "x": -14,
      "y": 3,
      "z": -12,
      "name": "Rock_Marble_Brick"
    },
    {
      "x": -14,
      "y": 4,
      "z": -12,
      "name": "Rock_Marble_Brick"
    },
    {
      "x": -14,
      "y": 5,
      "z": -12,
      "name": "Empty"
    },
    {
      "x": -14,
      "y": 6,
      "z": -12,
      "name": "Empty"
    },
    {
      "x": -14,
      "y": 7,
      "z": -12,
      "name": "Empty"
    },
    {
      "x": -14,
      "y": 8,
      "z": -12,
      "name": "Empty"
    },
    {
      "x": -14,
      "y": 9,
      "z": -12,
      "name": "Empty"
    },
    {
      "x": -14,
      "y": 10,
      "z": -12,
      "name": "Rock_Marble_Brick"
    },
    {
      "x": -14,
      "y": 11,
      "z": -12,
      "name": "Empty"
    },
    {
      "x": -14,
      "y": 0,
      "z": -11,
      "name": "Rock_Marble_Brick"
    },
    {
      "x": -14,
      "y": 1,
      "z": -11,
      "name": "Rock_Marble_Brick"
    },
    {
      "x": -14,
      "y": 2,
      "z": -11,
      "name": "Rock_Marble_Brick"
    },
    {
      "x": -14,
      "y": 3,
      "z": -11,
      "name": "Rock_Marble_Brick"
    },
    {
      "x": -14,
      "y": 4,
      "z": -11,
      "name": "Rock_Ice"
    },
    {
      "x": -14,
      "y": 5,
      "z": -11,
      "name": "Empty"
    },
    {
      "x": -14,
      "y": 6,
      "z": -11,
      "name": "Empty"
    },
    {
      "x": -14,
      "y": 7,
      "z": -11,
      "name": "Empty"
    },
    {
      "x": -14,
      "y": 8,
      "z": -11,
      "name": "Empty"
    },
    {
      "x": -14,
      "y": 9,
      "z": -11,
      "name": "Empty"
    },
    {
      "x": -14,
      "y": 10,
      "z": -11,
      "name": "Rock_Marble_Brick"
    },
    {
      "x": -14,
      "y": 11,
      "z": -11,
      "name": "Empty"
    },
    {
      "x": -14,
      "y": 0,
      "z": -10,
      "name": "Rock_Marble_Brick"
    },
    {
      "x": -14,
      "y": 1,
      "z": -10,
      "name": "Rock_Marble_Brick"
    },
    {
      "x": -14,
      "y": 2,
      "z": -10,
      "name": "Rock_Marble_Brick"
    },
    {
      "x": -14,
      "y": 3,
      "z": -10,
      "name": "Rock_Marble_Brick"
    },
    {
      "x": -14,
      "y": 4,
      "z": -10,
      "name": "Rock_Marble_Brick"
    },
    {
      "x": -14,
      "y": 5,
      "z": -10,
      "name": "Rubble_Ice",
      "support": 15
    },
    {
      "x": -14,
      "y": 6,
      "z": -10,
      "name": "Empty"
    },
    {
      "x": -14,
      "y": 7,
      "z": -10,
      "name": "Empty"
    },
    {
      "x": -14,
      "y": 8,
      "z": -10,
      "name": "Empty"
    },
    {
      "x": -14,
      "y": 9,
      "z": -10,
      "name": "Rock_Marble_Brick_Smooth_Half",
      "rotation": 6
    },
    {
      "x": -14,
      "y": 10,
      "z": -10,
      "name": "Rock_Marble_Brick"
    },
    {
      "x": -14,
      "y": 11,
      "z": -10,
      "name": "Empty"
    },
    {
      "x": -14,
      "y": 0,
      "z": -9,
      "name": "Rock_Marble_Brick"
    },
    {
      "x": -14,
      "y": 1,
      "z": -9,
      "name": "Rock_Marble_Brick"
    },
    {
      "x": -14,
      "y": 2,
      "z": -9,
      "name": "Rock_Marble_Brick"
    },
    {
      "x": -14,
      "y": 3,
      "z": -9,
      "name": "Rock_Marble_Brick"
    },
    {
      "x": -14,
      "y": 4,
      "z": -9,
      "name": "Rock_Marble_Brick"
    },
    {
      "x": -14,
      "y": 5,
      "z": -9,
      "name": "Rock_Calcite_Brick_Ornate"
    },
    {
      "x": -14,
      "y": 6,
      "z": -9,
      "name": "Rock_Calcite_Brick_Smooth"
    },
    {
      "x": -14,
      "y": 7,
      "z": -9,
      "name": "Rock_Calcite_Brick_Smooth"
    },
    {
      "x": -14,
      "y": 8,
      "z": -9,
      "name": "Rock_Calcite_Brick_Ornate"
    },
    {
      "x": -14,
      "y": 9,
      "z": -9,
      "name": "Rock_Calcite_Brick_Smooth"
    },
    {
      "x": -14,
      "y": 10,
      "z": -9,
      "name": "Rock_Marble_Brick"
    },
    {
      "x": -14,
      "y": 11,
      "z": -9,
      "name": "Empty"
    },
    {
      "x": -14,
      "y": 0,
      "z": -8,
      "name": "Rock_Marble_Brick"
    },
    {
      "x": -14,
      "y": 1,
      "z": -8,
      "name": "Rock_Marble_Brick"
    },
    {
      "x": -14,
      "y": 2,
      "z": -8,
      "name": "Rock_Marble_Brick"
    },
    {
      "x": -14,
      "y": 3,
      "z": -8,
      "name": "Rock_Marble_Brick"
    },
    {
      "x": -14,
      "y": 4,
      "z": -8,
      "name": "Rock_Ice"
    },
    {
      "x": -14,
      "y": 5,
      "z": -8,
      "name": "Empty"
    },
    {
      "x": -14,
      "y": 6,
      "z": -8,
      "name": "Empty"
    },
    {
      "x": -14,
      "y": 7,
      "z": -8,
      "name": "Empty"
    },
    {
      "x": -14,
      "y": 8,
      "z": -8,
      "name": "Empty"
    },
    {
      "x": -14,
      "y": 9,
      "z": -8,
      "name": "Rock_Marble_Brick_Smooth"
    },
    {
      "x": -14,
      "y": 10,
      "z": -8,
      "name": "Rock_Marble_Brick"
    },
    {
      "x": -14,
      "y": 11,
      "z": -8,
      "name": "Empty"
    },
    {
      "x": -14,
      "y": 0,
      "z": -7,
      "name": "Rock_Marble_Brick"
    },
    {
      "x": -14,
      "y": 1,
      "z": -7,
      "name": "Rock_Marble_Brick"
    },
    {
      "x": -14,
      "y": 2,
      "z": -7,
      "name": "Rock_Marble_Brick"
    },
    {
      "x": -14,
      "y": 3,
      "z": -7,
      "name": "Rock_Marble_Brick"
    },
    {
      "x": -14,
      "y": 4,
      "z": -7,
      "name": "Rock_Marble_Brick"
    },
    {
      "x": -14,
      "y": 5,
      "z": -7,
      "name": "Empty"
    },
    {
      "x": -14,
      "y": 6,
      "z": -7,
      "name": "Empty"
    },
    {
      "x": -14,
      "y": 7,
      "z": -7,
      "name": "Empty"
    },
    {
      "x": -14,
      "y": 8,
      "z": -7,
      "name": "Empty"
    },
    {
      "x": -14,
      "y": 9,
      "z": -7,
      "name": "Rock_Marble_Brick_Smooth_Half",
      "rotation": 5
    },
    {
      "x": -14,
      "y": 10,
      "z": -7,
      "name": "Rock_Ice"
    },
    {
      "x": -14,
      "y": 11,
      "z": -7,
      "name": "Empty"
    },
    {
      "x": -14,
      "y": 0,
      "z": -6,
      "name": "Rock_Marble_Brick"
    },
    {
      "x": -14,
      "y": 1,
      "z": -6,
      "name": "Rock_Marble_Brick"
    },
    {
      "x": -14,
      "y": 2,
      "z": -6,
      "name": "Rock_Marble_Brick"
    },
    {
      "x": -14,
      "y": 3,
      "z": -6,
      "name": "Rock_Marble_Brick"
    },
    {
      "x": -14,
      "y": 4,
      "z": -6,
      "name": "Rock_Ice"
    },
    {
      "x": -14,
      "y": 5,
      "z": -6,
      "name": "Rubble_Ice",
      "support": 15
    },
    {
      "x": -14,
      "y": 6,
      "z": -6,
      "name": "Empty"
    },
    {
      "x": -14,
      "y": 7,
      "z": -6,
      "name": "Empty"
    },
    {
      "x": -14,
      "y": 8,
      "z": -6,
      "name": "Empty"
    },
    {
      "x": -14,
      "y": 9,
      "z": -6,
      "name": "Rock_Marble_Brick_Smooth_Half",
      "rotation": 5
    },
    {
      "x": -14,
      "y": 10,
      "z": -6,
      "name": "Rock_Marble_Brick"
    },
    {
      "x": -14,
      "y": 11,
      "z": -6,
      "name": "Empty"
    },
    {
      "x": -14,
      "y": 0,
      "z": -5,
      "name": "Rock_Marble_Brick"
    },
    {
      "x": -14,
      "y": 1,
      "z": -5,
      "name": "Rock_Marble_Brick"
    },
    {
      "x": -14,
      "y": 2,
      "z": -5,
      "name": "Rock_Marble_Brick"
    },
    {
      "x": -14,
      "y": 3,
      "z": -5,
      "name": "Rock_Marble_Brick"
    },
    {
      "x": -14,
      "y": 4,
      "z": -5,
      "name": "Rock_Marble_Brick"
    },
    {
      "x": -14,
      "y": 5,
      "z": -5,
      "name": "Empty"
    },
    {
      "x": -14,
      "y": 6,
      "z": -5,
      "name": "Empty"
    },
    {
      "x": -14,
      "y": 7,
      "z": -5,
      "name": "Empty"
    },
    {
      "x": -14,
      "y": 8,
      "z": -5,
      "name": "Empty"
    },
    {
      "x": -14,
      "y": 9,
      "z": -5,
      "name": "Rock_Marble_Brick_Smooth_Half",
      "rotation": 5
    },
    {
      "x": -14,
      "y": 10,
      "z": -5,
      "name": "Rock_Ice"
    },
    {
      "x": -14,
      "y": 11,
      "z": -5,
      "name": "Empty"
    },
    {
      "x": -14,
      "y": 0,
      "z": -4,
      "name": "Rock_Marble_Brick"
    },
    {
      "x": -14,
      "y": 1,
      "z": -4,
      "name": "Rock_Marble_Brick"
    },
    {
      "x": -14,
      "y": 2,
      "z": -4,
      "name": "Rock_Marble_Brick"
    },
    {
      "x": -14,
      "y": 3,
      "z": -4,
      "name": "Rock_Marble_Brick"
    },
    {
      "x": -14,
      "y": 4,
      "z": -4,
      "name": "Rock_Marble_Brick"
    },
    {
      "x": -14,
      "y": 5,
      "z": -4,
      "name": "Empty"
    },
    {
      "x": -14,
      "y": 6,
      "z": -4,
      "name": "Empty"
    },
    {
      "x": -14,
      "y": 7,
      "z": -4,
      "name": "Empty"
    },
    {
      "x": -14,
      "y": 8,
      "z": -4,
      "name": "Empty"
    },
    {
      "x": -14,
      "y": 9,
      "z": -4,
      "name": "Rock_Marble_Brick_Smooth"
    },
    {
      "x": -14,
      "y": 10,
      "z": -4,
      "name": "Rock_Marble_Brick"
    },
    {
      "x": -14,
      "y": 11,
      "z": -4,
      "name": "Empty"
    },
    {
      "x": -14,
      "y": 0,
      "z": -3,
      "name": "Rock_Marble_Brick"
    },
    {
      "x": -14,
      "y": 1,
      "z": -3,
      "name": "Rock_Marble_Brick"
    },
    {
      "x": -14,
      "y": 2,
      "z": -3,
      "name": "Rock_Marble_Brick"
    },
    {
      "x": -14,
      "y": 3,
      "z": -3,
      "name": "Rock_Marble_Brick"
    },
    {
      "x": -14,
      "y": 4,
      "z": -3,
      "name": "Rock_Calcite_Brick_Smooth"
    },
    {
      "x": -14,
      "y": 5,
      "z": -3,
      "name": "Rock_Calcite_Brick_Ornate"
    },
    {
      "x": -14,
      "y": 6,
      "z": -3,
      "name": "Rock_Calcite_Brick_Smooth"
    },
    {
      "x": -14,
      "y": 7,
      "z": -3,
      "name": "Rock_Calcite_Brick_Smooth"
    },
    {
      "x": -14,
      "y": 8,
      "z": -3,
      "name": "Rock_Calcite_Brick_Ornate"
    },
    {
      "x": -14,
      "y": 9,
      "z": -3,
      "name": "Rock_Calcite_Brick_Smooth"
    },
    {
      "x": -14,
      "y": 10,
      "z": -3,
      "name": "Rock_Marble_Brick"
    },
    {
      "x": -14,
      "y": 11,
      "z": -3,
      "name": "Empty"
    },
    {
      "x": -14,
      "y": 0,
      "z": -2,
      "name": "Rock_Marble_Brick"
    },
    {
      "x": -14,
      "y": 1,
      "z": -2,
      "name": "Rock_Marble_Brick"
    },
    {
      "x": -14,
      "y": 2,
      "z": -2,
      "name": "Rock_Marble_Brick"
    },
    {
      "x": -14,
      "y": 3,
      "z": -2,
      "name": "Rock_Marble_Brick"
    },
    {
      "x": -14,
      "y": 4,
      "z": -2,
      "name": "Rock_Marble_Brick"
    },
    {
      "x": -14,
      "y": 5,
      "z": -2,
      "name": "Empty"
    },
    {
      "x": -14,
      "y": 6,
      "z": -2,
      "name": "Empty"
    },
    {
      "x": -14,
      "y": 7,
      "z": -2,
      "name": "Empty"
    },
    {
      "x": -14,
      "y": 8,
      "z": -2,
      "name": "Empty"
    },
    {
      "x": -14,
      "y": 9,
      "z": -2,
      "name": "Rock_Marble_Brick_Smooth"
    },
    {
      "x": -14,
      "y": 10,
      "z": -2,
      "name": "Rock_Marble_Brick"
    },
    {
      "x": -14,
      "y": 11,
      "z": -2,
      "name": "Empty"
    },
    {
      "x": -14,
      "y": 0,
      "z": -1,
      "name": "Rock_Marble_Brick"
    },
    {
      "x": -14,
      "y": 1,
      "z": -1,
      "name": "Rock_Marble_Brick"
    },
    {
      "x": -14,
      "y": 2,
      "z": -1,
      "name": "Rock_Marble_Brick"
    },
    {
      "x": -14,
      "y": 3,
      "z": -1,
      "name": "Rock_Marble_Brick"
    },
    {
      "x": -14,
      "y": 4,
      "z": -1,
      "name": "Rock_Ice"
    },
    {
      "x": -14,
      "y": 5,
      "z": -1,
      "name": "Rubble_Ice",
      "support": 15
    },
    {
      "x": -14,
      "y": 6,
      "z": -1,
      "name": "Empty"
    },
    {
      "x": -14,
      "y": 7,
      "z": -1,
      "name": "Empty"
    },
    {
      "x": -14,
      "y": 8,
      "z": -1,
      "name": "Empty"
    },
    {
      "x": -14,
      "y": 9,
      "z": -1,
      "name": "Rock_Marble_Brick_Smooth_Half",
      "rotation": 5
    },
    {
      "x": -14,
      "y": 10,
      "z": -1,
      "name": "Rock_Marble_Brick"
    },
    {
      "x": -14,
      "y": 11,
      "z": -1,
      "name": "Empty"
    },
    {
      "x": -14,
      "y": 0,
      "z": 0,
      "name": "Rock_Marble_Brick"
    },
    {
      "x": -14,
      "y": 1,
      "z": 0,
      "name": "Rock_Marble_Brick"
    },
    {
      "x": -14,
      "y": 2,
      "z": 0,
      "name": "Rock_Marble_Brick"
    },
    {
      "x": -14,
      "y": 3,
      "z": 0,
      "name": "Rock_Marble_Brick"
    },
    {
      "x": -14,
      "y": 4,
      "z": 0,
      "name": "Rock_Marble_Brick"
    },
    {
      "x": -14,
      "y": 5,
      "z": 0,
      "name": "Empty"
    },
    {
      "x": -14,
      "y": 6,
      "z": 0,
      "name": "Empty"
    },
    {
      "x": -14,
      "y": 7,
      "z": 0,
      "name": "Empty"
    },
    {
      "x": -14,
      "y": 8,
      "z": 0,
      "name": "Empty"
    },
    {
      "x": -14,
      "y": 9,
      "z": 0,
      "name": "Rock_Marble_Brick_Smooth_Half",
      "rotation": 5
    },
    {
      "x": -14,
      "y": 10,
      "z": 0,
      "name": "Rock_Marble_Brick"
    },
    {
      "x": -14,
      "y": 11,
      "z": 0,
      "name": "Empty"
    },
    {
      "x": -14,
      "y": 0,
      "z": 1,
      "name": "Rock_Marble_Brick"
    },
    {
      "x": -14,
      "y": 1,
      "z": 1,
      "name": "Rock_Marble_Brick"
    },
    {
      "x": -14,
      "y": 2,
      "z": 1,
      "name": "Rock_Marble_Brick"
    },
    {
      "x": -14,
      "y": 3,
      "z": 1,
      "name": "Rock_Marble_Brick"
    },
    {
      "x": -14,
      "y": 4,
      "z": 1,
      "name": "Rock_Marble_Brick"
    },
    {
      "x": -14,
      "y": 5,
      "z": 1,
      "name": "Empty"
    },
    {
      "x": -14,
      "y": 6,
      "z": 1,
      "name": "Empty"
    },
    {
      "x": -14,
      "y": 7,
      "z": 1,
      "name": "Empty"
    },
    {
      "x": -14,
      "y": 8,
      "z": 1,
      "name": "Empty"
    },
    {
      "x": -14,
      "y": 9,
      "z": 1,
      "name": "Rock_Marble_Brick_Smooth_Half",
      "rotation": 5
    },
    {
      "x": -14,
      "y": 10,
      "z": 1,
      "name": "Rock_Marble_Brick"
    },
    {
      "x": -14,
      "y": 11,
      "z": 1,
      "name": "Empty"
    },
    {
      "x": -14,
      "y": 0,
      "z": 2,
      "name": "Rock_Marble_Brick"
    },
    {
      "x": -14,
      "y": 1,
      "z": 2,
      "name": "Rock_Marble_Brick"
    },
    {
      "x": -14,
      "y": 2,
      "z": 2,
      "name": "Rock_Marble_Brick"
    },
    {
      "x": -14,
      "y": 3,
      "z": 2,
      "name": "Rock_Marble_Brick"
    },
    {
      "x": -14,
      "y": 4,
      "z": 2,
      "name": "Rock_Marble_Brick"
    },
    {
      "x": -14,
      "y": 5,
      "z": 2,
      "name": "Empty"
    },
    {
      "x": -14,
      "y": 6,
      "z": 2,
      "name": "Empty"
    },
    {
      "x": -14,
      "y": 7,
      "z": 2,
      "name": "Empty"
    },
    {
      "x": -14,
      "y": 8,
      "z": 2,
      "name": "Empty"
    },
    {
      "x": -14,
      "y": 9,
      "z": 2,
      "name": "Rock_Marble_Brick_Smooth"
    },
    {
      "x": -14,
      "y": 10,
      "z": 2,
      "name": "Rock_Marble_Brick"
    },
    {
      "x": -14,
      "y": 11,
      "z": 2,
      "name": "Empty"
    },
    {
      "x": -14,
      "y": 0,
      "z": 3,
      "name": "Rock_Marble_Brick"
    },
    {
      "x": -14,
      "y": 1,
      "z": 3,
      "name": "Rock_Marble_Brick"
    },
    {
      "x": -14,
      "y": 2,
      "z": 3,
      "name": "Rock_Marble_Brick"
    },
    {
      "x": -14,
      "y": 3,
      "z": 3,
      "name": "Rock_Marble_Brick"
    },
    {
      "x": -14,
      "y": 4,
      "z": 3,
      "name": "Rock_Calcite_Brick_Smooth"
    },
    {
      "x": -14,
      "y": 5,
      "z": 3,
      "name": "Rock_Calcite_Brick_Ornate"
    },
    {
      "x": -14,
      "y": 6,
      "z": 3,
      "name": "Rock_Calcite_Brick_Smooth"
    },
    {
      "x": -14,
      "y": 7,
      "z": 3,
      "name": "Rock_Calcite_Brick_Smooth"
    },
    {
      "x": -14,
      "y": 8,
      "z": 3,
      "name": "Rock_Calcite_Brick_Ornate"
    },
    {
      "x": -14,
      "y": 9,
      "z": 3,
      "name": "Rock_Calcite_Brick_Smooth"
    },
    {
      "x": -14,
      "y": 10,
      "z": 3,
      "name": "Rock_Marble_Brick"
    },
    {
      "x": -14,
      "y": 11,
      "z": 3,
      "name": "Empty"
    },
    {
      "x": -14,
      "y": 0,
      "z": 4,
      "name": "Rock_Marble_Brick"
    },
    {
      "x": -14,
      "y": 1,
      "z": 4,
      "name": "Rock_Marble_Brick"
    },
    {
      "x": -14,
      "y": 2,
      "z": 4,
      "name": "Rock_Marble_Brick"
    },
    {
      "x": -14,
      "y": 3,
      "z": 4,
      "name": "Rock_Marble_Brick"
    },
    {
      "x": -14,
      "y": 4,
      "z": 4,
      "name": "Rock_Marble_Brick"
    },
    {
      "x": -14,
      "y": 5,
      "z": 4,
      "name": "Empty"
    },
    {
      "x": -14,
      "y": 6,
      "z": 4,
      "name": "Empty"
    },
    {
      "x": -14,
      "y": 7,
      "z": 4,
      "name": "Empty"
    },
    {
      "x": -14,
      "y": 8,
      "z": 4,
      "name": "Empty"
    },
    {
      "x": -14,
      "y": 9,
      "z": 4,
      "name": "Rock_Marble_Brick_Smooth"
    },
    {
      "x": -14,
      "y": 10,
      "z": 4,
      "name": "Rock_Marble_Brick"
    },
    {
      "x": -14,
      "y": 11,
      "z": 4,
      "name": "Empty"
    },
    {
      "x": -14,
      "y": 0,
      "z": 5,
      "name": "Rock_Marble_Brick"
    },
    {
      "x": -14,
      "y": 1,
      "z": 5,
      "name": "Rock_Marble_Brick"
    },
    {
      "x": -14,
      "y": 2,
      "z": 5,
      "name": "Rock_Marble_Brick"
    },
    {
      "x": -14,
      "y": 3,
      "z": 5,
      "name": "Rock_Marble_Brick"
    },
    {
      "x": -14,
      "y": 4,
      "z": 5,
      "name": "Rock_Ice"
    },
    {
      "x": -14,
      "y": 5,
      "z": 5,
      "name": "Rubble_Ice",
      "support": 15
    },
    {
      "x": -14,
      "y": 6,
      "z": 5,
      "name": "Empty"
    },
    {
      "x": -14,
      "y": 7,
      "z": 5,
      "name": "Empty"
    },
    {
      "x": -14,
      "y": 8,
      "z": 5,
      "name": "Empty"
    },
    {
      "x": -14,
      "y": 9,
      "z": 5,
      "name": "Rock_Marble_Brick_Smooth_Half",
      "rotation": 5
    },
    {
      "x": -14,
      "y": 10,
      "z": 5,
      "name": "Rock_Marble_Brick"
    },
    {
      "x": -14,
      "y": 11,
      "z": 5,
      "name": "Empty"
    },
    {
      "x": -14,
      "y": 0,
      "z": 6,
      "name": "Rock_Marble_Brick"
    },
    {
      "x": -14,
      "y": 1,
      "z": 6,
      "name": "Rock_Marble_Brick"
    },
    {
      "x": -14,
      "y": 2,
      "z": 6,
      "name": "Rock_Marble_Brick"
    },
    {
      "x": -14,
      "y": 3,
      "z": 6,
      "name": "Rock_Marble_Brick"
    },
    {
      "x": -14,
      "y": 4,
      "z": 6,
      "name": "Rock_Marble_Brick"
    },
    {
      "x": -14,
      "y": 5,
      "z": 6,
      "name": "Empty"
    },
    {
      "x": -14,
      "y": 6,
      "z": 6,
      "name": "Empty"
    },
    {
      "x": -14,
      "y": 7,
      "z": 6,
      "name": "Empty"
    },
    {
      "x": -14,
      "y": 8,
      "z": 6,
      "name": "Empty"
    },
    {
      "x": -14,
      "y": 9,
      "z": 6,
      "name": "Rock_Marble_Brick_Smooth_Half",
      "rotation": 5
    },
    {
      "x": -14,
      "y": 10,
      "z": 6,
      "name": "Rock_Marble_Brick"
    },
    {
      "x": -14,
      "y": 11,
      "z": 6,
      "name": "Empty"
    },
    {
      "x": -14,
      "y": 0,
      "z": 7,
      "name": "Rock_Marble_Brick"
    },
    {
      "x": -14,
      "y": 1,
      "z": 7,
      "name": "Rock_Marble_Brick"
    },
    {
      "x": -14,
      "y": 2,
      "z": 7,
      "name": "Rock_Marble_Brick"
    },
    {
      "x": -14,
      "y": 3,
      "z": 7,
      "name": "Rock_Marble_Brick"
    },
    {
      "x": -14,
      "y": 4,
      "z": 7,
      "name": "Rock_Marble_Brick"
    },
    {
      "x": -14,
      "y": 5,
      "z": 7,
      "name": "Empty"
    },
    {
      "x": -14,
      "y": 6,
      "z": 7,
      "name": "Empty"
    },
    {
      "x": -14,
      "y": 7,
      "z": 7,
      "name": "Empty"
    },
    {
      "x": -14,
      "y": 8,
      "z": 7,
      "name": "Empty"
    },
    {
      "x": -14,
      "y": 9,
      "z": 7,
      "name": "Rock_Marble_Brick_Smooth_Half",
      "rotation": 5
    },
    {
      "x": -14,
      "y": 10,
      "z": 7,
      "name": "Rock_Marble_Brick"
    },
    {
      "x": -14,
      "y": 11,
      "z": 7,
      "name": "Empty"
    },
    {
      "x": -14,
      "y": 0,
      "z": 8,
      "name": "Rock_Marble_Brick"
    },
    {
      "x": -14,
      "y": 1,
      "z": 8,
      "name": "Rock_Marble_Brick"
    },
    {
      "x": -14,
      "y": 2,
      "z": 8,
      "name": "Rock_Marble_Brick"
    },
    {
      "x": -14,
      "y": 3,
      "z": 8,
      "name": "Rock_Marble_Brick"
    },
    {
      "x": -14,
      "y": 4,
      "z": 8,
      "name": "Rock_Marble_Brick"
    },
    {
      "x": -14,
      "y": 5,
      "z": 8,
      "name": "Empty"
    },
    {
      "x": -14,
      "y": 6,
      "z": 8,
      "name": "Empty"
    },
    {
      "x": -14,
      "y": 7,
      "z": 8,
      "name": "Empty"
    },
    {
      "x": -14,
      "y": 8,
      "z": 8,
      "name": "Empty"
    },
    {
      "x": -14,
      "y": 9,
      "z": 8,
      "name": "Rock_Marble_Brick_Smooth"
    },
    {
      "x": -14,
      "y": 10,
      "z": 8,
      "name": "Rock_Ice"
    },
    {
      "x": -14,
      "y": 11,
      "z": 8,
      "name": "Empty"
    },
    {
      "x": -14,
      "y": 0,
      "z": 9,
      "name": "Rock_Marble_Brick"
    },
    {
      "x": -14,
      "y": 1,
      "z": 9,
      "name": "Rock_Marble_Brick"
    },
    {
      "x": -14,
      "y": 2,
      "z": 9,
      "name": "Rock_Marble_Brick"
    },
    {
      "x": -14,
      "y": 3,
      "z": 9,
      "name": "Rock_Marble_Brick"
    },
    {
      "x": -14,
      "y": 4,
      "z": 9,
      "name": "Rock_Marble_Brick",
      "rotation": 2
    },
    {
      "x": -14,
      "y": 5,
      "z": 9,
      "name": "Rock_Calcite_Brick_Ornate",
      "rotation": 2
    },
    {
      "x": -14,
      "y": 6,
      "z": 9,
      "name": "Rock_Calcite_Brick_Smooth",
      "rotation": 2
    },
    {
      "x": -14,
      "y": 7,
      "z": 9,
      "name": "Rock_Calcite_Brick_Smooth",
      "rotation": 2
    },
    {
      "x": -14,
      "y": 8,
      "z": 9,
      "name": "Rock_Calcite_Brick_Ornate",
      "rotation": 2
    },
    {
      "x": -14,
      "y": 9,
      "z": 9,
      "name": "Rock_Calcite_Brick_Smooth",
      "rotation": 2
    },
    {
      "x": -14,
      "y": 10,
      "z": 9,
      "name": "Rock_Ice",
      "rotation": 2
    },
    {
      "x": -14,
      "y": 11,
      "z": 9,
      "name": "Empty"
    },
    {
      "x": -14,
      "y": 0,
      "z": 10,
      "name": "Rock_Marble_Brick"
    },
    {
      "x": -14,
      "y": 1,
      "z": 10,
      "name": "Rock_Marble_Brick"
    },
    {
      "x": -14,
      "y": 2,
      "z": 10,
      "name": "Rock_Marble_Brick"
    },
    {
      "x": -14,
      "y": 3,
      "z": 10,
      "name": "Rock_Marble_Brick"
    },
    {
      "x": -14,
      "y": 4,
      "z": 10,
      "name": "Rock_Ice",
      "rotation": 2
    },
    {
      "x": -14,
      "y": 5,
      "z": 10,
      "name": "Rubble_Ice",
      "support": 15
    },
    {
      "x": -14,
      "y": 6,
      "z": 10,
      "name": "Empty"
    },
    {
      "x": -14,
      "y": 7,
      "z": 10,
      "name": "Empty"
    },
    {
      "x": -14,
      "y": 8,
      "z": 10,
      "name": "Empty"
    },
    {
      "x": -14,
      "y": 9,
      "z": 10,
      "name": "Rock_Marble_Brick_Smooth_Half",
      "rotation": 4
    },
    {
      "x": -14,
      "y": 10,
      "z": 10,
      "name": "Rock_Marble_Brick",
      "rotation": 2
    },
    {
      "x": -14,
      "y": 11,
      "z": 10,
      "name": "Empty"
    },
    {
      "x": -14,
      "y": 0,
      "z": 11,
      "name": "Rock_Marble_Brick"
    },
    {
      "x": -14,
      "y": 1,
      "z": 11,
      "name": "Rock_Marble_Brick"
    },
    {
      "x": -14,
      "y": 2,
      "z": 11,
      "name": "Rock_Marble_Brick"
    },
    {
      "x": -14,
      "y": 3,
      "z": 11,
      "name": "Rock_Marble_Brick"
    },
    {
      "x": -14,
      "y": 4,
      "z": 11,
      "name": "Rock_Marble_Brick",
      "rotation": 2
    },
    {
      "x": -14,
      "y": 5,
      "z": 11,
      "name": "Empty"
    },
    {
      "x": -14,
      "y": 6,
      "z": 11,
      "name": "Empty"
    },
    {
      "x": -14,
      "y": 7,
      "z": 11,
      "name": "Empty"
    },
    {
      "x": -14,
      "y": 8,
      "z": 11,
      "name": "Empty"
    },
    {
      "x": -14,
      "y": 9,
      "z": 11,
      "name": "Empty"
    },
    {
      "x": -14,
      "y": 10,
      "z": 11,
      "name": "Rock_Marble_Brick",
      "rotation": 2
    },
    {
      "x": -14,
      "y": 11,
      "z": 11,
      "name": "Empty"
    },
    {
      "x": -14,
      "y": 0,
      "z": 12,
      "name": "Rock_Marble_Brick"
    },
    {
      "x": -14,
      "y": 1,
      "z": 12,
      "name": "Rock_Marble_Brick"
    },
    {
      "x": -14,
      "y": 2,
      "z": 12,
      "name": "Rock_Marble_Brick"
    },
    {
      "x": -14,
      "y": 3,
      "z": 12,
      "name": "Rock_Marble_Brick"
    },
    {
      "x": -14,
      "y": 4,
      "z": 12,
      "name": "Rock_Marble_Brick",
      "rotation": 2
    },
    {
      "x": -14,
      "y": 5,
      "z": 12,
      "name": "Empty"
    },
    {
      "x": -14,
      "y": 6,
      "z": 12,
      "name": "Empty"
    },
    {
      "x": -14,
      "y": 7,
      "z": 12,
      "name": "Empty"
    },
    {
      "x": -14,
      "y": 8,
      "z": 12,
      "name": "Empty"
    },
    {
      "x": -14,
      "y": 9,
      "z": 12,
      "name": "Empty"
    },
    {
      "x": -14,
      "y": 10,
      "z": 12,
      "name": "Rock_Marble_Brick",
      "rotation": 2
    },
    {
      "x": -14,
      "y": 11,
      "z": 12,
      "name": "Empty"
    },
    {
      "x": -14,
      "y": 0,
      "z": 13,
      "name": "Rock_Marble_Brick"
    },
    {
      "x": -14,
      "y": 1,
      "z": 13,
      "name": "Rock_Marble_Brick"
    },
    {
      "x": -14,
      "y": 2,
      "z": 13,
      "name": "Rock_Marble_Brick"
    },
    {
      "x": -14,
      "y": 3,
      "z": 13,
      "name": "Rock_Marble_Brick"
    },
    {
      "x": -14,
      "y": 4,
      "z": 13,
      "name": "Rock_Marble_Brick",
      "rotation": 2
    },
    {
      "x": -14,
      "y": 5,
      "z": 13,
      "name": "Furniture_Temple_Light_Pot"
    },
    {
      "x": -14,
      "y": 6,
      "z": 13,
      "name": "Empty"
    },
    {
      "x": -14,
      "y": 7,
      "z": 13,
      "name": "Empty"
    },
    {
      "x": -14,
      "y": 8,
      "z": 13,
      "name": "Empty"
    },
    {
      "x": -14,
      "y": 9,
      "z": 13,
      "name": "Rock_Marble_Brick_Smooth_Half",
      "rotation": 6
    },
    {
      "x": -14,
      "y": 10,
      "z": 13,
      "name": "Rock_Ice",
      "rotation": 2
    },
    {
      "x": -14,
      "y": 11,
      "z": 13,
      "name": "Empty"
    },
    {
      "x": -14,
      "y": 0,
      "z": 14,
      "name": "Rock_Marble_Brick"
    },
    {
      "x": -14,
      "y": 1,
      "z": 14,
      "name": "Rock_Marble_Brick"
    },
    {
      "x": -14,
      "y": 2,
      "z": 14,
      "name": "Rock_Marble_Brick"
    },
    {
      "x": -14,
      "y": 3,
      "z": 14,
      "name": "Rock_Marble_Brick"
    },
    {
      "x": -14,
      "y": 4,
      "z": 14,
      "name": "Rock_Marble_Brick",
      "rotation": 2
    },
    {
      "x": -14,
      "y": 5,
      "z": 14,
      "name": "Rock_Marble_Brick_Decorative",
      "rotation": 2
    },
    {
      "x": -14,
      "y": 6,
      "z": 14,
      "name": "Rock_Marble_Brick",
      "rotation": 2
    },
    {
      "x": -14,
      "y": 7,
      "z": 14,
      "name": "Rock_Marble_Brick",
      "rotation": 2
    },
    {
      "x": -14,
      "y": 8,
      "z": 14,
      "name": "Rock_Ice",
      "rotation": 2
    },
    {
      "x": -14,
      "y": 9,
      "z": 14,
      "name": "Rock_Marble_Brick",
      "rotation": 2
    },
    {
      "x": -14,
      "y": 10,
      "z": 14,
      "name": "Rock_Marble_Brick",
      "rotation": 2
    },
    {
      "x": -14,
      "y": 11,
      "z": 14,
      "name": "Empty"
    },
    {
      "x": -14,
      "y": 0,
      "z": 15,
      "name": "Rock_Marble_Brick"
    },
    {
      "x": -14,
      "y": 1,
      "z": 15,
      "name": "Rock_Marble_Brick"
    },
    {
      "x": -14,
      "y": 2,
      "z": 15,
      "name": "Rock_Marble_Brick"
    },
    {
      "x": -14,
      "y": 3,
      "z": 15,
      "name": "Rock_Marble_Brick"
    },
    {
      "x": -14,
      "y": 4,
      "z": 15,
      "name": "Empty"
    },
    {
      "x": -14,
      "y": 5,
      "z": 15,
      "name": "Empty"
    },
    {
      "x": -14,
      "y": 6,
      "z": 15,
      "name": "Empty"
    },
    {
      "x": -14,
      "y": 7,
      "z": 15,
      "name": "Empty"
    },
    {
      "x": -14,
      "y": 8,
      "z": 15,
      "name": "Empty"
    },
    {
      "x": -14,
      "y": 9,
      "z": 15,
      "name": "Empty"
    },
    {
      "x": -14,
      "y": 10,
      "z": 15,
      "name": "Empty"
    },
    {
      "x": -14,
      "y": 11,
      "z": 15,
      "name": "Empty"
    },
    {
      "x": -13,
      "y": 0,
      "z": -14,
      "name": "Rock_Marble_Brick"
    },
    {
      "x": -13,
      "y": 1,
      "z": -14,
      "name": "Rock_Marble_Brick"
    },
    {
      "x": -13,
      "y": 2,
      "z": -14,
      "name": "Rock_Marble_Brick"
    },
    {
      "x": -13,
      "y": 3,
      "z": -14,
      "name": "Rock_Marble_Brick"
    },
    {
      "x": -13,
      "y": 4,
      "z": -14,
      "name": "Rock_Marble_Brick"
    },
    {
      "x": -13,
      "y": 5,
      "z": -14,
      "name": "Rock_Marble_Brick_Decorative"
    },
    {
      "x": -13,
      "y": 6,
      "z": -14,
      "name": "Rock_Marble_Brick"
    },
    {
      "x": -13,
      "y": 7,
      "z": -14,
      "name": "Rock_Ice"
    },
    {
      "x": -13,
      "y": 8,
      "z": -14,
      "name": "Rock_Marble_Brick"
    },
    {
      "x": -13,
      "y": 9,
      "z": -14,
      "name": "Rock_Marble_Brick"
    },
    {
      "x": -13,
      "y": 10,
      "z": -14,
      "name": "Rock_Marble_Brick"
    },
    {
      "x": -13,
      "y": 11,
      "z": -14,
      "name": "Empty"
    },
    {
      "x": -13,
      "y": 0,
      "z": -13,
      "name": "Rock_Marble_Brick"
    },
    {
      "x": -13,
      "y": 1,
      "z": -13,
      "name": "Rock_Marble_Brick"
    },
    {
      "x": -13,
      "y": 2,
      "z": -13,
      "name": "Rock_Marble_Brick"
    },
    {
      "x": -13,
      "y": 3,
      "z": -13,
      "name": "Rock_Marble_Brick"
    },
